Workbook

Sheet 1-專案資訊
A1: RC 數量計算模板 v5
A2: 搭接40D / 彎鉤12D / FY自動判定 / 搭接次數統計
A4: 專案名稱
A5: 填表日期
A6: 填表人員
A8: ▎ 全域單價設定
A9: 混凝土 fc'=210 kgf/cm2 (元/m3) | B9: 2800 | C9: 地坪鋪面
A10: 混凝土 fc'=280 kgf/cm2 (元/m3) | B10: 3500 | C10: 結構體
A11: 鋼筋SD280單價 (元/噸) | B11: 26000
A12: 鋼筋SD420單價 (元/噸) | B12: 28000
A13: 模板單價 (元/m2) | B13: 450 | C13: 含支撐
A14: 粉光單價 (元/m2) | B14: 250
A15: PC墊層 fc'=140 kgf/cm2 (元/m3) | B15: 2500
A16: 開挖單價 (元/m3) | B16: 180 | C16: 機械開挖
A17: 回填單價 (元/m3) | B17: 150 | C17: 夯實
A18: 鋼絲網單價 (元/噸) | B18: 35000
A19: 鋼筋損耗率 | B19: 0 | C19: 0%
A20: 模板損耗率 | B20: 0.05
A23: ▎ 鋼筋規格表（#3~#5=SD280, #6~#11=SD420）
A24: 鋼筋號數 | B24: db (mm) | C24: As (cm2) | D24: 單位重 (kg/m) | E24: db (cm) | F24: FY等級 | G24: fy (kgf/cm2) | H24: 搭接40D (cm) | I24: 彎鉤12D (cm)
A25: #3 (D10) | B25: 9.53 | C25: 0.7133 | D25: 0.56 | E25: 0.953 | F25: SD280 | G25: 2800 | H25: 38.1 | I25: 11.4
A26: #4 (D13) | B26: 12.7 | C26: 1.267 | D26: 0.994 | E26: 1.27 | F26: SD280 | G26: 2800 | H26: 50.8 | I26: 15.2
A27: #5 (D16) | B27: 15.88 | C27: 1.979 | D27: 1.56 | E27: 1.588 | F27: SD280 | G27: 2800 | H27: 63.5 | I27: 19.1
A28: #6 (D19) | B28: 19.05 | C28: 2.85 | D28: 2.24 | E28: 1.905 | F28: SD420 | G28: 4200 | H28: 76.2 | I28: 22.9
A29: #7 (D22) | B29: 22.23 | C29: 3.871 | D29: 3.04 | E29: 2.223 | F29: SD420 | G29: 4200 | H29: 88.9 | I29: 26.7
A30: #8 (D25) | B30: 25.4 | C30: 5.067 | D30: 3.98 | E30: 2.54 | F30: SD420 | G30: 4200 | H30: 101.6 | I30: 30.5
A31: #9 (D29) | B31: 28.65 | C31: 6.469 | D31: 5.08 | E31: 2.865 | F31: SD420 | G31: 4200 | H31: 114.6 | I31: 34.4
A32: #10 (D32) | B32: 32.26 | C32: 8.143 | D32: 6.39 | E32: 3.226 | F32: SD420 | G32: 4200 | H32: 129 | I32: 38.7
A33: #11 (D36) | B33: 35.81 | C33: 10.07 | D33: 7.9 | E33: 3.581 | F33: SD420 | G33: 4200 | H33: 143.2 | I33: 43
A36: ▎ 鋼絲網規格表
A37: 規格 | B37: 單位重 (kg/m2)
A38: φ6@150x150 | B38: 3.7
A51: ▎ 數量計算基準
A52: 項目 | B52: 規定
A53: 鋼筋搭接 | B53: 40D
A54: 鋼筋彎鉤 | B54: 12D
A55: FY判定 | B55: #3~#5=SD280; #6~#11=SD420
A56: 鋼筋損耗 | B56: 0%
A57: 尺寸量測 | B57: 柱心到柱心
A58: 混凝土 | B58: 不扣鋼筋重
...

Sheet 2-型式庫
A1: 配筋型式庫
A4: ▎ 柱
A5: 代號 | B5: 描述 | C5: 主筋 | D5: 支數 | E5: 箍筋 | F5: 間距 | G5: 繫筋
A6: C-01 | B6: 40x40-8#7 | C6: #7 (D22) | D6: 8 | E6: #4 (D13) | F6: 150 | G6: 0
A7: C-02 | B7: 60x60-12#8+4繫 | C7: #8 (D25) | D7: 12 | E7: #4 (D13) | F7: 150 | G7: 4
A10: ▎ 梁
A11: 代號 | B11: 描述 | C11: 上筋 | D11: 上支 | E11: 下筋 | F11: 下支 | G11: 箍筋 | H11: 密箍 | I11: 疏箍 | J11: 腰筋
A12: G-01 | B12: 30x60 | C12: #8 (D25) | D12: 3 | E12: #8 (D25) | F12: 4 | G12: #4 (D13) | H12: 150 | I12: 200 | J12: 0
A13: B-01 | B13: 25x45 | C13: #6 (D19) | D13: 2 | E13: #6 (D19) | F13: 3 | G13: #3 (D10) | H13: 200 | I13: 200 | J13: 0
A16: ▎ 版/牆/地坪/基礎/樓梯
A17: 代號 | B17: 描述 | C17: 筋號數 | D17: 間距 | E17: 鋼絲網 | F17: 備註
A18: S-01 | B18: 版t=15 #4@200雙層 | C18: #4 (D13) | D18: 200 | E18: 無 | F18: fc280
A19: W-01 | B19: 牆t=20 #4@200雙面 | C19: #4 (D13) | D19: 200 | E19: 無 | F19: fc280
A20: F-01 | B20: 地坪t=15 WWM+#4 | C20: #4 (D13) | D20: 200 | E20: φ4.0@150x150 | F20: fc210
A21: FD-01 | B21: 獨基 #6@200 | C21: #6 (D19) | D21: 200 | E21: 無 | F21: fc280
A22: EQ-01 | B22: 小設備 #4@200 | C22: #4 (D13) | D22: 200 | E22: φ4.0@150x150 | F22: fc280
A23: ST-01 | B23: 樓梯t=18 #5@150 | C23: #5 (D16) | D23: 150 | E23: 無 | F23: fc280

Sheet 3-柱
A1: 柱 數量計算表
A2: 主筋含搭接40D。箍筋繫筋含12D彎鉤。B3=預設鋼筋長度。
A3: 預設鋼筋長度 (m): | B3: 6 | C3: ← 可調整
A4: No | B4: 樓層 | C4: 柱編號 | D4: ▼型式 | E4: B (mm) | F4: D (mm) | G4: H (mm) | H4: 數量 | I4: ▼主筋 | J4: 支數 | K4: ▼箍筋 | L4: 間距 (mm) | M4: 繫筋 | N4: 混凝土 (m3) | O4: 主筋重 (kg) | P4: 箍筋重 (kg) | Q4: 繫筋重 (kg) | R4: 模板 (m2) | S4: 主筋搭接次數 | T4: 搭接長度 (m) | U4: SD280 (kg) | V4: SD420 (kg)
A5: 1 | N5: =IF(AND(E5<>"",F5<>"",G5<>"",H5<>""),E5*F5*G5/1000000000*H5,0) | O5: =IF(AND(I5<>"",J5<>"",G5<>"",H5<>""),VLOOKUP(I5,'1-專案資訊'!A25:I33,4,0)*(G5/1000+VLOOKUP(I5,'1-專案資訊'!A25:I33,8,0)/100)*J5*H5,0) | P5: =IF(AND(K5<>"",L5<>"",E5<>"",F5<>"",G5<>"",H5<>""),VLOOKUP(K5,'1-專案資訊'!A25:I33,4,0)*(2*((E5+F5)/1000-0.08)+2*VLOOKUP(K5,'1-專案資訊'!A25:I33,9,0)/100)*(G5/L5+1)*H5,0) | Q5: =IF(AND(K5<>"",M5>0,L5<>"",E5<>"",G5<>"",H5<>""),VLOOKUP(K5,'1-專案資訊'!A25:I33,4,0)*(MAX(E5,F5)/1000-0.08+2*VLOOKUP(K5,'1-專案資訊'!A25:I33,9,0)/100)*M5*(G5/L5+1)*H5,0) | R5: =IF(AND(E5<>"",F5<>"",G5<>"",H5<>""),2*(E5+F5)*G5/1000000*H5,0) | S5: =IF(AND(I5<>"",J5<>"",G5<>"",H5<>""),ROUNDUP((G5/1000+VLOOKUP(I5,'1-專案資訊'!A25:I33,8,0)/100)/$B$3,0)*J5*H5,0) | T5: =IF(AND(S5>0,I5<>""),S5*VLOOKUP(I5,'1-專案資訊'!A25:I33,8,0)/100,0) | U5: =IF(OR(I5="#3 (D10)",I5="#4 (D13)",I5="#5 (D16)"),O5,0)+IF(OR(K5="#3 (D10)",K5="#4 (D13)",K5="#5 (D16)"),P5,0)+IF(OR(K5="#3 (D10)",K5="#4 (D13)",K5="#5 (D16)"),Q5,0) | V5: =IF(AND(I5<>"",I5<>"#3 (D10)",I5<>"#4 (D13)",I5<>"#5 (D16)"),O5,0)+IF(AND(K5<>"",K5<>"#3 (D10)",K5<>"#4 (D13)",K5<>"#5 (D16)"),P5,0)+IF(AND(K5<>"",K5<>"#3 (D10)",K5<>"#4 (D13)",K5<>"#5 (D16)"),Q5,0)
A6: 2 | N6: =IF(AND(E6<>"",F6<>"",G6<>"",H6<>""),E6*F6*G6/1000000000*H6,0) | O6: =IF(AND(I6<>"",J6<>"",G6<>"",H6<>""),VLOOKUP(I6,'1-專案資訊'!A25:I33,4,0)*(G6/1000+VLOOKUP(I6,'1-專案資訊'!A25:I33,8,0)/100)*J6*H6,0) | P6: =IF(AND(K6<>"",L6<>"",E6<>"",F6<>"",G6<>"",H6<>""),VLOOKUP(K6,'1-專案資訊'!A25:I33,4,0)*(2*((E6+F6)/1000-0.08)+2*VLOOKUP(K6,'1-專案資訊'!A25:I33,9,0)/100)*(G6/L6+1)*H6,0) | Q6: =IF(AND(K6<>"",M6>0,L6<>"",E6<>"",G6<>"",H6<>""),VLOOKUP(K6,'1-專案資訊'!A25:I33,4,0)*(MAX(E6,F6)/1000-0.08+2*VLOOKUP(K6,'1-專案資訊'!A25:I33,9,0)/100)*M6*(G6/L6+1)*H6,0) | R6: =IF(AND(E6<>"",F6<>"",G6<>"",H6<>""),2*(E6+F6)*G6/1000000*H6,0) | S6: =IF(AND(I6<>"",J6<>"",G6<>"",H6<>""),ROUNDUP((G6/1000+VLOOKUP(I6,'1-專案資訊'!A25:I33,8,0)/100)/$B$3,0)*J6*H6,0) | T6: =IF(AND(S6>0,I6<>""),S6*VLOOKUP(I6,'1-專案資訊'!A25:I33,8,0)/100,0) | U6: =IF(OR(I6="#3 (D10)",I6="#4 (D13)",I6="#5 (D16)"),O6,0)+IF(OR(K6="#3 (D10)",K6="#4 (D13)",K6="#5 (D16)"),P6,0)+IF(OR(K6="#3 (D10)",K6="#4 (D13)",K6="#5 (D16)"),Q6,0) | V6: =IF(AND(I6<>"",I6<>"#3 (D10)",I6<>"#4 (D13)",I6<>"#5 (D16)"),O6,0)+IF(AND(K6<>"",K6<>"#3 (D10)",K6<>"#4 (D13)",K6<>"#5 (D16)"),P6,0)+IF(AND(K6<>"",K6<>"#3 (D10)",K6<>"#4 (D13)",K6<>"#5 (D16)"),Q6,0)
A7: 3 | N7: =IF(AND(E7<>"",F7<>"",G7<>"",H7<>""),E7*F7*G7/1000000000*H7,0) | O7: =IF(AND(I7<>"",J7<>"",G7<>"",H7<>""),VLOOKUP(I7,'1-專案資訊'!A25:I33,4,0)*(G7/1000+VLOOKUP(I7,'1-專案資訊'!A25:I33,8,0)/100)*J7*H7,0) | P7: =IF(AND(K7<>"",L7<>"",E7<>"",F7<>"",G7<>"",H7<>""),VLOOKUP(K7,'1-專案資訊'!A25:I33,4,0)*(2*((E7+F7)/1000-0.08)+2*VLOOKUP(K7,'1-專案資訊'!A25:I33,9,0)/100)*(G7/L7+1)*H7,0) | Q7: =IF(AND(K7<>"",M7>0,L7<>"",E7<>"",G7<>"",H7<>""),VLOOKUP(K7,'1-專案資訊'!A25:I33,4,0)*(MAX(E7,F7)/1000-0.08+2*VLOOKUP(K7,'1-專案資訊'!A25:I33,9,0)/100)*M7*(G7/L7+1)*H7,0) | R7: =IF(AND(E7<>"",F7<>"",G7<>"",H7<>""),2*(E7+F7)*G7/1000000*H7,0) | S7: =IF(AND(I7<>"",J7<>"",G7<>"",H7<>""),ROUNDUP((G7/1000+VLOOKUP(I7,'1-專案資訊'!A25:I33,8,0)/100)/$B$3,0)*J7*H7,0) | T7: =IF(AND(S7>0,I7<>""),S7*VLOOKUP(I7,'1-專案資訊'!A25:I33,8,0)/100,0) | U7: =IF(OR(I7="#3 (D10)",I7="#4 (D13)",I7="#5 (D16)"),O7,0)+IF(OR(K7="#3 (D10)",K7="#4 (D13)",K7="#5 (D16)"),P7,0)+IF(OR(K7="#3 (D10)",K7="#4 (D13)",K7="#5 (D16)"),Q7,0) | V7: =IF(AND(I7<>"",I7<>"#3 (D10)",I7<>"#4 (D13)",I7<>"#5 (D16)"),O7,0)+IF(AND(K7<>"",K7<>"#3 (D10)",K7<>"#4 (D13)",K7<>"#5 (D16)"),P7,0)+IF(AND(K7<>"",K7<>"#3 (D10)",K7<>"#4 (D13)",K7<>"#5 (D16)"),Q7,0)
A8: 4 | N8: =IF(AND(E8<>"",F8<>"",G8<>"",H8<>""),E8*F8*G8/1000000000*H8,0) | O8: =IF(AND(I8<>"",J8<>"",G8<>"",H8<>""),VLOOKUP(I8,'1-專案資訊'!A25:I33,4,0)*(G8/1000+VLOOKUP(I8,'1-專案資訊'!A25:I33,8,0)/100)*J8*H8,0) | P8: =IF(AND(K8<>"",L8<>"",E8<>"",F8<>"",G8<>"",H8<>""),VLOOKUP(K8,'1-專案資訊'!A25:I33,4,0)*(2*((E8+F8)/1000-0.08)+2*VLOOKUP(K8,'1-專案資訊'!A25:I33,9,0)/100)*(G8/L8+1)*H8,0) | Q8: =IF(AND(K8<>"",M8>0,L8<>"",E8<>"",G8<>"",H8<>""),VLOOKUP(K8,'1-專案資訊'!A25:I33,4,0)*(MAX(E8,F8)/1000-0.08+2*VLOOKUP(K8,'1-專案資訊'!A25:I33,9,0)/100)*M8*(G8/L8+1)*H8,0) | R8: =IF(AND(E8<>"",F8<>"",G8<>"",H8<>""),2*(E8+F8)*G8/1000000*H8,0) | S8: =IF(AND(I8<>"",J8<>"",G8<>"",H8<>""),ROUNDUP((G8/1000+VLOOKUP(I8,'1-專案資訊'!A25:I33,8,0)/100)/$B$3,0)*J8*H8,0) | T8: =IF(AND(S8>0,I8<>""),S8*VLOOKUP(I8,'1-專案資訊'!A25:I33,8,0)/100,0) | U8: =IF(OR(I8="#3 (D10)",I8="#4 (D13)",I8="#5 (D16)"),O8,0)+IF(OR(K8="#3 (D10)",K8="#4 (D13)",K8="#5 (D16)"),P8,0)+IF(OR(K8="#3 (D10)",K8="#4 (D13)",K8="#5 (D16)"),Q8,0) | V8: =IF(AND(I8<>"",I8<>"#3 (D10)",I8<>"#4 (D13)",I8<>"#5 (D16)"),O8,0)+IF(AND(K8<>"",K8<>"#3 (D10)",K8<>"#4 (D13)",K8<>"#5 (D16)"),P8,0)+IF(AND(K8<>"",K8<>"#3 (D10)",K8<>"#4 (D13)",K8<>"#5 (D16)"),Q8,0)
A9: 5 | N9: =IF(AND(E9<>"",F9<>"",G9<>"",H9<>""),E9*F9*G9/1000000000*H9,0) | O9: =IF(AND(I9<>"",J9<>"",G9<>"",H9<>""),VLOOKUP(I9,'1-專案資訊'!A25:I33,4,0)*(G9/1000+VLOOKUP(I9,'1-專案資訊'!A25:I33,8,0)/100)*J9*H9,0) | P9: =IF(AND(K9<>"",L9<>"",E9<>"",F9<>"",G9<>"",H9<>""),VLOOKUP(K9,'1-專案資訊'!A25:I33,4,0)*(2*((E9+F9)/1000-0.08)+2*VLOOKUP(K9,'1-專案資訊'!A25:I33,9,0)/100)*(G9/L9+1)*H9,0) | Q9: =IF(AND(K9<>"",M9>0,L9<>"",E9<>"",G9<>"",H9<>""),VLOOKUP(K9,'1-專案資訊'!A25:I33,4,0)*(MAX(E9,F9)/1000-0.08+2*VLOOKUP(K9,'1-專案資訊'!A25:I33,9,0)/100)*M9*(G9/L9+1)*H9,0) | R9: =IF(AND(E9<>"",F9<>"",G9<>"",H9<>""),2*(E9+F9)*G9/1000000*H9,0) | S9: =IF(AND(I9<>"",J9<>"",G9<>"",H9<>""),ROUNDUP((G9/1000+VLOOKUP(I9,'1-專案資訊'!A25:I33,8,0)/100)/$B$3,0)*J9*H9,0) | T9: =IF(AND(S9>0,I9<>""),S9*VLOOKUP(I9,'1-專案資訊'!A25:I33,8,0)/100,0) | U9: =IF(OR(I9="#3 (D10)",I9="#4 (D13)",I9="#5 (D16)"),O9,0)+IF(OR(K9="#3 (D10)",K9="#4 (D13)",K9="#5 (D16)"),P9,0)+IF(OR(K9="#3 (D10)",K9="#4 (D13)",K9="#5 (D16)"),Q9,0) | V9: =IF(AND(I9<>"",I9<>"#3 (D10)",I9<>"#4 (D13)",I9<>"#5 (D16)"),O9,0)+IF(AND(K9<>"",K9<>"#3 (D10)",K9<>"#4 (D13)",K9<>"#5 (D16)"),P9,0)+IF(AND(K9<>"",K9<>"#3 (D10)",K9<>"#4 (D13)",K9<>"#5 (D16)"),Q9,0)
A10: 6 | N10: =IF(AND(E10<>"",F10<>"",G10<>"",H10<>""),E10*F10*G10/1000000000*H10,0) | O10: =IF(AND(I10<>"",J10<>"",G10<>"",H10<>""),VLOOKUP(I10,'1-專案資訊'!A25:I33,4,0)*(G10/1000+VLOOKUP(I10,'1-專案資訊'!A25:I33,8,0)/100)*J10*H10,0) | P10: =IF(AND(K10<>"",L10<>"",E10<>"",F10<>"",G10<>"",H10<>""),VLOOKUP(K10,'1-專案資訊'!A25:I33,4,0)*(2*((E10+F10)/1000-0.08)+2*VLOOKUP(K10,'1-專案資訊'!A25:I33,9,0)/100)*(G10/L10+1)*H10,0) | Q10: =IF(AND(K10<>"",M10>0,L10<>"",E10<>"",G10<>"",H10<>""),VLOOKUP(K10,'1-專案資訊'!A25:I33,4,0)*(MAX(E10,F10)/1000-0.08+2*VLOOKUP(K10,'1-專案資訊'!A25:I33,9,0)/100)*M10*(G10/L10+1)*H10,0) | R10: =IF(AND(E10<>"",F10<>"",G10<>"",H10<>""),2*(E10+F10)*G10/1000000*H10,0) | S10: =IF(AND(I10<>"",J10<>"",G10<>"",H10<>""),ROUNDUP((G10/1000+VLOOKUP(I10,'1-專案資訊'!A25:I33,8,0)/100)/$B$3,0)*J10*H10,0) | T10: =IF(AND(S10>0,I10<>""),S10*VLOOKUP(I10,'1-專案資訊'!A25:I33,8,0)/100,0) | U10: =IF(OR(I10="#3 (D10)",I10="#4 (D13)",I10="#5 (D16)"),O10,0)+IF(OR(K10="#3 (D10)",K10="#4 (D13)",K10="#5 (D16)"),P10,0)+IF(OR(K10="#3 (D10)",K10="#4 (D13)",K10="#5 (D16)"),Q10,0) | V10: =IF(AND(I10<>"",I10<>"#3 (D10)",I10<>"#4 (D13)",I10<>"#5 (D16)"),O10,0)+IF(AND(K10<>"",K10<>"#3 (D10)",K10<>"#4 (D13)",K10<>"#5 (D16)"),P10,0)+IF(AND(K10<>"",K10<>"#3 (D10)",K10<>"#4 (D13)",K10<>"#5 (D16)"),Q10,0)
A11: 7 | N11: =IF(AND(E11<>"",F11<>"",G11<>"",H11<>""),E11*F11*G11/1000000000*H11,0) | O11: =IF(AND(I11<>"",J11<>"",G11<>"",H11<>""),VLOOKUP(I11,'1-專案資訊'!A25:I33,4,0)*(G11/1000+VLOOKUP(I11,'1-專案資訊'!A25:I33,8,0)/100)*J11*H11,0) | P11: =IF(AND(K11<>"",L11<>"",E11<>"",F11<>"",G11<>"",H11<>""),VLOOKUP(K11,'1-專案資訊'!A25:I33,4,0)*(2*((E11+F11)/1000-0.08)+2*VLOOKUP(K11,'1-專案資訊'!A25:I33,9,0)/100)*(G11/L11+1)*H11,0) | Q11: =IF(AND(K11<>"",M11>0,L11<>"",E11<>"",G11<>"",H11<>""),VLOOKUP(K11,'1-專案資訊'!A25:I33,4,0)*(MAX(E11,F11)/1000-0.08+2*VLOOKUP(K11,'1-專案資訊'!A25:I33,9,0)/100)*M11*(G11/L11+1)*H11,0) | R11: =IF(AND(E11<>"",F11<>"",G11<>"",H11<>""),2*(E11+F11)*G11/1000000*H11,0) | S11: =IF(AND(I11<>"",J11<>"",G11<>"",H11<>""),ROUNDUP((G11/1000+VLOOKUP(I11,'1-專案資訊'!A25:I33,8,0)/100)/$B$3,0)*J11*H11,0) | T11: =IF(AND(S11>0,I11<>""),S11*VLOOKUP(I11,'1-專案資訊'!A25:I33,8,0)/100,0) | U11: =IF(OR(I11="#3 (D10)",I11="#4 (D13)",I11="#5 (D16)"),O11,0)+IF(OR(K11="#3 (D10)",K11="#4 (D13)",K11="#5 (D16)"),P11,0)+IF(OR(K11="#3 (D10)",K11="#4 (D13)",K11="#5 (D16)"),Q11,0) | V11: =IF(AND(I11<>"",I11<>"#3 (D10)",I11<>"#4 (D13)",I11<>"#5 (D16)"),O11,0)+IF(AND(K11<>"",K11<>"#3 (D10)",K11<>"#4 (D13)",K11<>"#5 (D16)"),P11,0)+IF(AND(K11<>"",K11<>"#3 (D10)",K11<>"#4 (D13)",K11<>"#5 (D16)"),Q11,0)
A12: 8 | N12: =IF(AND(E12<>"",F12<>"",G12<>"",H12<>""),E12*F12*G12/1000000000*H12,0) | O12: =IF(AND(I12<>"",J12<>"",G12<>"",H12<>""),VLOOKUP(I12,'1-專案資訊'!A25:I33,4,0)*(G12/1000+VLOOKUP(I12,'1-專案資訊'!A25:I33,8,0)/100)*J12*H12,0) | P12: =IF(AND(K12<>"",L12<>"",E12<>"",F12<>"",G12<>"",H12<>""),VLOOKUP(K12,'1-專案資訊'!A25:I33,4,0)*(2*((E12+F12)/1000-0.08)+2*VLOOKUP(K12,'1-專案資訊'!A25:I33,9,0)/100)*(G12/L12+1)*H12,0) | Q12: =IF(AND(K12<>"",M12>0,L12<>"",E12<>"",G12<>"",H12<>""),VLOOKUP(K12,'1-專案資訊'!A25:I33,4,0)*(MAX(E12,F12)/1000-0.08+2*VLOOKUP(K12,'1-專案資訊'!A25:I33,9,0)/100)*M12*(G12/L12+1)*H12,0) | R12: =IF(AND(E12<>"",F12<>"",G12<>"",H12<>""),2*(E12+F12)*G12/1000000*H12,0) | S12: =IF(AND(I12<>"",J12<>"",G12<>"",H12<>""),ROUNDUP((G12/1000+VLOOKUP(I12,'1-專案資訊'!A25:I33,8,0)/100)/$B$3,0)*J12*H12,0) | T12: =IF(AND(S12>0,I12<>""),S12*VLOOKUP(I12,'1-專案資訊'!A25:I33,8,0)/100,0) | U12: =IF(OR(I12="#3 (D10)",I12="#4 (D13)",I12="#5 (D16)"),O12,0)+IF(OR(K12="#3 (D10)",K12="#4 (D13)",K12="#5 (D16)"),P12,0)+IF(OR(K12="#3 (D10)",K12="#4 (D13)",K12="#5 (D16)"),Q12,0) | V12: =IF(AND(I12<>"",I12<>"#3 (D10)",I12<>"#4 (D13)",I12<>"#5 (D16)"),O12,0)+IF(AND(K12<>"",K12<>"#3 (D10)",K12<>"#4 (D13)",K12<>"#5 (D16)"),P12,0)+IF(AND(K12<>"",K12<>"#3 (D10)",K12<>"#4 (D13)",K12<>"#5 (D16)"),Q12,0)
A13: 9 | N13: =IF(AND(E13<>"",F13<>"",G13<>"",H13<>""),E13*F13*G13/1000000000*H13,0) | O13: =IF(AND(I13<>"",J13<>"",G13<>"",H13<>""),VLOOKUP(I13,'1-專案資訊'!A25:I33,4,0)*(G13/1000+VLOOKUP(I13,'1-專案資訊'!A25:I33,8,0)/100)*J13*H13,0) | P13: =IF(AND(K13<>"",L13<>"",E13<>"",F13<>"",G13<>"",H13<>""),VLOOKUP(K13,'1-專案資訊'!A25:I33,4,0)*(2*((E13+F13)/1000-0.08)+2*VLOOKUP(K13,'1-專案資訊'!A25:I33,9,0)/100)*(G13/L13+1)*H13,0) | Q13: =IF(AND(K13<>"",M13>0,L13<>"",E13<>"",G13<>"",H13<>""),VLOOKUP(K13,'1-專案資訊'!A25:I33,4,0)*(MAX(E13,F13)/1000-0.08+2*VLOOKUP(K13,'1-專案資訊'!A25:I33,9,0)/100)*M13*(G13/L13+1)*H13,0) | R13: =IF(AND(E13<>"",F13<>"",G13<>"",H13<>""),2*(E13+F13)*G13/1000000*H13,0) | S13: =IF(AND(I13<>"",J13<>"",G13<>"",H13<>""),ROUNDUP((G13/1000+VLOOKUP(I13,'1-專案資訊'!A25:I33,8,0)/100)/$B$3,0)*J13*H13,0) | T13: =IF(AND(S13>0,I13<>""),S13*VLOOKUP(I13,'1-專案資訊'!A25:I33,8,0)/100,0) | U13: =IF(OR(I13="#3 (D10)",I13="#4 (D13)",I13="#5 (D16)"),O13,0)+IF(OR(K13="#3 (D10)",K13="#4 (D13)",K13="#5 (D16)"),P13,0)+IF(OR(K13="#3 (D10)",K13="#4 (D13)",K13="#5 (D16)"),Q13,0) | V13: =IF(AND(I13<>"",I13<>"#3 (D10)",I13<>"#4 (D13)",I13<>"#5 (D16)"),O13,0)+IF(AND(K13<>"",K13<>"#3 (D10)",K13<>"#4 (D13)",K13<>"#5 (D16)"),P13,0)+IF(AND(K13<>"",K13<>"#3 (D10)",K13<>"#4 (D13)",K13<>"#5 (D16)"),Q13,0)
A14: 10 | N14: =IF(AND(E14<>"",F14<>"",G14<>"",H14<>""),E14*F14*G14/1000000000*H14,0) | O14: =IF(AND(I14<>"",J14<>"",G14<>"",H14<>""),VLOOKUP(I14,'1-專案資訊'!A25:I33,4,0)*(G14/1000+VLOOKUP(I14,'1-專案資訊'!A25:I33,8,0)/100)*J14*H14,0) | P14: =IF(AND(K14<>"",L14<>"",E14<>"",F14<>"",G14<>"",H14<>""),VLOOKUP(K14,'1-專案資訊'!A25:I33,4,0)*(2*((E14+F14)/1000-0.08)+2*VLOOKUP(K14,'1-專案資訊'!A25:I33,9,0)/100)*(G14/L14+1)*H14,0) | Q14: =IF(AND(K14<>"",M14>0,L14<>"",E14<>"",G14<>"",H14<>""),VLOOKUP(K14,'1-專案資訊'!A25:I33,4,0)*(MAX(E14,F14)/1000-0.08+2*VLOOKUP(K14,'1-專案資訊'!A25:I33,9,0)/100)*M14*(G14/L14+1)*H14,0) | R14: =IF(AND(E14<>"",F14<>"",G14<>"",H14<>""),2*(E14+F14)*G14/1000000*H14,0) | S14: =IF(AND(I14<>"",J14<>"",G14<>"",H14<>""),ROUNDUP((G14/1000+VLOOKUP(I14,'1-專案資訊'!A25:I33,8,0)/100)/$B$3,0)*J14*H14,0) | T14: =IF(AND(S14>0,I14<>""),S14*VLOOKUP(I14,'1-專案資訊'!A25:I33,8,0)/100,0) | U14: =IF(OR(I14="#3 (D10)",I14="#4 (D13)",I14="#5 (D16)"),O14,0)+IF(OR(K14="#3 (D10)",K14="#4 (D13)",K14="#5 (D16)"),P14,0)+IF(OR(K14="#3 (D10)",K14="#4 (D13)",K14="#5 (D16)"),Q14,0) | V14: =IF(AND(I14<>"",I14<>"#3 (D10)",I14<>"#4 (D13)",I14<>"#5 (D16)"),O14,0)+IF(AND(K14<>"",K14<>"#3 (D10)",K14<>"#4 (D13)",K14<>"#5 (D16)"),P14,0)+IF(AND(K14<>"",K14<>"#3 (D10)",K14<>"#4 (D13)",K14<>"#5 (D16)"),Q14,0)
A15: 11 | N15: =IF(AND(E15<>"",F15<>"",G15<>"",H15<>""),E15*F15*G15/1000000000*H15,0) | O15: =IF(AND(I15<>"",J15<>"",G15<>"",H15<>""),VLOOKUP(I15,'1-專案資訊'!A25:I33,4,0)*(G15/1000+VLOOKUP(I15,'1-專案資訊'!A25:I33,8,0)/100)*J15*H15,0) | P15: =IF(AND(K15<>"",L15<>"",E15<>"",F15<>"",G15<>"",H15<>""),VLOOKUP(K15,'1-專案資訊'!A25:I33,4,0)*(2*((E15+F15)/1000-0.08)+2*VLOOKUP(K15,'1-專案資訊'!A25:I33,9,0)/100)*(G15/L15+1)*H15,0) | Q15: =IF(AND(K15<>"",M15>0,L15<>"",E15<>"",G15<>"",H15<>""),VLOOKUP(K15,'1-專案資訊'!A25:I33,4,0)*(MAX(E15,F15)/1000-0.08+2*VLOOKUP(K15,'1-專案資訊'!A25:I33,9,0)/100)*M15*(G15/L15+1)*H15,0) | R15: =IF(AND(E15<>"",F15<>"",G15<>"",H15<>""),2*(E15+F15)*G15/1000000*H15,0) | S15: =IF(AND(I15<>"",J15<>"",G15<>"",H15<>""),ROUNDUP((G15/1000+VLOOKUP(I15,'1-專案資訊'!A25:I33,8,0)/100)/$B$3,0)*J15*H15,0) | T15: =IF(AND(S15>0,I15<>""),S15*VLOOKUP(I15,'1-專案資訊'!A25:I33,8,0)/100,0) | U15: =IF(OR(I15="#3 (D10)",I15="#4 (D13)",I15="#5 (D16)"),O15,0)+IF(OR(K15="#3 (D10)",K15="#4 (D13)",K15="#5 (D16)"),P15,0)+IF(OR(K15="#3 (D10)",K15="#4 (D13)",K15="#5 (D16)"),Q15,0) | V15: =IF(AND(I15<>"",I15<>"#3 (D10)",I15<>"#4 (D13)",I15<>"#5 (D16)"),O15,0)+IF(AND(K15<>"",K15<>"#3 (D10)",K15<>"#4 (D13)",K15<>"#5 (D16)"),P15,0)+IF(AND(K15<>"",K15<>"#3 (D10)",K15<>"#4 (D13)",K15<>"#5 (D16)"),Q15,0)
A16: 12 | N16: =IF(AND(E16<>"",F16<>"",G16<>"",H16<>""),E16*F16*G16/1000000000*H16,0) | O16: =IF(AND(I16<>"",J16<>"",G16<>"",H16<>""),VLOOKUP(I16,'1-專案資訊'!A25:I33,4,0)*(G16/1000+VLOOKUP(I16,'1-專案資訊'!A25:I33,8,0)/100)*J16*H16,0) | P16: =IF(AND(K16<>"",L16<>"",E16<>"",F16<>"",G16<>"",H16<>""),VLOOKUP(K16,'1-專案資訊'!A25:I33,4,0)*(2*((E16+F16)/1000-0.08)+2*VLOOKUP(K16,'1-專案資訊'!A25:I33,9,0)/100)*(G16/L16+1)*H16,0) | Q16: =IF(AND(K16<>"",M16>0,L16<>"",E16<>"",G16<>"",H16<>""),VLOOKUP(K16,'1-專案資訊'!A25:I33,4,0)*(MAX(E16,F16)/1000-0.08+2*VLOOKUP(K16,'1-專案資訊'!A25:I33,9,0)/100)*M16*(G16/L16+1)*H16,0) | R16: =IF(AND(E16<>"",F16<>"",G16<>"",H16<>""),2*(E16+F16)*G16/1000000*H16,0) | S16: =IF(AND(I16<>"",J16<>"",G16<>"",H16<>""),ROUNDUP((G16/1000+VLOOKUP(I16,'1-專案資訊'!A25:I33,8,0)/100)/$B$3,0)*J16*H16,0) | T16: =IF(AND(S16>0,I16<>""),S16*VLOOKUP(I16,'1-專案資訊'!A25:I33,8,0)/100,0) | U16: =IF(OR(I16="#3 (D10)",I16="#4 (D13)",I16="#5 (D16)"),O16,0)+IF(OR(K16="#3 (D10)",K16="#4 (D13)",K16="#5 (D16)"),P16,0)+IF(OR(K16="#3 (D10)",K16="#4 (D13)",K16="#5 (D16)"),Q16,0) | V16: =IF(AND(I16<>"",I16<>"#3 (D10)",I16<>"#4 (D13)",I16<>"#5 (D16)"),O16,0)+IF(AND(K16<>"",K16<>"#3 (D10)",K16<>"#4 (D13)",K16<>"#5 (D16)"),P16,0)+IF(AND(K16<>"",K16<>"#3 (D10)",K16<>"#4 (D13)",K16<>"#5 (D16)"),Q16,0)
A17: 13 | N17: =IF(AND(E17<>"",F17<>"",G17<>"",H17<>""),E17*F17*G17/1000000000*H17,0) | O17: =IF(AND(I17<>"",J17<>"",G17<>"",H17<>""),VLOOKUP(I17,'1-專案資訊'!A25:I33,4,0)*(G17/1000+VLOOKUP(I17,'1-專案資訊'!A25:I33,8,0)/100)*J17*H17,0) | P17: =IF(AND(K17<>"",L17<>"",E17<>"",F17<>"",G17<>"",H17<>""),VLOOKUP(K17,'1-專案資訊'!A25:I33,4,0)*(2*((E17+F17)/1000-0.08)+2*VLOOKUP(K17,'1-專案資訊'!A25:I33,9,0)/100)*(G17/L17+1)*H17,0) | Q17: =IF(AND(K17<>"",M17>0,L17<>"",E17<>"",G17<>"",H17<>""),VLOOKUP(K17,'1-專案資訊'!A25:I33,4,0)*(MAX(E17,F17)/1000-0.08+2*VLOOKUP(K17,'1-專案資訊'!A25:I33,9,0)/100)*M17*(G17/L17+1)*H17,0) | R17: =IF(AND(E17<>"",F17<>"",G17<>"",H17<>""),2*(E17+F17)*G17/1000000*H17,0) | S17: =IF(AND(I17<>"",J17<>"",G17<>"",H17<>""),ROUNDUP((G17/1000+VLOOKUP(I17,'1-專案資訊'!A25:I33,8,0)/100)/$B$3,0)*J17*H17,0) | T17: =IF(AND(S17>0,I17<>""),S17*VLOOKUP(I17,'1-專案資訊'!A25:I33,8,0)/100,0) | U17: =IF(OR(I17="#3 (D10)",I17="#4 (D13)",I17="#5 (D16)"),O17,0)+IF(OR(K17="#3 (D10)",K17="#4 (D13)",K17="#5 (D16)"),P17,0)+IF(OR(K17="#3 (D10)",K17="#4 (D13)",K17="#5 (D16)"),Q17,0) | V17: =IF(AND(I17<>"",I17<>"#3 (D10)",I17<>"#4 (D13)",I17<>"#5 (D16)"),O17,0)+IF(AND(K17<>"",K17<>"#3 (D10)",K17<>"#4 (D13)",K17<>"#5 (D16)"),P17,0)+IF(AND(K17<>"",K17<>"#3 (D10)",K17<>"#4 (D13)",K17<>"#5 (D16)"),Q17,0)
A18: 14 | N18: =IF(AND(E18<>"",F18<>"",G18<>"",H18<>""),E18*F18*G18/1000000000*H18,0) | O18: =IF(AND(I18<>"",J18<>"",G18<>"",H18<>""),VLOOKUP(I18,'1-專案資訊'!A25:I33,4,0)*(G18/1000+VLOOKUP(I18,'1-專案資訊'!A25:I33,8,0)/100)*J18*H18,0) | P18: =IF(AND(K18<>"",L18<>"",E18<>"",F18<>"",G18<>"",H18<>""),VLOOKUP(K18,'1-專案資訊'!A25:I33,4,0)*(2*((E18+F18)/1000-0.08)+2*VLOOKUP(K18,'1-專案資訊'!A25:I33,9,0)/100)*(G18/L18+1)*H18,0) | Q18: =IF(AND(K18<>"",M18>0,L18<>"",E18<>"",G18<>"",H18<>""),VLOOKUP(K18,'1-專案資訊'!A25:I33,4,0)*(MAX(E18,F18)/1000-0.08+2*VLOOKUP(K18,'1-專案資訊'!A25:I33,9,0)/100)*M18*(G18/L18+1)*H18,0) | R18: =IF(AND(E18<>"",F18<>"",G18<>"",H18<>""),2*(E18+F18)*G18/1000000*H18,0) | S18: =IF(AND(I18<>"",J18<>"",G18<>"",H18<>""),ROUNDUP((G18/1000+VLOOKUP(I18,'1-專案資訊'!A25:I33,8,0)/100)/$B$3,0)*J18*H18,0) | T18: =IF(AND(S18>0,I18<>""),S18*VLOOKUP(I18,'1-專案資訊'!A25:I33,8,0)/100,0) | U18: =IF(OR(I18="#3 (D10)",I18="#4 (D13)",I18="#5 (D16)"),O18,0)+IF(OR(K18="#3 (D10)",K18="#4 (D13)",K18="#5 (D16)"),P18,0)+IF(OR(K18="#3 (D10)",K18="#4 (D13)",K18="#5 (D16)"),Q18,0) | V18: =IF(AND(I18<>"",I18<>"#3 (D10)",I18<>"#4 (D13)",I18<>"#5 (D16)"),O18,0)+IF(AND(K18<>"",K18<>"#3 (D10)",K18<>"#4 (D13)",K18<>"#5 (D16)"),P18,0)+IF(AND(K18<>"",K18<>"#3 (D10)",K18<>"#4 (D13)",K18<>"#5 (D16)"),Q18,0)
A19: 15 | N19: =IF(AND(E19<>"",F19<>"",G19<>"",H19<>""),E19*F19*G19/1000000000*H19,0) | O19: =IF(AND(I19<>"",J19<>"",G19<>"",H19<>""),VLOOKUP(I19,'1-專案資訊'!A25:I33,4,0)*(G19/1000+VLOOKUP(I19,'1-專案資訊'!A25:I33,8,0)/100)*J19*H19,0) | P19: =IF(AND(K19<>"",L19<>"",E19<>"",F19<>"",G19<>"",H19<>""),VLOOKUP(K19,'1-專案資訊'!A25:I33,4,0)*(2*((E19+F19)/1000-0.08)+2*VLOOKUP(K19,'1-專案資訊'!A25:I33,9,0)/100)*(G19/L19+1)*H19,0) | Q19: =IF(AND(K19<>"",M19>0,L19<>"",E19<>"",G19<>"",H19<>""),VLOOKUP(K19,'1-專案資訊'!A25:I33,4,0)*(MAX(E19,F19)/1000-0.08+2*VLOOKUP(K19,'1-專案資訊'!A25:I33,9,0)/100)*M19*(G19/L19+1)*H19,0) | R19: =IF(AND(E19<>"",F19<>"",G19<>"",H19<>""),2*(E19+F19)*G19/1000000*H19,0) | S19: =IF(AND(I19<>"",J19<>"",G19<>"",H19<>""),ROUNDUP((G19/1000+VLOOKUP(I19,'1-專案資訊'!A25:I33,8,0)/100)/$B$3,0)*J19*H19,0) | T19: =IF(AND(S19>0,I19<>""),S19*VLOOKUP(I19,'1-專案資訊'!A25:I33,8,0)/100,0) | U19: =IF(OR(I19="#3 (D10)",I19="#4 (D13)",I19="#5 (D16)"),O19,0)+IF(OR(K19="#3 (D10)",K19="#4 (D13)",K19="#5 (D16)"),P19,0)+IF(OR(K19="#3 (D10)",K19="#4 (D13)",K19="#5 (D16)"),Q19,0) | V19: =IF(AND(I19<>"",I19<>"#3 (D10)",I19<>"#4 (D13)",I19<>"#5 (D16)"),O19,0)+IF(AND(K19<>"",K19<>"#3 (D10)",K19<>"#4 (D13)",K19<>"#5 (D16)"),P19,0)+IF(AND(K19<>"",K19<>"#3 (D10)",K19<>"#4 (D13)",K19<>"#5 (D16)"),Q19,0)
A20: 16 | N20: =IF(AND(E20<>"",F20<>"",G20<>"",H20<>""),E20*F20*G20/1000000000*H20,0) | O20: =IF(AND(I20<>"",J20<>"",G20<>"",H20<>""),VLOOKUP(I20,'1-專案資訊'!A25:I33,4,0)*(G20/1000+VLOOKUP(I20,'1-專案資訊'!A25:I33,8,0)/100)*J20*H20,0) | P20: =IF(AND(K20<>"",L20<>"",E20<>"",F20<>"",G20<>"",H20<>""),VLOOKUP(K20,'1-專案資訊'!A25:I33,4,0)*(2*((E20+F20)/1000-0.08)+2*VLOOKUP(K20,'1-專案資訊'!A25:I33,9,0)/100)*(G20/L20+1)*H20,0) | Q20: =IF(AND(K20<>"",M20>0,L20<>"",E20<>"",G20<>"",H20<>""),VLOOKUP(K20,'1-專案資訊'!A25:I33,4,0)*(MAX(E20,F20)/1000-0.08+2*VLOOKUP(K20,'1-專案資訊'!A25:I33,9,0)/100)*M20*(G20/L20+1)*H20,0) | R20: =IF(AND(E20<>"",F20<>"",G20<>"",H20<>""),2*(E20+F20)*G20/1000000*H20,0) | S20: =IF(AND(I20<>"",J20<>"",G20<>"",H20<>""),ROUNDUP((G20/1000+VLOOKUP(I20,'1-專案資訊'!A25:I33,8,0)/100)/$B$3,0)*J20*H20,0) | T20: =IF(AND(S20>0,I20<>""),S20*VLOOKUP(I20,'1-專案資訊'!A25:I33,8,0)/100,0) | U20: =IF(OR(I20="#3 (D10)",I20="#4 (D13)",I20="#5 (D16)"),O20,0)+IF(OR(K20="#3 (D10)",K20="#4 (D13)",K20="#5 (D16)"),P20,0)+IF(OR(K20="#3 (D10)",K20="#4 (D13)",K20="#5 (D16)"),Q20,0) | V20: =IF(AND(I20<>"",I20<>"#3 (D10)",I20<>"#4 (D13)",I20<>"#5 (D16)"),O20,0)+IF(AND(K20<>"",K20<>"#3 (D10)",K20<>"#4 (D13)",K20<>"#5 (D16)"),P20,0)+IF(AND(K20<>"",K20<>"#3 (D10)",K20<>"#4 (D13)",K20<>"#5 (D16)"),Q20,0)
A21: 17 | N21: =IF(AND(E21<>"",F21<>"",G21<>"",H21<>""),E21*F21*G21/1000000000*H21,0) | O21: =IF(AND(I21<>"",J21<>"",G21<>"",H21<>""),VLOOKUP(I21,'1-專案資訊'!A25:I33,4,0)*(G21/1000+VLOOKUP(I21,'1-專案資訊'!A25:I33,8,0)/100)*J21*H21,0) | P21: =IF(AND(K21<>"",L21<>"",E21<>"",F21<>"",G21<>"",H21<>""),VLOOKUP(K21,'1-專案資訊'!A25:I33,4,0)*(2*((E21+F21)/1000-0.08)+2*VLOOKUP(K21,'1-專案資訊'!A25:I33,9,0)/100)*(G21/L21+1)*H21,0) | Q21: =IF(AND(K21<>"",M21>0,L21<>"",E21<>"",G21<>"",H21<>""),VLOOKUP(K21,'1-專案資訊'!A25:I33,4,0)*(MAX(E21,F21)/1000-0.08+2*VLOOKUP(K21,'1-專案資訊'!A25:I33,9,0)/100)*M21*(G21/L21+1)*H21,0) | R21: =IF(AND(E21<>"",F21<>"",G21<>"",H21<>""),2*(E21+F21)*G21/1000000*H21,0) | S21: =IF(AND(I21<>"",J21<>"",G21<>"",H21<>""),ROUNDUP((G21/1000+VLOOKUP(I21,'1-專案資訊'!A25:I33,8,0)/100)/$B$3,0)*J21*H21,0) | T21: =IF(AND(S21>0,I21<>""),S21*VLOOKUP(I21,'1-專案資訊'!A25:I33,8,0)/100,0) | U21: =IF(OR(I21="#3 (D10)",I21="#4 (D13)",I21="#5 (D16)"),O21,0)+IF(OR(K21="#3 (D10)",K21="#4 (D13)",K21="#5 (D16)"),P21,0)+IF(OR(K21="#3 (D10)",K21="#4 (D13)",K21="#5 (D16)"),Q21,0) | V21: =IF(AND(I21<>"",I21<>"#3 (D10)",I21<>"#4 (D13)",I21<>"#5 (D16)"),O21,0)+IF(AND(K21<>"",K21<>"#3 (D10)",K21<>"#4 (D13)",K21<>"#5 (D16)"),P21,0)+IF(AND(K21<>"",K21<>"#3 (D10)",K21<>"#4 (D13)",K21<>"#5 (D16)"),Q21,0)
A22: 18 | N22: =IF(AND(E22<>"",F22<>"",G22<>"",H22<>""),E22*F22*G22/1000000000*H22,0) | O22: =IF(AND(I22<>"",J22<>"",G22<>"",H22<>""),VLOOKUP(I22,'1-專案資訊'!A25:I33,4,0)*(G22/1000+VLOOKUP(I22,'1-專案資訊'!A25:I33,8,0)/100)*J22*H22,0) | P22: =IF(AND(K22<>"",L22<>"",E22<>"",F22<>"",G22<>"",H22<>""),VLOOKUP(K22,'1-專案資訊'!A25:I33,4,0)*(2*((E22+F22)/1000-0.08)+2*VLOOKUP(K22,'1-專案資訊'!A25:I33,9,0)/100)*(G22/L22+1)*H22,0) | Q22: =IF(AND(K22<>"",M22>0,L22<>"",E22<>"",G22<>"",H22<>""),VLOOKUP(K22,'1-專案資訊'!A25:I33,4,0)*(MAX(E22,F22)/1000-0.08+2*VLOOKUP(K22,'1-專案資訊'!A25:I33,9,0)/100)*M22*(G22/L22+1)*H22,0) | R22: =IF(AND(E22<>"",F22<>"",G22<>"",H22<>""),2*(E22+F22)*G22/1000000*H22,0) | S22: =IF(AND(I22<>"",J22<>"",G22<>"",H22<>""),ROUNDUP((G22/1000+VLOOKUP(I22,'1-專案資訊'!A25:I33,8,0)/100)/$B$3,0)*J22*H22,0) | T22: =IF(AND(S22>0,I22<>""),S22*VLOOKUP(I22,'1-專案資訊'!A25:I33,8,0)/100,0) | U22: =IF(OR(I22="#3 (D10)",I22="#4 (D13)",I22="#5 (D16)"),O22,0)+IF(OR(K22="#3 (D10)",K22="#4 (D13)",K22="#5 (D16)"),P22,0)+IF(OR(K22="#3 (D10)",K22="#4 (D13)",K22="#5 (D16)"),Q22,0) | V22: =IF(AND(I22<>"",I22<>"#3 (D10)",I22<>"#4 (D13)",I22<>"#5 (D16)"),O22,0)+IF(AND(K22<>"",K22<>"#3 (D10)",K22<>"#4 (D13)",K22<>"#5 (D16)"),P22,0)+IF(AND(K22<>"",K22<>"#3 (D10)",K22<>"#4 (D13)",K22<>"#5 (D16)"),Q22,0)
A23: 19 | N23: =IF(AND(E23<>"",F23<>"",G23<>"",H23<>""),E23*F23*G23/1000000000*H23,0) | O23: =IF(AND(I23<>"",J23<>"",G23<>"",H23<>""),VLOOKUP(I23,'1-專案資訊'!A25:I33,4,0)*(G23/1000+VLOOKUP(I23,'1-專案資訊'!A25:I33,8,0)/100)*J23*H23,0) | P23: =IF(AND(K23<>"",L23<>"",E23<>"",F23<>"",G23<>"",H23<>""),VLOOKUP(K23,'1-專案資訊'!A25:I33,4,0)*(2*((E23+F23)/1000-0.08)+2*VLOOKUP(K23,'1-專案資訊'!A25:I33,9,0)/100)*(G23/L23+1)*H23,0) | Q23: =IF(AND(K23<>"",M23>0,L23<>"",E23<>"",G23<>"",H23<>""),VLOOKUP(K23,'1-專案資訊'!A25:I33,4,0)*(MAX(E23,F23)/1000-0.08+2*VLOOKUP(K23,'1-專案資訊'!A25:I33,9,0)/100)*M23*(G23/L23+1)*H23,0) | R23: =IF(AND(E23<>"",F23<>"",G23<>"",H23<>""),2*(E23+F23)*G23/1000000*H23,0) | S23: =IF(AND(I23<>"",J23<>"",G23<>"",H23<>""),ROUNDUP((G23/1000+VLOOKUP(I23,'1-專案資訊'!A25:I33,8,0)/100)/$B$3,0)*J23*H23,0) | T23: =IF(AND(S23>0,I23<>""),S23*VLOOKUP(I23,'1-專案資訊'!A25:I33,8,0)/100,0) | U23: =IF(OR(I23="#3 (D10)",I23="#4 (D13)",I23="#5 (D16)"),O23,0)+IF(OR(K23="#3 (D10)",K23="#4 (D13)",K23="#5 (D16)"),P23,0)+IF(OR(K23="#3 (D10)",K23="#4 (D13)",K23="#5 (D16)"),Q23,0) | V23: =IF(AND(I23<>"",I23<>"#3 (D10)",I23<>"#4 (D13)",I23<>"#5 (D16)"),O23,0)+IF(AND(K23<>"",K23<>"#3 (D10)",K23<>"#4 (D13)",K23<>"#5 (D16)"),P23,0)+IF(AND(K23<>"",K23<>"#3 (D10)",K23<>"#4 (D13)",K23<>"#5 (D16)"),Q23,0)
A24: 20 | N24: =IF(AND(E24<>"",F24<>"",G24<>"",H24<>""),E24*F24*G24/1000000000*H24,0) | O24: =IF(AND(I24<>"",J24<>"",G24<>"",H24<>""),VLOOKUP(I24,'1-專案資訊'!A25:I33,4,0)*(G24/1000+VLOOKUP(I24,'1-專案資訊'!A25:I33,8,0)/100)*J24*H24,0) | P24: =IF(AND(K24<>"",L24<>"",E24<>"",F24<>"",G24<>"",H24<>""),VLOOKUP(K24,'1-專案資訊'!A25:I33,4,0)*(2*((E24+F24)/1000-0.08)+2*VLOOKUP(K24,'1-專案資訊'!A25:I33,9,0)/100)*(G24/L24+1)*H24,0) | Q24: =IF(AND(K24<>"",M24>0,L24<>"",E24<>"",G24<>"",H24<>""),VLOOKUP(K24,'1-專案資訊'!A25:I33,4,0)*(MAX(E24,F24)/1000-0.08+2*VLOOKUP(K24,'1-專案資訊'!A25:I33,9,0)/100)*M24*(G24/L24+1)*H24,0) | R24: =IF(AND(E24<>"",F24<>"",G24<>"",H24<>""),2*(E24+F24)*G24/1000000*H24,0) | S24: =IF(AND(I24<>"",J24<>"",G24<>"",H24<>""),ROUNDUP((G24/1000+VLOOKUP(I24,'1-專案資訊'!A25:I33,8,0)/100)/$B$3,0)*J24*H24,0) | T24: =IF(AND(S24>0,I24<>""),S24*VLOOKUP(I24,'1-專案資訊'!A25:I33,8,0)/100,0) | U24: =IF(OR(I24="#3 (D10)",I24="#4 (D13)",I24="#5 (D16)"),O24,0)+IF(OR(K24="#3 (D10)",K24="#4 (D13)",K24="#5 (D16)"),P24,0)+IF(OR(K24="#3 (D10)",K24="#4 (D13)",K24="#5 (D16)"),Q24,0) | V24: =IF(AND(I24<>"",I24<>"#3 (D10)",I24<>"#4 (D13)",I24<>"#5 (D16)"),O24,0)+IF(AND(K24<>"",K24<>"#3 (D10)",K24<>"#4 (D13)",K24<>"#5 (D16)"),P24,0)+IF(AND(K24<>"",K24<>"#3 (D10)",K24<>"#4 (D13)",K24<>"#5 (D16)"),Q24,0)
A25: 21 | N25: =IF(AND(E25<>"",F25<>"",G25<>"",H25<>""),E25*F25*G25/1000000000*H25,0) | O25: =IF(AND(I25<>"",J25<>"",G25<>"",H25<>""),VLOOKUP(I25,'1-專案資訊'!A25:I33,4,0)*(G25/1000+VLOOKUP(I25,'1-專案資訊'!A25:I33,8,0)/100)*J25*H25,0) | P25: =IF(AND(K25<>"",L25<>"",E25<>"",F25<>"",G25<>"",H25<>""),VLOOKUP(K25,'1-專案資訊'!A25:I33,4,0)*(2*((E25+F25)/1000-0.08)+2*VLOOKUP(K25,'1-專案資訊'!A25:I33,9,0)/100)*(G25/L25+1)*H25,0) | Q25: =IF(AND(K25<>"",M25>0,L25<>"",E25<>"",G25<>"",H25<>""),VLOOKUP(K25,'1-專案資訊'!A25:I33,4,0)*(MAX(E25,F25)/1000-0.08+2*VLOOKUP(K25,'1-專案資訊'!A25:I33,9,0)/100)*M25*(G25/L25+1)*H25,0) | R25: =IF(AND(E25<>"",F25<>"",G25<>"",H25<>""),2*(E25+F25)*G25/1000000*H25,0) | S25: =IF(AND(I25<>"",J25<>"",G25<>"",H25<>""),ROUNDUP((G25/1000+VLOOKUP(I25,'1-專案資訊'!A25:I33,8,0)/100)/$B$3,0)*J25*H25,0) | T25: =IF(AND(S25>0,I25<>""),S25*VLOOKUP(I25,'1-專案資訊'!A25:I33,8,0)/100,0) | U25: =IF(OR(I25="#3 (D10)",I25="#4 (D13)",I25="#5 (D16)"),O25,0)+IF(OR(K25="#3 (D10)",K25="#4 (D13)",K25="#5 (D16)"),P25,0)+IF(OR(K25="#3 (D10)",K25="#4 (D13)",K25="#5 (D16)"),Q25,0) | V25: =IF(AND(I25<>"",I25<>"#3 (D10)",I25<>"#4 (D13)",I25<>"#5 (D16)"),O25,0)+IF(AND(K25<>"",K25<>"#3 (D10)",K25<>"#4 (D13)",K25<>"#5 (D16)"),P25,0)+IF(AND(K25<>"",K25<>"#3 (D10)",K25<>"#4 (D13)",K25<>"#5 (D16)"),Q25,0)
A26: 22 | N26: =IF(AND(E26<>"",F26<>"",G26<>"",H26<>""),E26*F26*G26/1000000000*H26,0) | O26: =IF(AND(I26<>"",J26<>"",G26<>"",H26<>""),VLOOKUP(I26,'1-專案資訊'!A25:I33,4,0)*(G26/1000+VLOOKUP(I26,'1-專案資訊'!A25:I33,8,0)/100)*J26*H26,0) | P26: =IF(AND(K26<>"",L26<>"",E26<>"",F26<>"",G26<>"",H26<>""),VLOOKUP(K26,'1-專案資訊'!A25:I33,4,0)*(2*((E26+F26)/1000-0.08)+2*VLOOKUP(K26,'1-專案資訊'!A25:I33,9,0)/100)*(G26/L26+1)*H26,0) | Q26: =IF(AND(K26<>"",M26>0,L26<>"",E26<>"",G26<>"",H26<>""),VLOOKUP(K26,'1-專案資訊'!A25:I33,4,0)*(MAX(E26,F26)/1000-0.08+2*VLOOKUP(K26,'1-專案資訊'!A25:I33,9,0)/100)*M26*(G26/L26+1)*H26,0) | R26: =IF(AND(E26<>"",F26<>"",G26<>"",H26<>""),2*(E26+F26)*G26/1000000*H26,0) | S26: =IF(AND(I26<>"",J26<>"",G26<>"",H26<>""),ROUNDUP((G26/1000+VLOOKUP(I26,'1-專案資訊'!A25:I33,8,0)/100)/$B$3,0)*J26*H26,0) | T26: =IF(AND(S26>0,I26<>""),S26*VLOOKUP(I26,'1-專案資訊'!A25:I33,8,0)/100,0) | U26: =IF(OR(I26="#3 (D10)",I26="#4 (D13)",I26="#5 (D16)"),O26,0)+IF(OR(K26="#3 (D10)",K26="#4 (D13)",K26="#5 (D16)"),P26,0)+IF(OR(K26="#3 (D10)",K26="#4 (D13)",K26="#5 (D16)"),Q26,0) | V26: =IF(AND(I26<>"",I26<>"#3 (D10)",I26<>"#4 (D13)",I26<>"#5 (D16)"),O26,0)+IF(AND(K26<>"",K26<>"#3 (D10)",K26<>"#4 (D13)",K26<>"#5 (D16)"),P26,0)+IF(AND(K26<>"",K26<>"#3 (D10)",K26<>"#4 (D13)",K26<>"#5 (D16)"),Q26,0)
A27: 23 | N27: =IF(AND(E27<>"",F27<>"",G27<>"",H27<>""),E27*F27*G27/1000000000*H27,0) | O27: =IF(AND(I27<>"",J27<>"",G27<>"",H27<>""),VLOOKUP(I27,'1-專案資訊'!A25:I33,4,0)*(G27/1000+VLOOKUP(I27,'1-專案資訊'!A25:I33,8,0)/100)*J27*H27,0) | P27: =IF(AND(K27<>"",L27<>"",E27<>"",F27<>"",G27<>"",H27<>""),VLOOKUP(K27,'1-專案資訊'!A25:I33,4,0)*(2*((E27+F27)/1000-0.08)+2*VLOOKUP(K27,'1-專案資訊'!A25:I33,9,0)/100)*(G27/L27+1)*H27,0) | Q27: =IF(AND(K27<>"",M27>0,L27<>"",E27<>"",G27<>"",H27<>""),VLOOKUP(K27,'1-專案資訊'!A25:I33,4,0)*(MAX(E27,F27)/1000-0.08+2*VLOOKUP(K27,'1-專案資訊'!A25:I33,9,0)/100)*M27*(G27/L27+1)*H27,0) | R27: =IF(AND(E27<>"",F27<>"",G27<>"",H27<>""),2*(E27+F27)*G27/1000000*H27,0) | S27: =IF(AND(I27<>"",J27<>"",G27<>"",H27<>""),ROUNDUP((G27/1000+VLOOKUP(I27,'1-專案資訊'!A25:I33,8,0)/100)/$B$3,0)*J27*H27,0) | T27: =IF(AND(S27>0,I27<>""),S27*VLOOKUP(I27,'1-專案資訊'!A25:I33,8,0)/100,0) | U27: =IF(OR(I27="#3 (D10)",I27="#4 (D13)",I27="#5 (D16)"),O27,0)+IF(OR(K27="#3 (D10)",K27="#4 (D13)",K27="#5 (D16)"),P27,0)+IF(OR(K27="#3 (D10)",K27="#4 (D13)",K27="#5 (D16)"),Q27,0) | V27: =IF(AND(I27<>"",I27<>"#3 (D10)",I27<>"#4 (D13)",I27<>"#5 (D16)"),O27,0)+IF(AND(K27<>"",K27<>"#3 (D10)",K27<>"#4 (D13)",K27<>"#5 (D16)"),P27,0)+IF(AND(K27<>"",K27<>"#3 (D10)",K27<>"#4 (D13)",K27<>"#5 (D16)"),Q27,0)
A28: 24 | N28: =IF(AND(E28<>"",F28<>"",G28<>"",H28<>""),E28*F28*G28/1000000000*H28,0) | O28: =IF(AND(I28<>"",J28<>"",G28<>"",H28<>""),VLOOKUP(I28,'1-專案資訊'!A25:I33,4,0)*(G28/1000+VLOOKUP(I28,'1-專案資訊'!A25:I33,8,0)/100)*J28*H28,0) | P28: =IF(AND(K28<>"",L28<>"",E28<>"",F28<>"",G28<>"",H28<>""),VLOOKUP(K28,'1-專案資訊'!A25:I33,4,0)*(2*((E28+F28)/1000-0.08)+2*VLOOKUP(K28,'1-專案資訊'!A25:I33,9,0)/100)*(G28/L28+1)*H28,0) | Q28: =IF(AND(K28<>"",M28>0,L28<>"",E28<>"",G28<>"",H28<>""),VLOOKUP(K28,'1-專案資訊'!A25:I33,4,0)*(MAX(E28,F28)/1000-0.08+2*VLOOKUP(K28,'1-專案資訊'!A25:I33,9,0)/100)*M28*(G28/L28+1)*H28,0) | R28: =IF(AND(E28<>"",F28<>"",G28<>"",H28<>""),2*(E28+F28)*G28/1000000*H28,0) | S28: =IF(AND(I28<>"",J28<>"",G28<>"",H28<>""),ROUNDUP((G28/1000+VLOOKUP(I28,'1-專案資訊'!A25:I33,8,0)/100)/$B$3,0)*J28*H28,0) | T28: =IF(AND(S28>0,I28<>""),S28*VLOOKUP(I28,'1-專案資訊'!A25:I33,8,0)/100,0) | U28: =IF(OR(I28="#3 (D10)",I28="#4 (D13)",I28="#5 (D16)"),O28,0)+IF(OR(K28="#3 (D10)",K28="#4 (D13)",K28="#5 (D16)"),P28,0)+IF(OR(K28="#3 (D10)",K28="#4 (D13)",K28="#5 (D16)"),Q28,0) | V28: =IF(AND(I28<>"",I28<>"#3 (D10)",I28<>"#4 (D13)",I28<>"#5 (D16)"),O28,0)+IF(AND(K28<>"",K28<>"#3 (D10)",K28<>"#4 (D13)",K28<>"#5 (D16)"),P28,0)+IF(AND(K28<>"",K28<>"#3 (D10)",K28<>"#4 (D13)",K28<>"#5 (D16)"),Q28,0)
A29: 25 | N29: =IF(AND(E29<>"",F29<>"",G29<>"",H29<>""),E29*F29*G29/1000000000*H29,0) | O29: =IF(AND(I29<>"",J29<>"",G29<>"",H29<>""),VLOOKUP(I29,'1-專案資訊'!A25:I33,4,0)*(G29/1000+VLOOKUP(I29,'1-專案資訊'!A25:I33,8,0)/100)*J29*H29,0) | P29: =IF(AND(K29<>"",L29<>"",E29<>"",F29<>"",G29<>"",H29<>""),VLOOKUP(K29,'1-專案資訊'!A25:I33,4,0)*(2*((E29+F29)/1000-0.08)+2*VLOOKUP(K29,'1-專案資訊'!A25:I33,9,0)/100)*(G29/L29+1)*H29,0) | Q29: =IF(AND(K29<>"",M29>0,L29<>"",E29<>"",G29<>"",H29<>""),VLOOKUP(K29,'1-專案資訊'!A25:I33,4,0)*(MAX(E29,F29)/1000-0.08+2*VLOOKUP(K29,'1-專案資訊'!A25:I33,9,0)/100)*M29*(G29/L29+1)*H29,0) | R29: =IF(AND(E29<>"",F29<>"",G29<>"",H29<>""),2*(E29+F29)*G29/1000000*H29,0) | S29: =IF(AND(I29<>"",J29<>"",G29<>"",H29<>""),ROUNDUP((G29/1000+VLOOKUP(I29,'1-專案資訊'!A25:I33,8,0)/100)/$B$3,0)*J29*H29,0) | T29: =IF(AND(S29>0,I29<>""),S29*VLOOKUP(I29,'1-專案資訊'!A25:I33,8,0)/100,0) | U29: =IF(OR(I29="#3 (D10)",I29="#4 (D13)",I29="#5 (D16)"),O29,0)+IF(OR(K29="#3 (D10)",K29="#4 (D13)",K29="#5 (D16)"),P29,0)+IF(OR(K29="#3 (D10)",K29="#4 (D13)",K29="#5 (D16)"),Q29,0) | V29: =IF(AND(I29<>"",I29<>"#3 (D10)",I29<>"#4 (D13)",I29<>"#5 (D16)"),O29,0)+IF(AND(K29<>"",K29<>"#3 (D10)",K29<>"#4 (D13)",K29<>"#5 (D16)"),P29,0)+IF(AND(K29<>"",K29<>"#3 (D10)",K29<>"#4 (D13)",K29<>"#5 (D16)"),Q29,0)
A30: 26 | N30: =IF(AND(E30<>"",F30<>"",G30<>"",H30<>""),E30*F30*G30/1000000000*H30,0) | O30: =IF(AND(I30<>"",J30<>"",G30<>"",H30<>""),VLOOKUP(I30,'1-專案資訊'!A25:I33,4,0)*(G30/1000+VLOOKUP(I30,'1-專案資訊'!A25:I33,8,0)/100)*J30*H30,0) | P30: =IF(AND(K30<>"",L30<>"",E30<>"",F30<>"",G30<>"",H30<>""),VLOOKUP(K30,'1-專案資訊'!A25:I33,4,0)*(2*((E30+F30)/1000-0.08)+2*VLOOKUP(K30,'1-專案資訊'!A25:I33,9,0)/100)*(G30/L30+1)*H30,0) | Q30: =IF(AND(K30<>"",M30>0,L30<>"",E30<>"",G30<>"",H30<>""),VLOOKUP(K30,'1-專案資訊'!A25:I33,4,0)*(MAX(E30,F30)/1000-0.08+2*VLOOKUP(K30,'1-專案資訊'!A25:I33,9,0)/100)*M30*(G30/L30+1)*H30,0) | R30: =IF(AND(E30<>"",F30<>"",G30<>"",H30<>""),2*(E30+F30)*G30/1000000*H30,0) | S30: =IF(AND(I30<>"",J30<>"",G30<>"",H30<>""),ROUNDUP((G30/1000+VLOOKUP(I30,'1-專案資訊'!A25:I33,8,0)/100)/$B$3,0)*J30*H30,0) | T30: =IF(AND(S30>0,I30<>""),S30*VLOOKUP(I30,'1-專案資訊'!A25:I33,8,0)/100,0) | U30: =IF(OR(I30="#3 (D10)",I30="#4 (D13)",I30="#5 (D16)"),O30,0)+IF(OR(K30="#3 (D10)",K30="#4 (D13)",K30="#5 (D16)"),P30,0)+IF(OR(K30="#3 (D10)",K30="#4 (D13)",K30="#5 (D16)"),Q30,0) | V30: =IF(AND(I30<>"",I30<>"#3 (D10)",I30<>"#4 (D13)",I30<>"#5 (D16)"),O30,0)+IF(AND(K30<>"",K30<>"#3 (D10)",K30<>"#4 (D13)",K30<>"#5 (D16)"),P30,0)+IF(AND(K30<>"",K30<>"#3 (D10)",K30<>"#4 (D13)",K30<>"#5 (D16)"),Q30,0)
A31: 27 | N31: =IF(AND(E31<>"",F31<>"",G31<>"",H31<>""),E31*F31*G31/1000000000*H31,0) | O31: =IF(AND(I31<>"",J31<>"",G31<>"",H31<>""),VLOOKUP(I31,'1-專案資訊'!A25:I33,4,0)*(G31/1000+VLOOKUP(I31,'1-專案資訊'!A25:I33,8,0)/100)*J31*H31,0) | P31: =IF(AND(K31<>"",L31<>"",E31<>"",F31<>"",G31<>"",H31<>""),VLOOKUP(K31,'1-專案資訊'!A25:I33,4,0)*(2*((E31+F31)/1000-0.08)+2*VLOOKUP(K31,'1-專案資訊'!A25:I33,9,0)/100)*(G31/L31+1)*H31,0) | Q31: =IF(AND(K31<>"",M31>0,L31<>"",E31<>"",G31<>"",H31<>""),VLOOKUP(K31,'1-專案資訊'!A25:I33,4,0)*(MAX(E31,F31)/1000-0.08+2*VLOOKUP(K31,'1-專案資訊'!A25:I33,9,0)/100)*M31*(G31/L31+1)*H31,0) | R31: =IF(AND(E31<>"",F31<>"",G31<>"",H31<>""),2*(E31+F31)*G31/1000000*H31,0) | S31: =IF(AND(I31<>"",J31<>"",G31<>"",H31<>""),ROUNDUP((G31/1000+VLOOKUP(I31,'1-專案資訊'!A25:I33,8,0)/100)/$B$3,0)*J31*H31,0) | T31: =IF(AND(S31>0,I31<>""),S31*VLOOKUP(I31,'1-專案資訊'!A25:I33,8,0)/100,0) | U31: =IF(OR(I31="#3 (D10)",I31="#4 (D13)",I31="#5 (D16)"),O31,0)+IF(OR(K31="#3 (D10)",K31="#4 (D13)",K31="#5 (D16)"),P31,0)+IF(OR(K31="#3 (D10)",K31="#4 (D13)",K31="#5 (D16)"),Q31,0) | V31: =IF(AND(I31<>"",I31<>"#3 (D10)",I31<>"#4 (D13)",I31<>"#5 (D16)"),O31,0)+IF(AND(K31<>"",K31<>"#3 (D10)",K31<>"#4 (D13)",K31<>"#5 (D16)"),P31,0)+IF(AND(K31<>"",K31<>"#3 (D10)",K31<>"#4 (D13)",K31<>"#5 (D16)"),Q31,0)
A32: 28 | N32: =IF(AND(E32<>"",F32<>"",G32<>"",H32<>""),E32*F32*G32/1000000000*H32,0) | O32: =IF(AND(I32<>"",J32<>"",G32<>"",H32<>""),VLOOKUP(I32,'1-專案資訊'!A25:I33,4,0)*(G32/1000+VLOOKUP(I32,'1-專案資訊'!A25:I33,8,0)/100)*J32*H32,0) | P32: =IF(AND(K32<>"",L32<>"",E32<>"",F32<>"",G32<>"",H32<>""),VLOOKUP(K32,'1-專案資訊'!A25:I33,4,0)*(2*((E32+F32)/1000-0.08)+2*VLOOKUP(K32,'1-專案資訊'!A25:I33,9,0)/100)*(G32/L32+1)*H32,0) | Q32: =IF(AND(K32<>"",M32>0,L32<>"",E32<>"",G32<>"",H32<>""),VLOOKUP(K32,'1-專案資訊'!A25:I33,4,0)*(MAX(E32,F32)/1000-0.08+2*VLOOKUP(K32,'1-專案資訊'!A25:I33,9,0)/100)*M32*(G32/L32+1)*H32,0) | R32: =IF(AND(E32<>"",F32<>"",G32<>"",H32<>""),2*(E32+F32)*G32/1000000*H32,0) | S32: =IF(AND(I32<>"",J32<>"",G32<>"",H32<>""),ROUNDUP((G32/1000+VLOOKUP(I32,'1-專案資訊'!A25:I33,8,0)/100)/$B$3,0)*J32*H32,0) | T32: =IF(AND(S32>0,I32<>""),S32*VLOOKUP(I32,'1-專案資訊'!A25:I33,8,0)/100,0) | U32: =IF(OR(I32="#3 (D10)",I32="#4 (D13)",I32="#5 (D16)"),O32,0)+IF(OR(K32="#3 (D10)",K32="#4 (D13)",K32="#5 (D16)"),P32,0)+IF(OR(K32="#3 (D10)",K32="#4 (D13)",K32="#5 (D16)"),Q32,0) | V32: =IF(AND(I32<>"",I32<>"#3 (D10)",I32<>"#4 (D13)",I32<>"#5 (D16)"),O32,0)+IF(AND(K32<>"",K32<>"#3 (D10)",K32<>"#4 (D13)",K32<>"#5 (D16)"),P32,0)+IF(AND(K32<>"",K32<>"#3 (D10)",K32<>"#4 (D13)",K32<>"#5 (D16)"),Q32,0)
A33: 29 | N33: =IF(AND(E33<>"",F33<>"",G33<>"",H33<>""),E33*F33*G33/1000000000*H33,0) | O33: =IF(AND(I33<>"",J33<>"",G33<>"",H33<>""),VLOOKUP(I33,'1-專案資訊'!A25:I33,4,0)*(G33/1000+VLOOKUP(I33,'1-專案資訊'!A25:I33,8,0)/100)*J33*H33,0) | P33: =IF(AND(K33<>"",L33<>"",E33<>"",F33<>"",G33<>"",H33<>""),VLOOKUP(K33,'1-專案資訊'!A25:I33,4,0)*(2*((E33+F33)/1000-0.08)+2*VLOOKUP(K33,'1-專案資訊'!A25:I33,9,0)/100)*(G33/L33+1)*H33,0) | Q33: =IF(AND(K33<>"",M33>0,L33<>"",E33<>"",G33<>"",H33<>""),VLOOKUP(K33,'1-專案資訊'!A25:I33,4,0)*(MAX(E33,F33)/1000-0.08+2*VLOOKUP(K33,'1-專案資訊'!A25:I33,9,0)/100)*M33*(G33/L33+1)*H33,0) | R33: =IF(AND(E33<>"",F33<>"",G33<>"",H33<>""),2*(E33+F33)*G33/1000000*H33,0) | S33: =IF(AND(I33<>"",J33<>"",G33<>"",H33<>""),ROUNDUP((G33/1000+VLOOKUP(I33,'1-專案資訊'!A25:I33,8,0)/100)/$B$3,0)*J33*H33,0) | T33: =IF(AND(S33>0,I33<>""),S33*VLOOKUP(I33,'1-專案資訊'!A25:I33,8,0)/100,0) | U33: =IF(OR(I33="#3 (D10)",I33="#4 (D13)",I33="#5 (D16)"),O33,0)+IF(OR(K33="#3 (D10)",K33="#4 (D13)",K33="#5 (D16)"),P33,0)+IF(OR(K33="#3 (D10)",K33="#4 (D13)",K33="#5 (D16)"),Q33,0) | V33: =IF(AND(I33<>"",I33<>"#3 (D10)",I33<>"#4 (D13)",I33<>"#5 (D16)"),O33,0)+IF(AND(K33<>"",K33<>"#3 (D10)",K33<>"#4 (D13)",K33<>"#5 (D16)"),P33,0)+IF(AND(K33<>"",K33<>"#3 (D10)",K33<>"#4 (D13)",K33<>"#5 (D16)"),Q33,0)
A34: 30 | N34: =IF(AND(E34<>"",F34<>"",G34<>"",H34<>""),E34*F34*G34/1000000000*H34,0) | O34: =IF(AND(I34<>"",J34<>"",G34<>"",H34<>""),VLOOKUP(I34,'1-專案資訊'!A25:I33,4,0)*(G34/1000+VLOOKUP(I34,'1-專案資訊'!A25:I33,8,0)/100)*J34*H34,0) | P34: =IF(AND(K34<>"",L34<>"",E34<>"",F34<>"",G34<>"",H34<>""),VLOOKUP(K34,'1-專案資訊'!A25:I33,4,0)*(2*((E34+F34)/1000-0.08)+2*VLOOKUP(K34,'1-專案資訊'!A25:I33,9,0)/100)*(G34/L34+1)*H34,0) | Q34: =IF(AND(K34<>"",M34>0,L34<>"",E34<>"",G34<>"",H34<>""),VLOOKUP(K34,'1-專案資訊'!A25:I33,4,0)*(MAX(E34,F34)/1000-0.08+2*VLOOKUP(K34,'1-專案資訊'!A25:I33,9,0)/100)*M34*(G34/L34+1)*H34,0) | R34: =IF(AND(E34<>"",F34<>"",G34<>"",H34<>""),2*(E34+F34)*G34/1000000*H34,0) | S34: =IF(AND(I34<>"",J34<>"",G34<>"",H34<>""),ROUNDUP((G34/1000+VLOOKUP(I34,'1-專案資訊'!A25:I33,8,0)/100)/$B$3,0)*J34*H34,0) | T34: =IF(AND(S34>0,I34<>""),S34*VLOOKUP(I34,'1-專案資訊'!A25:I33,8,0)/100,0) | U34: =IF(OR(I34="#3 (D10)",I34="#4 (D13)",I34="#5 (D16)"),O34,0)+IF(OR(K34="#3 (D10)",K34="#4 (D13)",K34="#5 (D16)"),P34,0)+IF(OR(K34="#3 (D10)",K34="#4 (D13)",K34="#5 (D16)"),Q34,0) | V34: =IF(AND(I34<>"",I34<>"#3 (D10)",I34<>"#4 (D13)",I34<>"#5 (D16)"),O34,0)+IF(AND(K34<>"",K34<>"#3 (D10)",K34<>"#4 (D13)",K34<>"#5 (D16)"),P34,0)+IF(AND(K34<>"",K34<>"#3 (D10)",K34<>"#4 (D13)",K34<>"#5 (D16)"),Q34,0)
B35: 合計 | N35: =SUM(N5:N34) | O35: =SUM(O5:O34) | P35: =SUM(P5:P34) | Q35: =SUM(Q5:Q34) | R35: =SUM(R5:R34) | S35: =SUM(S5:S34) | T35: =SUM(T5:T34) | U35: =SUM(U5:U34) | V35: =SUM(V5:V34)

Sheet 4-梁
A1: 梁 數量計算表
A2: 上下筋含搭接40D。箍筋含12D彎鉤，分密疏區。
A3: 預設鋼筋長度 (m): | B3: 6 | C3: ← 可調整
A4: No | B4: 樓層 | C4: 梁編號 | D4: ▼型式 | E4: B (mm) | F4: D (mm) | G4: L (mm) | H4: 數量 | I4: ▼上筋 | J4: 上支 | K4: ▼下筋 | L4: 下支 | M4: ▼箍筋 | N4: 密箍 (mm) | O4: 疏箍 (mm) | P4: 腰筋 | Q4: 混凝土 (m3) | R4: 上筋重 (kg) | S4: 下筋重 (kg) | T4: 箍筋重 (kg) | U4: 模板 (m2) | V4: 搭接次數 | W4: 搭接長度 (m) | X4: SD280 (kg) | Y4: SD420 (kg)
A5: 1 | Q5: =IF(AND(E5<>"",F5<>"",G5<>"",H5<>""),E5*F5*G5/1000000000*H5,0) | R5: =IF(AND(I5<>"",J5<>"",G5<>"",H5<>""),VLOOKUP(I5,'1-專案資訊'!A25:I33,4,0)*(G5/1000+2*VLOOKUP(I5,'1-專案資訊'!A25:I33,8,0)/100)*J5*H5,0) | S5: =IF(AND(K5<>"",L5<>"",G5<>"",H5<>""),VLOOKUP(K5,'1-專案資訊'!A25:I33,4,0)*(G5/1000+2*VLOOKUP(K5,'1-專案資訊'!A25:I33,8,0)/100)*L5*H5,0) | T5: =IF(AND(M5<>"",N5<>"",O5<>"",E5<>"",F5<>"",G5<>"",H5<>""),VLOOKUP(M5,'1-專案資訊'!A25:I33,4,0)*(2*((E5+F5)/1000-0.08)+2*VLOOKUP(M5,'1-專案資訊'!A25:I33,9,0)/100)*((G5*0.4/N5)+(G5*0.6/O5)+2)*H5,0) | U5: =IF(AND(E5<>"",F5<>"",G5<>"",H5<>""),(2*F5+E5)*G5/1000000*H5,0) | V5: =IF(AND(I5<>"",J5<>"",G5<>"",H5<>""),(ROUNDUP((G5/1000+2*VLOOKUP(I5,'1-專案資訊'!A25:I33,8,0)/100)/$B$3,0)-1)*(J5+L5)*H5,0) | W5: =IF(AND(V5>0,I5<>""),V5*VLOOKUP(I5,'1-專案資訊'!A25:I33,8,0)/100,0) | X5: =IF(OR(I5="#3 (D10)",I5="#4 (D13)",I5="#5 (D16)"),R5,0)+IF(OR(K5="#3 (D10)",K5="#4 (D13)",K5="#5 (D16)"),S5,0)+IF(OR(M5="#3 (D10)",M5="#4 (D13)",M5="#5 (D16)"),T5,0) | Y5: =IF(AND(I5<>"",I5<>"#3 (D10)",I5<>"#4 (D13)",I5<>"#5 (D16)"),R5,0)+IF(AND(K5<>"",K5<>"#3 (D10)",K5<>"#4 (D13)",K5<>"#5 (D16)"),S5,0)+IF(AND(M5<>"",M5<>"#3 (D10)",M5<>"#4 (D13)",M5<>"#5 (D16)"),T5,0)
A6: 2 | Q6: =IF(AND(E6<>"",F6<>"",G6<>"",H6<>""),E6*F6*G6/1000000000*H6,0) | R6: =IF(AND(I6<>"",J6<>"",G6<>"",H6<>""),VLOOKUP(I6,'1-專案資訊'!A25:I33,4,0)*(G6/1000+2*VLOOKUP(I6,'1-專案資訊'!A25:I33,8,0)/100)*J6*H6,0) | S6: =IF(AND(K6<>"",L6<>"",G6<>"",H6<>""),VLOOKUP(K6,'1-專案資訊'!A25:I33,4,0)*(G6/1000+2*VLOOKUP(K6,'1-專案資訊'!A25:I33,8,0)/100)*L6*H6,0) | T6: =IF(AND(M6<>"",N6<>"",O6<>"",E6<>"",F6<>"",G6<>"",H6<>""),VLOOKUP(M6,'1-專案資訊'!A25:I33,4,0)*(2*((E6+F6)/1000-0.08)+2*VLOOKUP(M6,'1-專案資訊'!A25:I33,9,0)/100)*((G6*0.4/N6)+(G6*0.6/O6)+2)*H6,0) | U6: =IF(AND(E6<>"",F6<>"",G6<>"",H6<>""),(2*F6+E6)*G6/1000000*H6,0) | V6: =IF(AND(I6<>"",J6<>"",G6<>"",H6<>""),(ROUNDUP((G6/1000+2*VLOOKUP(I6,'1-專案資訊'!A25:I33,8,0)/100)/$B$3,0)-1)*(J6+L6)*H6,0) | W6: =IF(AND(V6>0,I6<>""),V6*VLOOKUP(I6,'1-專案資訊'!A25:I33,8,0)/100,0) | X6: =IF(OR(I6="#3 (D10)",I6="#4 (D13)",I6="#5 (D16)"),R6,0)+IF(OR(K6="#3 (D10)",K6="#4 (D13)",K6="#5 (D16)"),S6,0)+IF(OR(M6="#3 (D10)",M6="#4 (D13)",M6="#5 (D16)"),T6,0) | Y6: =IF(AND(I6<>"",I6<>"#3 (D10)",I6<>"#4 (D13)",I6<>"#5 (D16)"),R6,0)+IF(AND(K6<>"",K6<>"#3 (D10)",K6<>"#4 (D13)",K6<>"#5 (D16)"),S6,0)+IF(AND(M6<>"",M6<>"#3 (D10)",M6<>"#4 (D13)",M6<>"#5 (D16)"),T6,0)
A7: 3 | Q7: =IF(AND(E7<>"",F7<>"",G7<>"",H7<>""),E7*F7*G7/1000000000*H7,0) | R7: =IF(AND(I7<>"",J7<>"",G7<>"",H7<>""),VLOOKUP(I7,'1-專案資訊'!A25:I33,4,0)*(G7/1000+2*VLOOKUP(I7,'1-專案資訊'!A25:I33,8,0)/100)*J7*H7,0) | S7: =IF(AND(K7<>"",L7<>"",G7<>"",H7<>""),VLOOKUP(K7,'1-專案資訊'!A25:I33,4,0)*(G7/1000+2*VLOOKUP(K7,'1-專案資訊'!A25:I33,8,0)/100)*L7*H7,0) | T7: =IF(AND(M7<>"",N7<>"",O7<>"",E7<>"",F7<>"",G7<>"",H7<>""),VLOOKUP(M7,'1-專案資訊'!A25:I33,4,0)*(2*((E7+F7)/1000-0.08)+2*VLOOKUP(M7,'1-專案資訊'!A25:I33,9,0)/100)*((G7*0.4/N7)+(G7*0.6/O7)+2)*H7,0) | U7: =IF(AND(E7<>"",F7<>"",G7<>"",H7<>""),(2*F7+E7)*G7/1000000*H7,0) | V7: =IF(AND(I7<>"",J7<>"",G7<>"",H7<>""),(ROUNDUP((G7/1000+2*VLOOKUP(I7,'1-專案資訊'!A25:I33,8,0)/100)/$B$3,0)-1)*(J7+L7)*H7,0) | W7: =IF(AND(V7>0,I7<>""),V7*VLOOKUP(I7,'1-專案資訊'!A25:I33,8,0)/100,0) | X7: =IF(OR(I7="#3 (D10)",I7="#4 (D13)",I7="#5 (D16)"),R7,0)+IF(OR(K7="#3 (D10)",K7="#4 (D13)",K7="#5 (D16)"),S7,0)+IF(OR(M7="#3 (D10)",M7="#4 (D13)",M7="#5 (D16)"),T7,0) | Y7: =IF(AND(I7<>"",I7<>"#3 (D10)",I7<>"#4 (D13)",I7<>"#5 (D16)"),R7,0)+IF(AND(K7<>"",K7<>"#3 (D10)",K7<>"#4 (D13)",K7<>"#5 (D16)"),S7,0)+IF(AND(M7<>"",M7<>"#3 (D10)",M7<>"#4 (D13)",M7<>"#5 (D16)"),T7,0)
A8: 4 | Q8: =IF(AND(E8<>"",F8<>"",G8<>"",H8<>""),E8*F8*G8/1000000000*H8,0) | R8: =IF(AND(I8<>"",J8<>"",G8<>"",H8<>""),VLOOKUP(I8,'1-專案資訊'!A25:I33,4,0)*(G8/1000+2*VLOOKUP(I8,'1-專案資訊'!A25:I33,8,0)/100)*J8*H8,0) | S8: =IF(AND(K8<>"",L8<>"",G8<>"",H8<>""),VLOOKUP(K8,'1-專案資訊'!A25:I33,4,0)*(G8/1000+2*VLOOKUP(K8,'1-專案資訊'!A25:I33,8,0)/100)*L8*H8,0) | T8: =IF(AND(M8<>"",N8<>"",O8<>"",E8<>"",F8<>"",G8<>"",H8<>""),VLOOKUP(M8,'1-專案資訊'!A25:I33,4,0)*(2*((E8+F8)/1000-0.08)+2*VLOOKUP(M8,'1-專案資訊'!A25:I33,9,0)/100)*((G8*0.4/N8)+(G8*0.6/O8)+2)*H8,0) | U8: =IF(AND(E8<>"",F8<>"",G8<>"",H8<>""),(2*F8+E8)*G8/1000000*H8,0) | V8: =IF(AND(I8<>"",J8<>"",G8<>"",H8<>""),(ROUNDUP((G8/1000+2*VLOOKUP(I8,'1-專案資訊'!A25:I33,8,0)/100)/$B$3,0)-1)*(J8+L8)*H8,0) | W8: =IF(AND(V8>0,I8<>""),V8*VLOOKUP(I8,'1-專案資訊'!A25:I33,8,0)/100,0) | X8: =IF(OR(I8="#3 (D10)",I8="#4 (D13)",I8="#5 (D16)"),R8,0)+IF(OR(K8="#3 (D10)",K8="#4 (D13)",K8="#5 (D16)"),S8,0)+IF(OR(M8="#3 (D10)",M8="#4 (D13)",M8="#5 (D16)"),T8,0) | Y8: =IF(AND(I8<>"",I8<>"#3 (D10)",I8<>"#4 (D13)",I8<>"#5 (D16)"),R8,0)+IF(AND(K8<>"",K8<>"#3 (D10)",K8<>"#4 (D13)",K8<>"#5 (D16)"),S8,0)+IF(AND(M8<>"",M8<>"#3 (D10)",M8<>"#4 (D13)",M8<>"#5 (D16)"),T8,0)
A9: 5 | Q9: =IF(AND(E9<>"",F9<>"",G9<>"",H9<>""),E9*F9*G9/1000000000*H9,0) | R9: =IF(AND(I9<>"",J9<>"",G9<>"",H9<>""),VLOOKUP(I9,'1-專案資訊'!A25:I33,4,0)*(G9/1000+2*VLOOKUP(I9,'1-專案資訊'!A25:I33,8,0)/100)*J9*H9,0) | S9: =IF(AND(K9<>"",L9<>"",G9<>"",H9<>""),VLOOKUP(K9,'1-專案資訊'!A25:I33,4,0)*(G9/1000+2*VLOOKUP(K9,'1-專案資訊'!A25:I33,8,0)/100)*L9*H9,0) | T9: =IF(AND(M9<>"",N9<>"",O9<>"",E9<>"",F9<>"",G9<>"",H9<>""),VLOOKUP(M9,'1-專案資訊'!A25:I33,4,0)*(2*((E9+F9)/1000-0.08)+2*VLOOKUP(M9,'1-專案資訊'!A25:I33,9,0)/100)*((G9*0.4/N9)+(G9*0.6/O9)+2)*H9,0) | U9: =IF(AND(E9<>"",F9<>"",G9<>"",H9<>""),(2*F9+E9)*G9/1000000*H9,0) | V9: =IF(AND(I9<>"",J9<>"",G9<>"",H9<>""),(ROUNDUP((G9/1000+2*VLOOKUP(I9,'1-專案資訊'!A25:I33,8,0)/100)/$B$3,0)-1)*(J9+L9)*H9,0) | W9: =IF(AND(V9>0,I9<>""),V9*VLOOKUP(I9,'1-專案資訊'!A25:I33,8,0)/100,0) | X9: =IF(OR(I9="#3 (D10)",I9="#4 (D13)",I9="#5 (D16)"),R9,0)+IF(OR(K9="#3 (D10)",K9="#4 (D13)",K9="#5 (D16)"),S9,0)+IF(OR(M9="#3 (D10)",M9="#4 (D13)",M9="#5 (D16)"),T9,0) | Y9: =IF(AND(I9<>"",I9<>"#3 (D10)",I9<>"#4 (D13)",I9<>"#5 (D16)"),R9,0)+IF(AND(K9<>"",K9<>"#3 (D10)",K9<>"#4 (D13)",K9<>"#5 (D16)"),S9,0)+IF(AND(M9<>"",M9<>"#3 (D10)",M9<>"#4 (D13)",M9<>"#5 (D16)"),T9,0)
A10: 6 | Q10: =IF(AND(E10<>"",F10<>"",G10<>"",H10<>""),E10*F10*G10/1000000000*H10,0) | R10: =IF(AND(I10<>"",J10<>"",G10<>"",H10<>""),VLOOKUP(I10,'1-專案資訊'!A25:I33,4,0)*(G10/1000+2*VLOOKUP(I10,'1-專案資訊'!A25:I33,8,0)/100)*J10*H10,0) | S10: =IF(AND(K10<>"",L10<>"",G10<>"",H10<>""),VLOOKUP(K10,'1-專案資訊'!A25:I33,4,0)*(G10/1000+2*VLOOKUP(K10,'1-專案資訊'!A25:I33,8,0)/100)*L10*H10,0) | T10: =IF(AND(M10<>"",N10<>"",O10<>"",E10<>"",F10<>"",G10<>"",H10<>""),VLOOKUP(M10,'1-專案資訊'!A25:I33,4,0)*(2*((E10+F10)/1000-0.08)+2*VLOOKUP(M10,'1-專案資訊'!A25:I33,9,0)/100)*((G10*0.4/N10)+(G10*0.6/O10)+2)*H10,0) | U10: =IF(AND(E10<>"",F10<>"",G10<>"",H10<>""),(2*F10+E10)*G10/1000000*H10,0) | V10: =IF(AND(I10<>"",J10<>"",G10<>"",H10<>""),(ROUNDUP((G10/1000+2*VLOOKUP(I10,'1-專案資訊'!A25:I33,8,0)/100)/$B$3,0)-1)*(J10+L10)*H10,0) | W10: =IF(AND(V10>0,I10<>""),V10*VLOOKUP(I10,'1-專案資訊'!A25:I33,8,0)/100,0) | X10: =IF(OR(I10="#3 (D10)",I10="#4 (D13)",I10="#5 (D16)"),R10,0)+IF(OR(K10="#3 (D10)",K10="#4 (D13)",K10="#5 (D16)"),S10,0)+IF(OR(M10="#3 (D10)",M10="#4 (D13)",M10="#5 (D16)"),T10,0) | Y10: =IF(AND(I10<>"",I10<>"#3 (D10)",I10<>"#4 (D13)",I10<>"#5 (D16)"),R10,0)+IF(AND(K10<>"",K10<>"#3 (D10)",K10<>"#4 (D13)",K10<>"#5 (D16)"),S10,0)+IF(AND(M10<>"",M10<>"#3 (D10)",M10<>"#4 (D13)",M10<>"#5 (D16)"),T10,0)
A11: 7 | Q11: =IF(AND(E11<>"",F11<>"",G11<>"",H11<>""),E11*F11*G11/1000000000*H11,0) | R11: =IF(AND(I11<>"",J11<>"",G11<>"",H11<>""),VLOOKUP(I11,'1-專案資訊'!A25:I33,4,0)*(G11/1000+2*VLOOKUP(I11,'1-專案資訊'!A25:I33,8,0)/100)*J11*H11,0) | S11: =IF(AND(K11<>"",L11<>"",G11<>"",H11<>""),VLOOKUP(K11,'1-專案資訊'!A25:I33,4,0)*(G11/1000+2*VLOOKUP(K11,'1-專案資訊'!A25:I33,8,0)/100)*L11*H11,0) | T11: =IF(AND(M11<>"",N11<>"",O11<>"",E11<>"",F11<>"",G11<>"",H11<>""),VLOOKUP(M11,'1-專案資訊'!A25:I33,4,0)*(2*((E11+F11)/1000-0.08)+2*VLOOKUP(M11,'1-專案資訊'!A25:I33,9,0)/100)*((G11*0.4/N11)+(G11*0.6/O11)+2)*H11,0) | U11: =IF(AND(E11<>"",F11<>"",G11<>"",H11<>""),(2*F11+E11)*G11/1000000*H11,0) | V11: =IF(AND(I11<>"",J11<>"",G11<>"",H11<>""),(ROUNDUP((G11/1000+2*VLOOKUP(I11,'1-專案資訊'!A25:I33,8,0)/100)/$B$3,0)-1)*(J11+L11)*H11,0) | W11: =IF(AND(V11>0,I11<>""),V11*VLOOKUP(I11,'1-專案資訊'!A25:I33,8,0)/100,0) | X11: =IF(OR(I11="#3 (D10)",I11="#4 (D13)",I11="#5 (D16)"),R11,0)+IF(OR(K11="#3 (D10)",K11="#4 (D13)",K11="#5 (D16)"),S11,0)+IF(OR(M11="#3 (D10)",M11="#4 (D13)",M11="#5 (D16)"),T11,0) | Y11: =IF(AND(I11<>"",I11<>"#3 (D10)",I11<>"#4 (D13)",I11<>"#5 (D16)"),R11,0)+IF(AND(K11<>"",K11<>"#3 (D10)",K11<>"#4 (D13)",K11<>"#5 (D16)"),S11,0)+IF(AND(M11<>"",M11<>"#3 (D10)",M11<>"#4 (D13)",M11<>"#5 (D16)"),T11,0)
A12: 8 | Q12: =IF(AND(E12<>"",F12<>"",G12<>"",H12<>""),E12*F12*G12/1000000000*H12,0) | R12: =IF(AND(I12<>"",J12<>"",G12<>"",H12<>""),VLOOKUP(I12,'1-專案資訊'!A25:I33,4,0)*(G12/1000+2*VLOOKUP(I12,'1-專案資訊'!A25:I33,8,0)/100)*J12*H12,0) | S12: =IF(AND(K12<>"",L12<>"",G12<>"",H12<>""),VLOOKUP(K12,'1-專案資訊'!A25:I33,4,0)*(G12/1000+2*VLOOKUP(K12,'1-專案資訊'!A25:I33,8,0)/100)*L12*H12,0) | T12: =IF(AND(M12<>"",N12<>"",O12<>"",E12<>"",F12<>"",G12<>"",H12<>""),VLOOKUP(M12,'1-專案資訊'!A25:I33,4,0)*(2*((E12+F12)/1000-0.08)+2*VLOOKUP(M12,'1-專案資訊'!A25:I33,9,0)/100)*((G12*0.4/N12)+(G12*0.6/O12)+2)*H12,0) | U12: =IF(AND(E12<>"",F12<>"",G12<>"",H12<>""),(2*F12+E12)*G12/1000000*H12,0) | V12: =IF(AND(I12<>"",J12<>"",G12<>"",H12<>""),(ROUNDUP((G12/1000+2*VLOOKUP(I12,'1-專案資訊'!A25:I33,8,0)/100)/$B$3,0)-1)*(J12+L12)*H12,0) | W12: =IF(AND(V12>0,I12<>""),V12*VLOOKUP(I12,'1-專案資訊'!A25:I33,8,0)/100,0) | X12: =IF(OR(I12="#3 (D10)",I12="#4 (D13)",I12="#5 (D16)"),R12,0)+IF(OR(K12="#3 (D10)",K12="#4 (D13)",K12="#5 (D16)"),S12,0)+IF(OR(M12="#3 (D10)",M12="#4 (D13)",M12="#5 (D16)"),T12,0) | Y12: =IF(AND(I12<>"",I12<>"#3 (D10)",I12<>"#4 (D13)",I12<>"#5 (D16)"),R12,0)+IF(AND(K12<>"",K12<>"#3 (D10)",K12<>"#4 (D13)",K12<>"#5 (D16)"),S12,0)+IF(AND(M12<>"",M12<>"#3 (D10)",M12<>"#4 (D13)",M12<>"#5 (D16)"),T12,0)
A13: 9 | Q13: =IF(AND(E13<>"",F13<>"",G13<>"",H13<>""),E13*F13*G13/1000000000*H13,0) | R13: =IF(AND(I13<>"",J13<>"",G13<>"",H13<>""),VLOOKUP(I13,'1-專案資訊'!A25:I33,4,0)*(G13/1000+2*VLOOKUP(I13,'1-專案資訊'!A25:I33,8,0)/100)*J13*H13,0) | S13: =IF(AND(K13<>"",L13<>"",G13<>"",H13<>""),VLOOKUP(K13,'1-專案資訊'!A25:I33,4,0)*(G13/1000+2*VLOOKUP(K13,'1-專案資訊'!A25:I33,8,0)/100)*L13*H13,0) | T13: =IF(AND(M13<>"",N13<>"",O13<>"",E13<>"",F13<>"",G13<>"",H13<>""),VLOOKUP(M13,'1-專案資訊'!A25:I33,4,0)*(2*((E13+F13)/1000-0.08)+2*VLOOKUP(M13,'1-專案資訊'!A25:I33,9,0)/100)*((G13*0.4/N13)+(G13*0.6/O13)+2)*H13,0) | U13: =IF(AND(E13<>"",F13<>"",G13<>"",H13<>""),(2*F13+E13)*G13/1000000*H13,0) | V13: =IF(AND(I13<>"",J13<>"",G13<>"",H13<>""),(ROUNDUP((G13/1000+2*VLOOKUP(I13,'1-專案資訊'!A25:I33,8,0)/100)/$B$3,0)-1)*(J13+L13)*H13,0) | W13: =IF(AND(V13>0,I13<>""),V13*VLOOKUP(I13,'1-專案資訊'!A25:I33,8,0)/100,0) | X13: =IF(OR(I13="#3 (D10)",I13="#4 (D13)",I13="#5 (D16)"),R13,0)+IF(OR(K13="#3 (D10)",K13="#4 (D13)",K13="#5 (D16)"),S13,0)+IF(OR(M13="#3 (D10)",M13="#4 (D13)",M13="#5 (D16)"),T13,0) | Y13: =IF(AND(I13<>"",I13<>"#3 (D10)",I13<>"#4 (D13)",I13<>"#5 (D16)"),R13,0)+IF(AND(K13<>"",K13<>"#3 (D10)",K13<>"#4 (D13)",K13<>"#5 (D16)"),S13,0)+IF(AND(M13<>"",M13<>"#3 (D10)",M13<>"#4 (D13)",M13<>"#5 (D16)"),T13,0)
A14: 10 | Q14: =IF(AND(E14<>"",F14<>"",G14<>"",H14<>""),E14*F14*G14/1000000000*H14,0) | R14: =IF(AND(I14<>"",J14<>"",G14<>"",H14<>""),VLOOKUP(I14,'1-專案資訊'!A25:I33,4,0)*(G14/1000+2*VLOOKUP(I14,'1-專案資訊'!A25:I33,8,0)/100)*J14*H14,0) | S14: =IF(AND(K14<>"",L14<>"",G14<>"",H14<>""),VLOOKUP(K14,'1-專案資訊'!A25:I33,4,0)*(G14/1000+2*VLOOKUP(K14,'1-專案資訊'!A25:I33,8,0)/100)*L14*H14,0) | T14: =IF(AND(M14<>"",N14<>"",O14<>"",E14<>"",F14<>"",G14<>"",H14<>""),VLOOKUP(M14,'1-專案資訊'!A25:I33,4,0)*(2*((E14+F14)/1000-0.08)+2*VLOOKUP(M14,'1-專案資訊'!A25:I33,9,0)/100)*((G14*0.4/N14)+(G14*0.6/O14)+2)*H14,0) | U14: =IF(AND(E14<>"",F14<>"",G14<>"",H14<>""),(2*F14+E14)*G14/1000000*H14,0) | V14: =IF(AND(I14<>"",J14<>"",G14<>"",H14<>""),(ROUNDUP((G14/1000+2*VLOOKUP(I14,'1-專案資訊'!A25:I33,8,0)/100)/$B$3,0)-1)*(J14+L14)*H14,0) | W14: =IF(AND(V14>0,I14<>""),V14*VLOOKUP(I14,'1-專案資訊'!A25:I33,8,0)/100,0) | X14: =IF(OR(I14="#3 (D10)",I14="#4 (D13)",I14="#5 (D16)"),R14,0)+IF(OR(K14="#3 (D10)",K14="#4 (D13)",K14="#5 (D16)"),S14,0)+IF(OR(M14="#3 (D10)",M14="#4 (D13)",M14="#5 (D16)"),T14,0) | Y14: =IF(AND(I14<>"",I14<>"#3 (D10)",I14<>"#4 (D13)",I14<>"#5 (D16)"),R14,0)+IF(AND(K14<>"",K14<>"#3 (D10)",K14<>"#4 (D13)",K14<>"#5 (D16)"),S14,0)+IF(AND(M14<>"",M14<>"#3 (D10)",M14<>"#4 (D13)",M14<>"#5 (D16)"),T14,0)
A15: 11 | Q15: =IF(AND(E15<>"",F15<>"",G15<>"",H15<>""),E15*F15*G15/1000000000*H15,0) | R15: =IF(AND(I15<>"",J15<>"",G15<>"",H15<>""),VLOOKUP(I15,'1-專案資訊'!A25:I33,4,0)*(G15/1000+2*VLOOKUP(I15,'1-專案資訊'!A25:I33,8,0)/100)*J15*H15,0) | S15: =IF(AND(K15<>"",L15<>"",G15<>"",H15<>""),VLOOKUP(K15,'1-專案資訊'!A25:I33,4,0)*(G15/1000+2*VLOOKUP(K15,'1-專案資訊'!A25:I33,8,0)/100)*L15*H15,0) | T15: =IF(AND(M15<>"",N15<>"",O15<>"",E15<>"",F15<>"",G15<>"",H15<>""),VLOOKUP(M15,'1-專案資訊'!A25:I33,4,0)*(2*((E15+F15)/1000-0.08)+2*VLOOKUP(M15,'1-專案資訊'!A25:I33,9,0)/100)*((G15*0.4/N15)+(G15*0.6/O15)+2)*H15,0) | U15: =IF(AND(E15<>"",F15<>"",G15<>"",H15<>""),(2*F15+E15)*G15/1000000*H15,0) | V15: =IF(AND(I15<>"",J15<>"",G15<>"",H15<>""),(ROUNDUP((G15/1000+2*VLOOKUP(I15,'1-專案資訊'!A25:I33,8,0)/100)/$B$3,0)-1)*(J15+L15)*H15,0) | W15: =IF(AND(V15>0,I15<>""),V15*VLOOKUP(I15,'1-專案資訊'!A25:I33,8,0)/100,0) | X15: =IF(OR(I15="#3 (D10)",I15="#4 (D13)",I15="#5 (D16)"),R15,0)+IF(OR(K15="#3 (D10)",K15="#4 (D13)",K15="#5 (D16)"),S15,0)+IF(OR(M15="#3 (D10)",M15="#4 (D13)",M15="#5 (D16)"),T15,0) | Y15: =IF(AND(I15<>"",I15<>"#3 (D10)",I15<>"#4 (D13)",I15<>"#5 (D16)"),R15,0)+IF(AND(K15<>"",K15<>"#3 (D10)",K15<>"#4 (D13)",K15<>"#5 (D16)"),S15,0)+IF(AND(M15<>"",M15<>"#3 (D10)",M15<>"#4 (D13)",M15<>"#5 (D16)"),T15,0)
A16: 12 | Q16: =IF(AND(E16<>"",F16<>"",G16<>"",H16<>""),E16*F16*G16/1000000000*H16,0) | R16: =IF(AND(I16<>"",J16<>"",G16<>"",H16<>""),VLOOKUP(I16,'1-專案資訊'!A25:I33,4,0)*(G16/1000+2*VLOOKUP(I16,'1-專案資訊'!A25:I33,8,0)/100)*J16*H16,0) | S16: =IF(AND(K16<>"",L16<>"",G16<>"",H16<>""),VLOOKUP(K16,'1-專案資訊'!A25:I33,4,0)*(G16/1000+2*VLOOKUP(K16,'1-專案資訊'!A25:I33,8,0)/100)*L16*H16,0) | T16: =IF(AND(M16<>"",N16<>"",O16<>"",E16<>"",F16<>"",G16<>"",H16<>""),VLOOKUP(M16,'1-專案資訊'!A25:I33,4,0)*(2*((E16+F16)/1000-0.08)+2*VLOOKUP(M16,'1-專案資訊'!A25:I33,9,0)/100)*((G16*0.4/N16)+(G16*0.6/O16)+2)*H16,0) | U16: =IF(AND(E16<>"",F16<>"",G16<>"",H16<>""),(2*F16+E16)*G16/1000000*H16,0) | V16: =IF(AND(I16<>"",J16<>"",G16<>"",H16<>""),(ROUNDUP((G16/1000+2*VLOOKUP(I16,'1-專案資訊'!A25:I33,8,0)/100)/$B$3,0)-1)*(J16+L16)*H16,0) | W16: =IF(AND(V16>0,I16<>""),V16*VLOOKUP(I16,'1-專案資訊'!A25:I33,8,0)/100,0) | X16: =IF(OR(I16="#3 (D10)",I16="#4 (D13)",I16="#5 (D16)"),R16,0)+IF(OR(K16="#3 (D10)",K16="#4 (D13)",K16="#5 (D16)"),S16,0)+IF(OR(M16="#3 (D10)",M16="#4 (D13)",M16="#5 (D16)"),T16,0) | Y16: =IF(AND(I16<>"",I16<>"#3 (D10)",I16<>"#4 (D13)",I16<>"#5 (D16)"),R16,0)+IF(AND(K16<>"",K16<>"#3 (D10)",K16<>"#4 (D13)",K16<>"#5 (D16)"),S16,0)+IF(AND(M16<>"",M16<>"#3 (D10)",M16<>"#4 (D13)",M16<>"#5 (D16)"),T16,0)
A17: 13 | Q17: =IF(AND(E17<>"",F17<>"",G17<>"",H17<>""),E17*F17*G17/1000000000*H17,0) | R17: =IF(AND(I17<>"",J17<>"",G17<>"",H17<>""),VLOOKUP(I17,'1-專案資訊'!A25:I33,4,0)*(G17/1000+2*VLOOKUP(I17,'1-專案資訊'!A25:I33,8,0)/100)*J17*H17,0) | S17: =IF(AND(K17<>"",L17<>"",G17<>"",H17<>""),VLOOKUP(K17,'1-專案資訊'!A25:I33,4,0)*(G17/1000+2*VLOOKUP(K17,'1-專案資訊'!A25:I33,8,0)/100)*L17*H17,0) | T17: =IF(AND(M17<>"",N17<>"",O17<>"",E17<>"",F17<>"",G17<>"",H17<>""),VLOOKUP(M17,'1-專案資訊'!A25:I33,4,0)*(2*((E17+F17)/1000-0.08)+2*VLOOKUP(M17,'1-專案資訊'!A25:I33,9,0)/100)*((G17*0.4/N17)+(G17*0.6/O17)+2)*H17,0) | U17: =IF(AND(E17<>"",F17<>"",G17<>"",H17<>""),(2*F17+E17)*G17/1000000*H17,0) | V17: =IF(AND(I17<>"",J17<>"",G17<>"",H17<>""),(ROUNDUP((G17/1000+2*VLOOKUP(I17,'1-專案資訊'!A25:I33,8,0)/100)/$B$3,0)-1)*(J17+L17)*H17,0) | W17: =IF(AND(V17>0,I17<>""),V17*VLOOKUP(I17,'1-專案資訊'!A25:I33,8,0)/100,0) | X17: =IF(OR(I17="#3 (D10)",I17="#4 (D13)",I17="#5 (D16)"),R17,0)+IF(OR(K17="#3 (D10)",K17="#4 (D13)",K17="#5 (D16)"),S17,0)+IF(OR(M17="#3 (D10)",M17="#4 (D13)",M17="#5 (D16)"),T17,0) | Y17: =IF(AND(I17<>"",I17<>"#3 (D10)",I17<>"#4 (D13)",I17<>"#5 (D16)"),R17,0)+IF(AND(K17<>"",K17<>"#3 (D10)",K17<>"#4 (D13)",K17<>"#5 (D16)"),S17,0)+IF(AND(M17<>"",M17<>"#3 (D10)",M17<>"#4 (D13)",M17<>"#5 (D16)"),T17,0)
A18: 14 | Q18: =IF(AND(E18<>"",F18<>"",G18<>"",H18<>""),E18*F18*G18/1000000000*H18,0) | R18: =IF(AND(I18<>"",J18<>"",G18<>"",H18<>""),VLOOKUP(I18,'1-專案資訊'!A25:I33,4,0)*(G18/1000+2*VLOOKUP(I18,'1-專案資訊'!A25:I33,8,0)/100)*J18*H18,0) | S18: =IF(AND(K18<>"",L18<>"",G18<>"",H18<>""),VLOOKUP(K18,'1-專案資訊'!A25:I33,4,0)*(G18/1000+2*VLOOKUP(K18,'1-專案資訊'!A25:I33,8,0)/100)*L18*H18,0) | T18: =IF(AND(M18<>"",N18<>"",O18<>"",E18<>"",F18<>"",G18<>"",H18<>""),VLOOKUP(M18,'1-專案資訊'!A25:I33,4,0)*(2*((E18+F18)/1000-0.08)+2*VLOOKUP(M18,'1-專案資訊'!A25:I33,9,0)/100)*((G18*0.4/N18)+(G18*0.6/O18)+2)*H18,0) | U18: =IF(AND(E18<>"",F18<>"",G18<>"",H18<>""),(2*F18+E18)*G18/1000000*H18,0) | V18: =IF(AND(I18<>"",J18<>"",G18<>"",H18<>""),(ROUNDUP((G18/1000+2*VLOOKUP(I18,'1-專案資訊'!A25:I33,8,0)/100)/$B$3,0)-1)*(J18+L18)*H18,0) | W18: =IF(AND(V18>0,I18<>""),V18*VLOOKUP(I18,'1-專案資訊'!A25:I33,8,0)/100,0) | X18: =IF(OR(I18="#3 (D10)",I18="#4 (D13)",I18="#5 (D16)"),R18,0)+IF(OR(K18="#3 (D10)",K18="#4 (D13)",K18="#5 (D16)"),S18,0)+IF(OR(M18="#3 (D10)",M18="#4 (D13)",M18="#5 (D16)"),T18,0) | Y18: =IF(AND(I18<>"",I18<>"#3 (D10)",I18<>"#4 (D13)",I18<>"#5 (D16)"),R18,0)+IF(AND(K18<>"",K18<>"#3 (D10)",K18<>"#4 (D13)",K18<>"#5 (D16)"),S18,0)+IF(AND(M18<>"",M18<>"#3 (D10)",M18<>"#4 (D13)",M18<>"#5 (D16)"),T18,0)
