Workbook

Sheet ❶ 專案資訊
A1: 鋼構重量 / 塗裝面積 計算模板 v6
A2: 黃色=手動輸入，藍色底+▼=下拉選單，灰色=自動計算
A4: 專案名稱 | B4: （範例）XX廠房新建工程
A5: 填表日期 | B5: 2025/01/01
A6: 填表人員
A8: ▎ 全域參數設定
A9: 附加重量係數 | B9: 0.1 | C9: 螺栓/銲接/補強板等
A10: 鋼材單價 (元/噸) | B10: 30000
A11: 油漆單價 (元/m²) | B11: 350
A12: 防火漆1hr單價 (元/m²) | B12: 600
A13: 防火漆2hr單價 (元/m²) | B13: 1000
A14: 防火批覆單價 (元/m²) | B14: 1200
A15: RC單價 (元/m³) | B15: 3500
A16: 粉光單價 (元/m²) | B16: 250
A17: WWM單價 (元/噸) | B17: 35000
A18: 底層筋單價 (元/噸) | B18: 28000
A20: ▎ 鋼料類別參考表
A21: 鋼料類別 | B21: 鈑厚t(mm) | C21: Fy(kg/c㎡) | D21: 備註
A22: SN400B | B22: t≦40 | C22: 2400 | D22: CNS SN400B or SM400
A23: SN400B | B23: t>40 | C23: 2200 | D23: CNS SN400B or SM400
A24: SN490B | C24: 3300 | D24: CNS SN490B
A25: A572 Gr.50 | C25: 3450 | D25: ASTM A572 Gr.50
A26: A36 | B26: C型鋼、角鋼 | C26: 2400

Sheet ❷ 區塊定義
A1: 黃色=手動輸入，藍色底+▼=下拉選單，灰色=自動。塗裝長度留空=全塗。
A3: ▎ 區塊 A — 標準梁柱(防火漆2hr)
A4: ▼快速篩選 | B4: 構件名稱 | C4: ▼規格 | D4: ▼材質 | E4: 長度(mm) | F4: 數量 | G4: ▼塗裝類型 | H4: 塗裝長度 (mm)空白=全塗 | I4: ▼扣梁上面積 | J4: 單位重 | K4: 表面積 (m²/m) | L4: 重量(kg) | M4: 塗裝面積 (m²)
A5: H | B5: 主梁X向 | C5: H294×200 | D5: SN400B | E5: 7500 | F5: 2 | G5: 油漆 | I5: 否 | J5: =IFERROR(VLOOKUP(C5,規格資料庫!$A$2:$E$162,3,FALSE()),"") -> 55.8 | K5: =IFERROR(VLOOKUP(C5,規格資料庫!$A$2:$E$162,4,FALSE()),"") -> 1.372 | L5: =IF(J5="","",J5*E5/1000*F5) -> 837 | M5: =IF(OR(C5="",G5="",G5="無"),"",IFERROR(K5*IF(OR(H5="",H5=0),E5,H5)/1000*F5-IF(I5="是",VLOOKUP(C5,規格資料庫!$A$2:$E$162,5,FALSE())/1000*IF(OR(H5="",H5=0),E5,H5)/1000*F5,0),"")) -> 20.58 | N5: =IFERROR(VLOOKUP(C5,規格資料庫!$A$2:$B$162,2,FALSE()),"") -> H
A6: H | B6: 主梁Y向 | C6: H244×175 | D6: SN400B | E6: 7500 | F6: 2 | G6: 油漆 | I6: 否 | J6: =IFERROR(VLOOKUP(C6,規格資料庫!$A$2:$E$162,3,FALSE()),"") -> 43.6 | K6: =IFERROR(VLOOKUP(C6,規格資料庫!$A$2:$E$162,4,FALSE()),"") -> 1.174 | L6: =IF(J6="","",J6*E6/1000*F6) -> 654 | M6: =IF(OR(C6="",G6="",G6="無"),"",IFERROR(K6*IF(OR(H6="",H6=0),E6,H6)/1000*F6-IF(I6="是",VLOOKUP(C6,規格資料庫!$A$2:$E$162,5,FALSE())/1000*IF(OR(H6="",H6=0),E6,H6)/1000*F6,0),"")) -> 17.61 | N6: =IFERROR(VLOOKUP(C6,規格資料庫!$A$2:$B$162,2,FALSE()),"") -> H
A7: H | B7: 次梁 | C7: H194×150 | D7: SN400B | E7: 2500 | F7: 6 | G7: 油漆 | I7: 否 | J7: =IFERROR(VLOOKUP(C7,規格資料庫!$A$2:$E$162,3,FALSE()),"") -> 29.9 | K7: =IFERROR(VLOOKUP(C7,規格資料庫!$A$2:$E$162,4,FALSE()),"") -> 0.976 | L7: =IF(J7="","",J7*E7/1000*F7) -> 448.5 | M7: =IF(OR(C7="",G7="",G7="無"),"",IFERROR(K7*IF(OR(H7="",H7=0),E7,H7)/1000*F7-IF(I7="是",VLOOKUP(C7,規格資料庫!$A$2:$E$162,5,FALSE())/1000*IF(OR(H7="",H7=0),E7,H7)/1000*F7,0),"")) -> 14.64 | N7: =IFERROR(VLOOKUP(C7,規格資料庫!$A$2:$B$162,2,FALSE()),"") -> H
A8: BOX | B8: 柱 | C8: BOX400×400×19 | D8: SN400B | E8: 6000 | F8: 4 | G8: 防火漆2hr | I8: 否 | J8: =IFERROR(VLOOKUP(C8,規格資料庫!$A$2:$E$162,3,FALSE()),"") -> 210 | K8: =IFERROR(VLOOKUP(C8,規格資料庫!$A$2:$E$162,4,FALSE()),"") -> 1.6 | L8: =IF(J8="","",J8*E8/1000*F8) -> 5040 | M8: =IF(OR(C8="",G8="",G8="無"),"",IFERROR(K8*IF(OR(H8="",H8=0),E8,H8)/1000*F8-IF(I8="是",VLOOKUP(C8,規格資料庫!$A$2:$E$162,5,FALSE())/1000*IF(OR(H8="",H8=0),E8,H8)/1000*F8,0),"")) -> 38.4 | N8: =IFERROR(VLOOKUP(C8,規格資料庫!$A$2:$B$162,2,FALSE()),"") -> BOX
A9: L | B9: 斜撐 | C9: L100×100×10 | D9: A36 | E9: 5000 | F9: 2 | G9: 油漆 | I9: 否 | J9: =IFERROR(VLOOKUP(C9,規格資料庫!$A$2:$E$162,3,FALSE()),"") -> 14.9 | K9: =IFERROR(VLOOKUP(C9,規格資料庫!$A$2:$E$162,4,FALSE()),"") -> 0.39 | L9: =IF(J9="","",J9*E9/1000*F9) -> 149 | M9: =IF(OR(C9="",G9="",G9="無"),"",IFERROR(K9*IF(OR(H9="",H9=0),E9,H9)/1000*F9-IF(I9="是",VLOOKUP(C9,規格資料庫!$A$2:$E$162,5,FALSE())/1000*IF(OR(H9="",H9=0),E9,H9)/1000*F9,0),"")) -> 3.9 | N9: =IFERROR(VLOOKUP(C9,規格資料庫!$A$2:$B$162,2,FALSE()),"") -> L
J10: =IFERROR(VLOOKUP(C10,規格資料庫!$A$2:$E$162,3,FALSE()),"") | K10: =IFERROR(VLOOKUP(C10,規格資料庫!$A$2:$E$162,4,FALSE()),"") | L10: =IF(J10="","",J10*E10/1000*F10) | M10: =IF(OR(C10="",G10="",G10="無"),"",IFERROR(K10*IF(OR(H10="",H10=0),E10,H10)/1000*F10-IF(I10="是",VLOOKUP(C10,規格資料庫!$A$2:$E$162,5,FALSE())/1000*IF(OR(H10="",H10=0),E10,H10)/1000*F10,0),"")) | N10: =IFERROR(VLOOKUP(C10,規格資料庫!$A$2:$B$162,2,FALSE()),"")
J11: =IFERROR(VLOOKUP(C11,規格資料庫!$A$2:$E$162,3,FALSE()),"") | K11: =IFERROR(VLOOKUP(C11,規格資料庫!$A$2:$E$162,4,FALSE()),"") | L11: =IF(J11="","",J11*E11/1000*F11) | M11: =IF(OR(C11="",G11="",G11="無"),"",IFERROR(K11*IF(OR(H11="",H11=0),E11,H11)/1000*F11-IF(I11="是",VLOOKUP(C11,規格資料庫!$A$2:$E$162,5,FALSE())/1000*IF(OR(H11="",H11=0),E11,H11)/1000*F11,0),"")) | N11: =IFERROR(VLOOKUP(C11,規格資料庫!$A$2:$B$162,2,FALSE()),"")
J12: =IFERROR(VLOOKUP(C12,規格資料庫!$A$2:$E$162,3,FALSE()),"") | K12: =IFERROR(VLOOKUP(C12,規格資料庫!$A$2:$E$162,4,FALSE()),"") | L12: =IF(J12="","",J12*E12/1000*F12) | M12: =IF(OR(C12="",G12="",G12="無"),"",IFERROR(K12*IF(OR(H12="",H12=0),E12,H12)/1000*F12-IF(I12="是",VLOOKUP(C12,規格資料庫!$A$2:$E$162,5,FALSE())/1000*IF(OR(H12="",H12=0),E12,H12)/1000*F12,0),"")) | N12: =IFERROR(VLOOKUP(C12,規格資料庫!$A$2:$B$162,2,FALSE()),"")
J13: =IFERROR(VLOOKUP(C13,規格資料庫!$A$2:$E$162,3,FALSE()),"") | K13: =IFERROR(VLOOKUP(C13,規格資料庫!$A$2:$E$162,4,FALSE()),"") | L13: =IF(J13="","",J13*E13/1000*F13) | M13: =IF(OR(C13="",G13="",G13="無"),"",IFERROR(K13*IF(OR(H13="",H13=0),E13,H13)/1000*F13-IF(I13="是",VLOOKUP(C13,規格資料庫!$A$2:$E$162,5,FALSE())/1000*IF(OR(H13="",H13=0),E13,H13)/1000*F13,0),"")) | N13: =IFERROR(VLOOKUP(C13,規格資料庫!$A$2:$B$162,2,FALSE()),"")
J14: =IFERROR(VLOOKUP(C14,規格資料庫!$A$2:$E$162,3,FALSE()),"") | K14: =IFERROR(VLOOKUP(C14,規格資料庫!$A$2:$E$162,4,FALSE()),"") | L14: =IF(J14="","",J14*E14/1000*F14) | M14: =IF(OR(C14="",G14="",G14="無"),"",IFERROR(K14*IF(OR(H14="",H14=0),E14,H14)/1000*F14-IF(I14="是",VLOOKUP(C14,規格資料庫!$A$2:$E$162,5,FALSE())/1000*IF(OR(H14="",H14=0),E14,H14)/1000*F14,0),"")) | N14: =IFERROR(VLOOKUP(C14,規格資料庫!$A$2:$B$162,2,FALSE()),"")
J15: =IFERROR(VLOOKUP(C15,規格資料庫!$A$2:$E$162,3,FALSE()),"") | K15: =IFERROR(VLOOKUP(C15,規格資料庫!$A$2:$E$162,4,FALSE()),"") | L15: =IF(J15="","",J15*E15/1000*F15) | M15: =IF(OR(C15="",G15="",G15="無"),"",IFERROR(K15*IF(OR(H15="",H15=0),E15,H15)/1000*F15-IF(I15="是",VLOOKUP(C15,規格資料庫!$A$2:$E$162,5,FALSE())/1000*IF(OR(H15="",H15=0),E15,H15)/1000*F15,0),"")) | N15: =IFERROR(VLOOKUP(C15,規格資料庫!$A$2:$B$162,2,FALSE()),"")
J16: =IFERROR(VLOOKUP(C16,規格資料庫!$A$2:$E$162,3,FALSE()),"") | K16: =IFERROR(VLOOKUP(C16,規格資料庫!$A$2:$E$162,4,FALSE()),"") | L16: =IF(J16="","",J16*E16/1000*F16) | M16: =IF(OR(C16="",G16="",G16="無"),"",IFERROR(K16*IF(OR(H16="",H16=0),E16,H16)/1000*F16-IF(I16="是",VLOOKUP(C16,規格資料庫!$A$2:$E$162,5,FALSE())/1000*IF(OR(H16="",H16=0),E16,H16)/1000*F16,0),"")) | N16: =IFERROR(VLOOKUP(C16,規格資料庫!$A$2:$B$162,2,FALSE()),"")
J17: =IFERROR(VLOOKUP(C17,規格資料庫!$A$2:$E$162,3,FALSE()),"") | K17: =IFERROR(VLOOKUP(C17,規格資料庫!$A$2:$E$162,4,FALSE()),"") | L17: =IF(J17="","",J17*E17/1000*F17) | M17: =IF(OR(C17="",G17="",G17="無"),"",IFERROR(K17*IF(OR(H17="",H17=0),E17,H17)/1000*F17-IF(I17="是",VLOOKUP(C17,規格資料庫!$A$2:$E$162,5,FALSE())/1000*IF(OR(H17="",H17=0),E17,H17)/1000*F17,0),"")) | N17: =IFERROR(VLOOKUP(C17,規格資料庫!$A$2:$B$162,2,FALSE()),"")
J18: =IFERROR(VLOOKUP(C18,規格資料庫!$A$2:$E$162,3,FALSE()),"") | K18: =IFERROR(VLOOKUP(C18,規格資料庫!$A$2:$E$162,4,FALSE()),"") | L18: =IF(J18="","",J18*E18/1000*F18) | M18: =IF(OR(C18="",G18="",G18="無"),"",IFERROR(K18*IF(OR(H18="",H18=0),E18,H18)/1000*F18-IF(I18="是",VLOOKUP(C18,規格資料庫!$A$2:$E$162,5,FALSE())/1000*IF(OR(H18="",H18=0),E18,H18)/1000*F18,0),"")) | N18: =IFERROR(VLOOKUP(C18,規格資料庫!$A$2:$B$162,2,FALSE()),"")
J19: =IFERROR(VLOOKUP(C19,規格資料庫!$A$2:$E$162,3,FALSE()),"") | K19: =IFERROR(VLOOKUP(C19,規格資料庫!$A$2:$E$162,4,FALSE()),"") | L19: =IF(J19="","",J19*E19/1000*F19) | M19: =IF(OR(C19="",G19="",G19="無"),"",IFERROR(K19*IF(OR(H19="",H19=0),E19,H19)/1000*F19-IF(I19="是",VLOOKUP(C19,規格資料庫!$A$2:$E$162,5,FALSE())/1000*IF(OR(H19="",H19=0),E19,H19)/1000*F19,0),"")) | N19: =IFERROR(VLOOKUP(C19,規格資料庫!$A$2:$B$162,2,FALSE()),"")
J20: =IFERROR(VLOOKUP(C20,規格資料庫!$A$2:$E$162,3,FALSE()),"") | K20: =IFERROR(VLOOKUP(C20,規格資料庫!$A$2:$E$162,4,FALSE()),"") | L20: =IF(J20="","",J20*E20/1000*F20) | M20: =IF(OR(C20="",G20="",G20="無"),"",IFERROR(K20*IF(OR(H20="",H20=0),E20,H20)/1000*F20-IF(I20="是",VLOOKUP(C20,規格資料庫!$A$2:$E$162,5,FALSE())/1000*IF(OR(H20="",H20=0),E20,H20)/1000*F20,0),"")) | N20: =IFERROR(VLOOKUP(C20,規格資料庫!$A$2:$B$162,2,FALSE()),"")
J21: =IFERROR(VLOOKUP(C21,規格資料庫!$A$2:$E$162,3,FALSE()),"") | K21: =IFERROR(VLOOKUP(C21,規格資料庫!$A$2:$E$162,4,FALSE()),"") | L21: =IF(J21="","",J21*E21/1000*F21) | M21: =IF(OR(C21="",G21="",G21="無"),"",IFERROR(K21*IF(OR(H21="",H21=0),E21,H21)/1000*F21-IF(I21="是",VLOOKUP(C21,規格資料庫!$A$2:$E$162,5,FALSE())/1000*IF(OR(H21="",H21=0),E21,H21)/1000*F21,0),"")) | N21: =IFERROR(VLOOKUP(C21,規格資料庫!$A$2:$B$162,2,FALSE()),"")
... J24: =IFERROR(VLOOKUP(C24,規格資料庫!$A$2:$E$162,3,FALSE()),"") | K24: =IFERROR(VLOOKUP(C24,規格資料庫!$A$2:$E$162,4,FALSE()),"") | L24: =IF(J24="","",J24*E24/1000*F24) | M24: =IF(OR(C24="",G24="",G24="無"),"",IFERROR(K24*IF(OR(H24="",H24=0),E24,H24)/1000*F24-IF(I24="是",VLOOKUP(C24,規格資料庫!$A$2:$E$162,5,FALSE())/1000*IF(OR(H24="",H24=0),E24,H24)/1000*F24,0),"")) | N24: =IFERROR(VLOOKUP(C24,規格資料庫!$A$2:$B$162,2,FALSE()),"")
A25: 小計 | L25: =SUM(L5:L24) -> 7128.5 | M25: =SUM(M5:M24) -> 95.13 | O25: =SUMIF(G5:G24,"油漆",M5:M24) -> 56.73 | P25: =SUMIF(G5:G24,"防火漆1hr",M5:M24) -> 0 | Q25: =SUMIF(G5:G24,"防火漆2hr",M5:M24) -> 38.4 | R25: =SUMIF(G5:G24,"防火批覆",M5:M24) -> 0 | S25: =SUMPRODUCT((D5:D24="SN400B")*IF(ISNUMBER(L5:L24),L5:L24,0)) -> 6979.5 | T25: =SUMPRODUCT((D5:D24="A36")*IF(ISNUMBER(L5:L24),L5:L24,0)) -> 149 | U25: =SUMPRODUCT((D5:D24="SN490B")*IF(ISNUMBER(L5:L24),L5:L24,0)) -> 0 | V25: =SUMPRODUCT((D5:D24="A572 Gr.50")*IF(ISNUMBER(L5:L24),L5:L24,0)) -> 0 | W25: =SUMPRODUCT((N5:N24="GR")*IF(ISNUMBER(L5:L24),L5:L24,0)) -> 0 | X25: =SUMPRODUCT((N5:N24="CP")*IF(ISNUMBER(L5:L24),L5:L24,0)) -> 0
A27: ▎ 區塊 B — 管架柱(下半截2hr)
A28: ▼快速篩選 | B28: 構件名稱 | C28: ▼規格 | D28: ▼材質 | E28: 長度(mm) | F28: 數量 | G28: ▼塗裝類型 | H28: 塗裝長度 (mm)空白=全塗 | I28: ▼扣梁上面積 | J28: 單位重 | K28: 表面積 (m²/m) | L28: 重量(kg) | M28: 塗裝面積 (m²)
A29: H | B29: 設備梁 | C29: H488×300 | D29: SN400B | E29: 7500 | F29: 2 | G29: 油漆 | I29: 否 | J29: =IFERROR(VLOOKUP(C29,規格資料庫!$A$2:$E$162,3,FALSE()),"") -> 125 | K29: =IFERROR(VLOOKUP(C29,規格資料庫!$A$2:$E$162,4,FALSE()),"") -> 2.154 | L29: =IF(J29="","",J29*E29/1000*F29) -> 1875 | M29: =IF(OR(C29="",G29="",G29="無"),"",IFERROR(K29*IF(OR(H29="",H29=0),E29,H29)/1000*F29-IF(I29="是",VLOOKUP(C29,規格資料庫!$A$2:$E$162,5,FALSE())/1000*IF(OR(H29="",H29=0),E29,H29)/1000*F29,0),"")) -> 32.31 | N29: =IFERROR(VLOOKUP(C29,規格資料庫!$A$2:$B$162,2,FALSE()),"") -> H
A30: H | B30: 支撐梁 | C30: H340×175 | D30: SN400B | E30: 2500 | F30: 4 | G30: 油漆 | I30: 否 | J30: =IFERROR(VLOOKUP(C30,規格資料庫!$A$2:$E$162,3,FALSE()),"") -> 49.6 | K30: =IFERROR(VLOOKUP(C30,規格資料庫!$A$2:$E$162,4,FALSE()),"") -> 1.366 | L30: =IF(J30="","",J30*E30/1000*F30) -> 496 | M30: =IF(OR(C30="",G30="",G30="無"),"",IFERROR(K30*IF(OR(H30="",H30=0),E30,H30)/1000*F30-IF(I30="是",VLOOKUP(C30,規格資料庫!$A$2:$E$162,5,FALSE())/1000*IF(OR(H30="",H30=0),E30,H30)/1000*F30,0),"")) -> 13.66 | N30: =IFERROR(VLOOKUP(C30,規格資料庫!$A$2:$B$162,2,FALSE()),"") -> H
A31: BOX | B31: 柱 | C31: BOX500×500×19 | D31: SN400B | E31: 12000 | F31: 4 | G31: 防火漆2hr | H31: 6000 | I31: 否 | J31: =IFERROR(VLOOKUP(C31,規格資料庫!$A$2:$E$162,3,FALSE()),"") -> 267 | K31: =IFERROR(VLOOKUP(C31,規格資料庫!$A$2:$E$162,4,FALSE()),"") -> 2 | L31: =IF(J31="","",J31*E31/1000*F31) -> 12816 | M31: =IF(OR(C31="",G31="",G31="無"),"",IFERROR(K31*IF(OR(H31="",H31=0),E31,H31)/1000*F31-IF(I31="是",VLOOKUP(C31,規格資料庫!$A$2:$E$162,5,FALSE())/1000*IF(OR(H31="",H31=0),E31,H31)/1000*F31,0),"")) -> 48 | N31: =IFERROR(VLOOKUP(C31,規格資料庫!$A$2:$B$162,2,FALSE()),"") -> BOX
A32: H | B32: 次梁 | C32: H194×150 | D32: SN400B | E32: 2500 | F32: 4 | G32: 油漆 | I32: 否 | J32: =IFERROR(VLOOKUP(C32,規格資料庫!$A$2:$E$162,3,FALSE()),"") -> 29.9 | K32: =IFERROR(VLOOKUP(C32,規格資料庫!$A$2:$E$162,4,FALSE()),"") -> 0.976 | L32: =IF(J32="","",J32*E32/1000*F32) -> 299 | M32: =IF(OR(C32="",G32="",G32="無"),"",IFERROR(K32*IF(OR(H32="",H32=0),E32,H32)/1000*F32-IF(I32="是",VLOOKUP(C32,規格資料庫!$A$2:$E$162,5,FALSE())/1000*IF(OR(H32="",H32=0),E32,H32)/1000*F32,0),"")) -> 9.76 | N32: =IFERROR(VLOOKUP(C32,規格資料庫!$A$2:$B$162,2,FALSE()),"") -> H
J33: =IFERROR(VLOOKUP(C33,規格資料庫!$A$2:$E$162,3,FALSE()),"") | K33: =IFERROR(VLOOKUP(C33,規格資料庫!$A$2:$E$162,4,FALSE()),"") | L33: =IF(J33="","",J33*E33/1000*F33) | M33: =IF(OR(C33="",G33="",G33="無"),"",IFERROR(K33*IF(OR(H33="",H33=0),E33,H33)/1000*F33-IF(I33="是",VLOOKUP(C33,規格資料庫!$A$2:$E$162,5,FALSE())/1000*IF(OR(H33="",H33=0),E33,H33)/1000*F33,0),"")) | N33: =IFERROR(VLOOKUP(C33,規格資料庫!$A$2:$B$162,2,FALSE()),"")
J34: =IFERROR(VLOOKUP(C34,規格資料庫!$A$2:$E$162,3,FALSE()),"") | K34: =IFERROR(VLOOKUP(C34,規格資料庫!$A$2:$E$162,4,FALSE()),"") | L34: =IF(J34="","",J34*E34/1000*F34) | M34: =IF(OR(C34="",G34="",G34="無"),"",IFERROR(K34*IF(OR(H34="",H34=0),E34,H34)/1000*F34-IF(I34="是",VLOOKUP(C34,規格資料庫!$A$2:$E$162,5,FALSE())/1000*IF(OR(H34="",H34=0),E34,H34)/1000*F34,0),"")) | N34: =IFERROR(VLOOKUP(C34,規格資料庫!$A$2:$B$162,2,FALSE()),"")
J35: =IFERROR(VLOOKUP(C35,規格資料庫!$A$2:$E$162,3,FALSE()),"") | K35: =IFERROR(VLOOKUP(C35,規格資料庫!$A$2:$E$162,4,FALSE()),"") | L35: =IF(J35="","",J35*E35/1000*F35) | M35: =IF(OR(C35="",G35="",G35="無"),"",IFERROR(K35*IF(OR(H35="",H35=0),E35,H35)/1000*F35-IF(I35="是",VLOOKUP(C35,規格資料庫!$A$2:$E$162,5,FALSE())/1000*IF(OR(H35="",H35=0),E35,H35)/1000*F35,0),"")) | N35: =IFERROR(VLOOKUP(C35,規格資料庫!$A$2:$B$162,2,FALSE()),"")
J36: =IFERROR(VLOOKUP(C36,規格資料庫!$A$2:$E$162,3,FALSE()),"") | K36: =IFERROR(VLOOKUP(C36,規格資料庫!$A$2:$E$162,4,FALSE()),"") | L36: =IF(J36="","",J36*E36/1000*F36) | M36: =IF(OR(C36="",G36="",G36="無"),"",IFERROR(K36*IF(OR(H36="",H36=0),E36,H36)/1000*F36-IF(I36="是",VLOOKUP(C36,規格資料庫!$A$2:$E$162,5,FALSE())/1000*IF(OR(H36="",H36=0),E36,H36)/1000*F36,0),"")) | N36: =IFERROR(VLOOKUP(C36,規格資料庫!$A$2:$B$162,2,FALSE()),"")
J37: =IFERROR(VLOOKUP(C37,規格資料庫!$A$2:$E$162,3,FALSE()),"") | K37: =IFERROR(VLOOKUP(C37,規格資料庫!$A$2:$E$162,4,FALSE()),"") | L37: =IF(J37="","",J37*E37/1000*F37) | M37: =IF(OR(C37="",G37="",G37="無"),"",IFERROR(K37*IF(OR(H37="",H37=0),E37,H37)/1000*F37-IF(I37="是",VLOOKUP(C37,規格資料庫!$A$2:$E$162,5,FALSE())/1000*IF(OR(H37="",H37=0),E37,H37)/1000*F37,0),"")) | N37: =IFERROR(VLOOKUP(C37,規格資料庫!$A$2:$B$162,2,FALSE()),"")
J38: =IFERROR(VLOOKUP(C38,規格資料庫!$A$2:$E$162,3,FALSE()),"") | K38: =IFERROR(VLOOKUP(C38,規格資料庫!$A$2:$E$162,4,FALSE()),"") | L38: =IF(J38="","",J38*E38/1000*F38) | M38: =IF(OR(C38="",G38="",G38="無"),"",IFERROR(K38*IF(OR(H38="",H38=0),E38,H38)/1000*F38-IF(I38="是",VLOOKUP(C38,規格資料庫!$A$2:$E$162,5,FALSE())/1000*IF(OR(H38="",H38=0),E38,H38)/1000*F38,0),"")) | N38: =IFERROR(VLOOKUP(C38,規格資料庫!$A$2:$B$162,2,FALSE()),"")
J39: =IFERROR(VLOOKUP(C39,規格資料庫!$A$2:$E$162,3,FALSE()),"") | K39: =IFERROR(VLOOKUP(C39,規格資料庫!$A$2:$E$162,4,FALSE()),"") | L39: =IF(J39="","",J39*E39/1000*F39) | M39: =IF(OR(C39="",G39="",G39="無"),"",IFERROR(K39*IF(OR(H39="",H39=0),E39,H39)/1000*F39-IF(I39="是",VLOOKUP(C39,規格資料庫!$A$2:$E$162,5,FALSE())/1000*IF(OR(H39="",H39=0),E39,H39)/1000*F39,0),"")) | N39: =IFERROR(VLOOKUP(C39,規格資料庫!$A$2:$B$162,2,FALSE()),"")
J40: =IFERROR(VLOOKUP(C40,規格資料庫!$A$2:$E$162,3,FALSE()),"") | K40: =IFERROR(VLOOKUP(C40,規格資料庫!$A$2:$E$162,4,FALSE()),"") | L40: =IF(J40="","",J40*E40/1000*F40) | M40: =IF(OR(C40="",G40="",G40="無"),"",IFERROR(K40*IF(OR(H40="",H40=0),E40,H40)/1000*F40-IF(I40="是",VLOOKUP(C40,規格資料庫!$A$2:$E$162,5,FALSE())/1000*IF(OR(H40="",H40=0),E40,H40)/1000*F40,0),"")) | N40: =IFERROR(VLOOKUP(C40,規格資料庫!$A$2:$B$162,2,FALSE()),"")
J41: =IFERROR(VLOOKUP(C41,規格資料庫!$A$2:$E$162,3,FALSE()),"") | K41: =IFERROR(VLOOKUP(C41,規格資料庫!$A$2:$E$162,4,FALSE()),"") | L41: =IF(J41="","",J41*E41/1000*F41) | M41: =IF(OR(C41="",G41="",G41="無"),"",IFERROR(K41*IF(OR(H41="",H41=0),E41,H41)/1000*F41-IF(I41="是",VLOOKUP(C41,規格資料庫!$A$2:$E$162,5,FALSE())/1000*IF(OR(H41="",H41=0),E41,H41)/1000*F41,0),"")) | N41: =IFERROR(VLOOKUP(C41,規格資料庫!$A$2:$B$162,2,FALSE()),"")
J42: =IFERROR(VLOOKUP(C42,規格資料庫!$A$2:$E$162,3,FALSE()),"") | K42: =IFERROR(VLOOKUP(C42,規格資料庫!$A$2:$E$162,4,FALSE()),"") | L42: =IF(J42="","",J42*E42/1000*F42) | M42: =IF(OR(C42="",G42="",G42="無"),"",IFERROR(K42*IF(OR(H42="",H42=0),E42,H42)/1000*F42-IF(I42="是",VLOOKUP(C42,規格資料庫!$A$2:$E$162,5,FALSE())/1000*IF(OR(H42="",H42=0),E42,H42)/1000*F42,0),"")) | N42: =IFERROR(VLOOKUP(C42,規格資料庫!$A$2:$B$162,2,FALSE()),"")
J43: =IFERROR(VLOOKUP(C43,規格資料庫!$A$2:$E$162,3,FALSE()),"") | K43: =IFERROR(VLOOKUP(C43,規格資料庫!$A$2:$E$162,4,FALSE()),"") | L43: =IF(J43="","",J43*E43/1000*F43) | M43: =IF(OR(C43="",G43="",G43="無"),"",IFERROR(K43*IF(OR(H43="",H43=0),E43,H43)/1000*F43-IF(I43="是",VLOOKUP(C43,規格資料庫!$A$2:$E$162,5,FALSE())/1000*IF(OR(H43="",H43=0),E43,H43)/1000*F43,0),"")) | N43: =IFERROR(VLOOKUP(C43,規格資料庫!$A$2:$B$162,2,FALSE()),"")
J44: =IFERROR(VLOOKUP(C44,規格資料庫!$A$2:$E$162,3,FALSE()),"") | K44: =IFERROR(VLOOKUP(C44,規格資料庫!$A$2:$E$162,4,FALSE()),"") | L44: =IF(J44="","",J44*E44/1000*F44) | M44: =IF(OR(C44="",G44="",G44="無"),"",IFERROR(K44*IF(OR(H44="",H44=0),E44,H44)/1000*F44-IF(I44="是",VLOOKUP(C44,規格資料庫!$A$2:$E$162,5,FALSE())/1000*IF(OR(H44="",H44=0),E44,H44)/1000*F44,0),"")) | N44: =IFERROR(VLOOKUP(C44,規格資料庫!$A$2:$B$162,2,FALSE()),"")
...

Sheet ❸ 樓層配置
A1: 填寫每層各區塊Bay數量，右側自動計算。
A3: 樓層 | B3: 區塊A 數量 | C3: 區塊B 數量 | D3: 區塊C 數量 | E3: 區塊D 數量 | F3: 區塊E 數量 | G3: 樓層重量 (kg) | H3: 油漆面積 (m²) | I3: 防火漆1hr 面積(m²) | J3: 防火漆2hr 面積(m²) | K3: 防火批覆 面積(m²) | L3: 樓層總面積 (m²)
A4: 1F | B4: 6 | C4: 2 | D4: 4 | E4: 0 | F4: 0 | G4: =IF(A4="","",IF(B4="",0,B4)*'❷ 區塊定義'!L25+IF(C4="",0,C4)*'❷ 區塊定義'!L49+IF(D4="",0,D4)*'❷ 區塊定義'!L73+IF(E4="",0,E4)*'❷ 區塊定義'!L97+IF(F4="",0,F4)*'❷ 區塊定義'!L121) -> 79602.432 | H4: =IF(A4="","",IF(B4="",0,B4)*'❷ 區塊定義'!O25+IF(C4="",0,C4)*'❷ 區塊定義'!O49+IF(D4="",0,D4)*'❷ 區塊定義'!O73+IF(E4="",0,E4)*'❷ 區塊定義'!O97+IF(F4="",0,F4)*'❷ 區塊定義'!O121) -> 527.656 | I4: =IF(A4="","",IF(B4="",0,B4)*'❷ 區塊定義'!P25+IF(C4="",0,C4)*'❷ 區塊定義'!P49+IF(D4="",0,D4)*'❷ 區塊定義'!P73+IF(E4="",0,E4)*'❷ 區塊定義'!P97+IF(F4="",0,F4)*'❷ 區塊定義'!P121) -> 84.72 | J4: =IF(A4="","",IF(B4="",0,B4)*'❷ 區塊定義'!Q25+IF(C4="",0,C4)*'❷ 區塊定義'!Q49+IF(D4="",0,D4)*'❷ 區塊定義'!Q73+IF(E4="",0,E4)*'❷ 區塊定義'!Q97+IF(F4="",0,F4)*'❷ 區塊定義'!Q121) -> 326.4 | K4: =IF(A4="","",IF(B4="",0,B4)*'❷ 區塊定義'!R25+IF(C4="",0,C4)*'❷ 區塊定義'!R49+IF(D4="",0,D4)*'❷ 區塊定義'!R73+IF(E4="",0,E4)*'❷ 區塊定義'!R97+IF(F4="",0,F4)*'❷ 區塊定義'!R121) -> 0 | L4: =IF(A4="","",H4+I4+J4+K4) -> 938.776 | M4: =IF(A4="","",IF(B4="",0,B4)*'❷ 區塊定義'!S25+IF(C4="",0,C4)*'❷ 區塊定義'!S49+IF(D4="",0,D4)*'❷ 區塊定義'!S73+IF(E4="",0,E4)*'❷ 區塊定義'!S97+IF(F4="",0,F4)*'❷ 區塊定義'!S121) -> 76476.432 | N4: =IF(A4="","",IF(B4="",0,B4)*'❷ 區塊定義'!T25+IF(C4="",0,C4)*'❷ 區塊定義'!T49+IF(D4="",0,D4)*'❷ 區塊定義'!T73+IF(E4="",0,E4)*'❷ 區塊定義'!T97+IF(F4="",0,F4)*'❷ 區塊定義'!T121) -> 3126 | O4: =IF(A4="","",IF(B4="",0,B4)*'❷ 區塊定義'!U25+IF(C4="",0,C4)*'❷ 區塊定義'!U49+IF(D4="",0,D4)*'❷ 區塊定義'!U73+IF(E4="",0,E4)*'❷ 區塊定義'!U97+IF(F4="",0,F4)*'❷ 區塊定義'!U121) -> 0 | P4: =IF(A4="","",IF(B4="",0,B4)*'❷ 區塊定義'!V25+IF(C4="",0,C4)*'❷ 區塊定義'!V49+IF(D4="",0,D4)*'❷ 區塊定義'!V73+IF(E4="",0,E4)*'❷ 區塊定義'!V97+IF(F4="",0,F4)*'❷ 區塊定義'!V121) -> 0 | Q4: =IF(A4="","",IF(B4="",0,B4)*'❷ 區塊定義'!W25+IF(C4="",0,C4)*'❷ 區塊定義'!W49+IF(D4="",0,D4)*'❷ 區塊定義'!W73+IF(E4="",0,E4)*'❷ 區塊定義'!W97+IF(F4="",0,F4)*'❷ 區塊定義'!W121) -> 0 | R4: =IF(A4="","",IF(B4="",0,B4)*'❷ 區塊定義'!X25+IF(C4="",0,C4)*'❷ 區塊定義'!X49+IF(D4="",0,D4)*'❷ 區塊定義'!X73+IF(E4="",0,E4)*'❷ 區塊定義'!X97+IF(F4="",0,F4)*'❷ 區塊定義'!X121) -> 0
A5: 2F | B5: 6 | C5: 2 | D5: 4 | E5: 0 | F5: 0 | G5: =IF(A5="","",IF(B5="",0,B5)*'❷ 區塊定義'!L25+IF(C5="",0,C5)*'❷ 區塊定義'!L49+IF(D5="",0,D5)*'❷ 區塊定義'!L73+IF(E5="",0,E5)*'❷ 區塊定義'!L97+IF(F5="",0,F5)*'❷ 區塊定義'!L121) -> 79602.432 | H5: =IF(A5="","",IF(B5="",0,B5)*'❷ 區塊定義'!O25+IF(C5="",0,C5)*'❷ 區塊定義'!O49+IF(D5="",0,D5)*'❷ 區塊定義'!O73+IF(E5="",0,E5)*'❷ 區塊定義'!O97+IF(F5="",0,F5)*'❷ 區塊定義'!O121) -> 527.656 | I5: =IF(A5="","",IF(B5="",0,B5)*'❷ 區塊定義'!P25+IF(C5="",0,C5)*'❷ 區塊定義'!P49+IF(D5="",0,D5)*'❷ 區塊定義'!P73+IF(E5="",0,E5)*'❷ 區塊定義'!P97+IF(F5="",0,F5)*'❷ 區塊定義'!P121) -> 84.72 | J5: =IF(A5="","",IF(B5="",0,B5)*'❷ 區塊定義'!Q25+IF(C5="",0,C5)*'❷ 區塊定義'!Q49+IF(D5="",0,D5)*'❷ 區塊定義'!Q73+IF(E5="",0,E5)*'❷ 區塊定義'!Q97+IF(F5="",0,F5)*'❷ 區塊定義'!Q121) -> 326.4 | K5: =IF(A5="","",IF(B5="",0,B5)*'❷ 區塊定義'!R25+IF(C5="",0,C5)*'❷ 區塊定義'!R49+IF(D5="",0,D5)*'❷ 區塊定義'!R73+IF(E5="",0,E5)*'❷ 區塊定義'!R97+IF(F5="",0,F5)*'❷ 區塊定義'!R121) -> 0 | L5: =IF(A5="","",H5+I5+J5+K5) -> 938.776 | M5: =IF(A5="","",IF(B5="",0,B5)*'❷ 區塊定義'!S25+IF(C5="",0,C5)*'❷ 區塊定義'!S49+IF(D5="",0,D5)*'❷ 區塊定義'!S73+IF(E5="",0,E5)*'❷ 區塊定義'!S97+IF(F5="",0,F5)*'❷ 區塊定義'!S121) -> 76476.432 | N5: =IF(A5="","",IF(B5="",0,B5)*'❷ 區塊定義'!T25+IF(C5="",0,C5)*'❷ 區塊定義'!T49+IF(D5="",0,D5)*'❷ 區塊定義'!T73+IF(E5="",0,E5)*'❷ 區塊定義'!T97+IF(F5="",0,F5)*'❷ 區塊定義'!T121) -> 3126 | O5: =IF(A5="","",IF(B5="",0,B5)*'❷ 區塊定義'!U25+IF(C5="",0,C5)*'❷ 區塊定義'!U49+IF(D5="",0,D5)*'❷ 區塊定義'!U73+IF(E5="",0,E5)*'❷ 區塊定義'!U97+IF(F5="",0,F5)*'❷ 區塊定義'!U121) -> 0 | P5: =IF(A5="","",IF(B5="",0,B5)*'❷ 區塊定義'!V25+IF(C5="",0,C5)*'❷ 區塊定義'!V49+IF(D5="",0,D5)*'❷ 區塊定義'!V73+IF(E5="",0,E5)*'❷ 區塊定義'!V97+IF(F5="",0,F5)*'❷ 區塊定義'!V121) -> 0 | Q5: =IF(A5="","",IF(B5="",0,B5)*'❷ 區塊定義'!W25+IF(C5="",0,C5)*'❷ 區塊定義'!W49+IF(D5="",0,D5)*'❷ 區塊定義'!W73+IF(E5="",0,E5)*'❷ 區塊定義'!W97+IF(F5="",0,F5)*'❷ 區塊定義'!W121) -> 0 | R5: =IF(A5="","",IF(B5="",0,B5)*'❷ 區塊定義'!X25+IF(C5="",0,C5)*'❷ 區塊定義'!X49+IF(D5="",0,D5)*'❷ 區塊定義'!X73+IF(E5="",0,E5)*'❷ 區塊定義'!X97+IF(F5="",0,F5)*'❷ 區塊定義'!X121) -> 0
A6: 3F | B6: 6 | C6: 2 | D6: 4 | E6: 0 | F6: 0 | G6: =IF(A6="","",IF(B6="",0,B6)*'❷ 區塊定義'!L25+IF(C6="",0,C6)*'❷ 區塊定義'!L49+IF(D6="",0,D6)*'❷ 區塊定義'!L73+IF(E6="",0,E6)*'❷ 區塊定義'!L97+IF(F6="",0,F6)*'❷ 區塊定義'!L121) -> 79602.432 | H6: =IF(A6="","",IF(B6="",0,B6)*'❷ 區塊定義'!O25+IF(C6="",0,C6)*'❷ 區塊定義'!O49+IF(D6="",0,D6)*'❷ 區塊定義'!O73+IF(E6="",0,E6)*'❷ 區塊定義'!O97+IF(F6="",0,F6)*'❷ 區塊定義'!O121) -> 527.656 | I6: =IF(A6="","",IF(B6="",0,B6)*'❷ 區塊定義'!P25+IF(C6="",0,C6)*'❷ 區塊定義'!P49+IF(D6="",0,D6)*'❷ 區塊定義'!P73+IF(E6="",0,E6)*'❷ 區塊定義'!P97+IF(F6="",0,F6)*'❷ 區塊定義'!P121) -> 84.72 | J6: =IF(A6="","",IF(B6="",0,B6)*'❷ 區塊定義'!Q25+IF(C6="",0,C6)*'❷ 區塊定義'!Q49+IF(D6="",0,D6)*'❷ 區塊定義'!Q73+IF(E6="",0,E6)*'❷ 區塊定義'!Q97+IF(F6="",0,F6)*'❷ 區塊定義'!Q121) -> 326.4 | K6: =IF(A6="","",IF(B6="",0,B6)*'❷ 區塊定義'!R25+IF(C6="",0,C6)*'❷ 區塊定義'!R49+IF(D6="",0,D6)*'❷ 區塊定義'!R73+IF(E6="",0,E6)*'❷ 區塊定義'!R97+IF(F6="",0,F6)*'❷ 區塊定義'!R121) -> 0 | L6: =IF(A6="","",H6+I6+J6+K6) -> 938.776 | M6: =IF(A6="","",IF(B6="",0,B6)*'❷ 區塊定義'!S25+IF(C6="",0,C6)*'❷ 區塊定義'!S49+IF(D6="",0,D6)*'❷ 區塊定義'!S73+IF(E6="",0,E6)*'❷ 區塊定義'!S97+IF(F6="",0,F6)*'❷ 區塊定義'!S121) -> 76476.432 | N6: =IF(A6="","",IF(B6="",0,B6)*'❷ 區塊定義'!T25+IF(C6="",0,C6)*'❷ 區塊定義'!T49+IF(D6="",0,D6)*'❷ 區塊定義'!T73+IF(E6="",0,E6)*'❷ 區塊定義'!T97+IF(F6="",0,F6)*'❷ 區塊定義'!T121) -> 3126 | O6: =IF(A6="","",IF(B6="",0,B6)*'❷ 區塊定義'!U25+IF(C6="",0,C6)*'❷ 區塊定義'!U49+IF(D6="",0,D6)*'❷ 區塊定義'!U73+IF(E6="",0,E6)*'❷ 區塊定義'!U97+IF(F6="",0,F6)*'❷ 區塊定義'!U121) -> 0 | P6: =IF(A6="","",IF(B6="",0,B6)*'❷ 區塊定義'!V25+IF(C6="",0,C6)*'❷ 區塊定義'!V49+IF(D6="",0,D6)*'❷ 區塊定義'!V73+IF(E6="",0,E6)*'❷ 區塊定義'!V97+IF(F6="",0,F6)*'❷ 區塊定義'!V121) -> 0 | Q6: =IF(A6="","",IF(B6="",0,B6)*'❷ 區塊定義'!W25+IF(C6="",0,C6)*'❷ 區塊定義'!W49+IF(D6="",0,D6)*'❷ 區塊定義'!W73+IF(E6="",0,E6)*'❷ 區塊定義'!W97+IF(F6="",0,F6)*'❷ 區塊定義'!W121) -> 0 | R6: =IF(A6="","",IF(B6="",0,B6)*'❷ 區塊定義'!X25+IF(C6="",0,C6)*'❷ 區塊定義'!X49+IF(D6="",0,D6)*'❷ 區塊定義'!X73+IF(E6="",0,E6)*'❷ 區塊定義'!X97+IF(F6="",0,F6)*'❷ 區塊定義'!X121) -> 0
A7: RF | B7: 6 | C7: 0 | D7: 4 | E7: 0 | F7: 0 | G7: =IF(A7="","",IF(B7="",0,B7)*'❷ 區塊定義'!L25+IF(C7="",0,C7)*'❷ 區塊定義'!L49+IF(D7="",0,D7)*'❷ 區塊定義'!L73+IF(E7="",0,E7)*'❷ 區塊定義'!L97+IF(F7="",0,F7)*'❷ 區塊定義'!L121) -> 48630.432 | H7: =IF(A7="","",IF(B7="",0,B7)*'❷ 區塊定義'!O25+IF(C7="",0,C7)*'❷ 區塊定義'!O49+IF(D7="",0,D7)*'❷ 區塊定義'!O73+IF(E7="",0,E7)*'❷ 區塊定義'!O97+IF(F7="",0,F7)*'❷ 區塊定義'!O121) -> 416.196 | I7: =IF(A7="","",IF(B7="",0,B7)*'❷ 區塊定義'!P25+IF(C7="",0,C7)*'❷ 區塊定義'!P49+IF(D7="",0,D7)*'❷ 區塊定義'!P73+IF(E7="",0,E7)*'❷ 區塊定義'!P97+IF(F7="",0,F7)*'❷ 區塊定義'!P121) -> 84.72 | J7: =IF(A7="","",IF(B7="",0,B7)*'❷ 區塊定義'!Q25+IF(C7="",0,C7)*'❷ 區塊定義'!Q49+IF(D7="",0,D7)*'❷ 區塊定義'!Q73+IF(E7="",0,E7)*'❷ 區塊定義'!Q97+IF(F7="",0,F7)*'❷ 區塊定義'!Q121) -> 230.4 | K7: =IF(A7="","",IF(B7="",0,B7)*'❷ 區塊定義'!R25+IF(C7="",0,C7)*'❷ 區塊定義'!R49+IF(D7="",0,D7)*'❷ 區塊定義'!R73+IF(E7="",0,E7)*'❷ 區塊定義'!R97+IF(F7="",0,F7)*'❷ 區塊定義'!R121) -> 0 | L7: =IF(A7="","",H7+I7+J7+K7) -> 731.316 | M7: =IF(A7="","",IF(B7="",0,B7)*'❷ 區塊定義'!S25+IF(C7="",0,C7)*'❷ 區塊定義'!S49+IF(D7="",0,D7)*'❷ 區塊定義'!S73+IF(E7="",0,E7)*'❷ 區塊定義'!S97+IF(F7="",0,F7)*'❷ 區塊定義'!S121) -> 45504.432 | N7: =IF(A7="","",IF(B7="",0,B7)*'❷ 區塊定義'!T25+IF(C7="",0,C7)*'❷ 區塊定義'!T49+IF(D7="",0,D7)*'❷ 區塊定義'!T73+IF(E7="",0,E7)*'❷ 區塊定義'!T97+IF(F7="",0,F7)*'❷ 區塊定義'!T121) -> 3126 | O7: =IF(A7="","",IF(B7="",0,B7)*'❷ 區塊定義'!U25+IF(C7="",0,C7)*'❷ 區塊定義'!U49+IF(D7="",0,D7)*'❷ 區塊定義'!U73+IF(E7="",0,E7)*'❷ 區塊定義'!U97+IF(F7="",0,F7)*'❷ 區塊定義'!U121) -> 0 | P7: =IF(A7="","",IF(B7="",0,B7)*'❷ 區塊定義'!V25+IF(C7="",0,C7)*'❷ 區塊定義'!V49+IF(D7="",0,D7)*'❷ 區塊定義'!V73+IF(E7="",0,E7)*'❷ 區塊定義'!V97+IF(F7="",0,F7)*'❷ 區塊定義'!V121) -> 0 | Q7: =IF(A7="","",IF(B7="",0,B7)*'❷ 區塊定義'!W25+IF(C7="",0,C7)*'❷ 區塊定義'!W49+IF(D7="",0,D7)*'❷ 區塊定義'!W73+IF(E7="",0,E7)*'❷ 區塊定義'!W97+IF(F7="",0,F7)*'❷ 區塊定義'!W121) -> 0 | R7: =IF(A7="","",IF(B7="",0,B7)*'❷ 區塊定義'!X25+IF(C7="",0,C7)*'❷ 區塊定義'!X49+IF(D7="",0,D7)*'❷ 區塊定義'!X73+IF(E7="",0,E7)*'❷ 區塊定義'!X97+IF(F7="",0,F7)*'❷ 區塊定義'!X121) -> 0
G8: =IF(A8="","",IF(B8="",0,B8)*'❷ 區塊定義'!L25+IF(C8="",0,C8)*'❷ 區塊定義'!L49+IF(D8="",0,D8)*'❷ 區塊定義'!L73+IF(E8="",0,E8)*'❷ 區塊定義'!L97+IF(F8="",0,F8)*'❷ 區塊定義'!L121) | H8: =IF(A8="","",IF(B8="",0,B8)*'❷ 區塊定義'!O25+IF(C8="",0,C8)*'❷ 區塊定義'!O49+IF(D8="",0,D8)*'❷ 區塊定義'!O73+IF(E8="",0,E8)*'❷ 區塊定義'!O97+IF(F8="",0,F8)*'❷ 區塊定義'!O121) | I8: =IF(A8="","",IF(B8="",0,B8)*'❷ 區塊定義'!P25+IF(C8="",0,C8)*'❷ 區塊定義'!P49+IF(D8="",0,D8)*'❷ 區塊定義'!P73+IF(E8="",0,E8)*'❷ 區塊定義'!P97+IF(F8="",0,F8)*'❷ 區塊定義'!P121) | J8: =IF(A8="","",IF(B8="",0,B8)*'❷ 區塊定義'!Q25+IF(C8="",0,C8)*'❷ 區塊定義'!Q49+IF(D8="",0,D8)*'❷ 區塊定義'!Q73+IF(E8="",0,E8)*'❷ 區塊定義'!Q97+IF(F8="",0,F8)*'❷ 區塊定義'!Q121) | K8: =IF(A8="","",IF(B8="",0,B8)*'❷ 區塊定義'!R25+IF(C8="",0,C8)*'❷ 區塊定義'!R49+IF(D8="",0,D8)*'❷ 區塊定義'!R73+IF(E8="",0,E8)*'❷ 區塊定義'!R97+IF(F8="",0,F8)*'❷ 區塊定義'!R121) | L8: =IF(A8="","",H8+I8+J8+K8) | M8: =IF(A8="","",IF(B8="",0,B8)*'❷ 區塊定義'!S25+IF(C8="",0,C8)*'❷ 區塊定義'!S49+IF(D8="",0,D8)*'❷ 區塊定義'!S73+IF(E8="",0,E8)*'❷ 區塊定義'!S97+IF(F8="",0,F8)*'❷ 區塊定義'!S121) | N8: =IF(A8="","",IF(B8="",0,B8)*'❷ 區塊定義'!T25+IF(C8="",0,C8)*'❷ 區塊定義'!T49+IF(D8="",0,D8)*'❷ 區塊定義'!T73+IF(E8="",0,E8)*'❷ 區塊定義'!T97+IF(F8="",0,F8)*'❷ 區塊定義'!T121) | O8: =IF(A8="","",IF(B8="",0,B8)*'❷ 區塊定義'!U25+IF(C8="",0,C8)*'❷ 區塊定義'!U49+IF(D8="",0,D8)*'❷ 區塊定義'!U73+IF(E8="",0,E8)*'❷ 區塊定義'!U97+IF(F8="",0,F8)*'❷ 區塊定義'!U121) | P8: =IF(A8="","",IF(B8="",0,B8)*'❷ 區塊定義'!V25+IF(C8="",0,C8)*'❷ 區塊定義'!V49+IF(D8="",0,D8)*'❷ 區塊定義'!V73+IF(E8="",0,E8)*'❷ 區塊定義'!V97+IF(F8="",0,F8)*'❷ 區塊定義'!V121) | Q8: =IF(A8="","",IF(B8="",0,B8)*'❷ 區塊定義'!W25+IF(C8="",0,C8)*'❷ 區塊定義'!W49+IF(D8="",0,D8)*'❷ 區塊定義'!W73+IF(E8="",0,E8)*'❷ 區塊定義'!W97+IF(F8="",0,F8)*'❷ 區塊定義'!W121) | R8: =IF(A8="","",IF(B8="",0,B8)*'❷ 區塊定義'!X25+IF(C8="",0,C8)*'❷ 區塊定義'!X49+IF(D8="",0,D8)*'❷ 區塊定義'!X73+IF(E8="",0,E8)*'❷ 區塊定義'!X97+IF(F8="",0,F8)*'❷ 區塊定義'!X121)
G9: =IF(A9="","",IF(B9="",0,B9)*'❷ 區塊定義'!L25+IF(C9="",0,C9)*'❷ 區塊定義'!L49+IF(D9="",0,D9)*'❷ 區塊定義'!L73+IF(E9="",0,E9)*'❷ 區塊定義'!L97+IF(F9="",0,F9)*'❷ 區塊定義'!L121) | H9: =IF(A9="","",IF(B9="",0,B9)*'❷ 區塊定義'!O25+IF(C9="",0,C9)*'❷ 區塊定義'!O49+IF(D9="",0,D9)*'❷ 區塊定義'!O73+IF(E9="",0,E9)*'❷ 區塊定義'!O97+IF(F9="",0,F9)*'❷ 區塊定義'!O121) | I9: =IF(A9="","",IF(B9="",0,B9)*'❷ 區塊定義'!P25+IF(C9="",0,C9)*'❷ 區塊定義'!P49+IF(D9="",0,D9)*'❷ 區塊定義'!P73+IF(E9="",0,E9)*'❷ 區塊定義'!P97+IF(F9="",0,F9)*'❷ 區塊定義'!P121) | J9: =IF(A9="","",IF(B9="",0,B9)*'❷ 區塊定義'!Q25+IF(C9="",0,C9)*'❷ 區塊定義'!Q49+IF(D9="",0,D9)*'❷ 區塊定義'!Q73+IF(E9="",0,E9)*'❷ 區塊定義'!Q97+IF(F9="",0,F9)*'❷ 區塊定義'!Q121) | K9: =IF(A9="","",IF(B9="",0,B9)*'❷ 區塊定義'!R25+IF(C9="",0,C9)*'❷ 區塊定義'!R49+IF(D9="",0,D9)*'❷ 區塊定義'!R73+IF(E9="",0,E9)*'❷ 區塊定義'!R97+IF(F9="",0,F9)*'❷ 區塊定義'!R121) | L9: =IF(A9="","",H9+I9+J9+K9) | M9: =IF(A9="","",IF(B9="",0,B9)*'❷ 區塊定義'!S25+IF(C9="",0,C9)*'❷ 區塊定義'!S49+IF(D9="",0,D9)*'❷ 區塊定義'!S73+IF(E9="",0,E9)*'❷ 區塊定義'!S97+IF(F9="",0,F9)*'❷ 區塊定義'!S121) | N9: =IF(A9="","",IF(B9="",0,B9)*'❷ 區塊定義'!T25+IF(C9="",0,C9)*'❷ 區塊定義'!T49+IF(D9="",0,D9)*'❷ 區塊定義'!T73+IF(E9="",0,E9)*'❷ 區塊定義'!T97+IF(F9="",0,F9)*'❷ 區塊定義'!T121) | O9: =IF(A9="","",IF(B9="",0,B9)*'❷ 區塊定義'!U25+IF(C9="",0,C9)*'❷ 區塊定義'!U49+IF(D9="",0,D9)*'❷ 區塊定義'!U73+IF(E9="",0,E9)*'❷ 區塊定義'!U97+IF(F9="",0,F9)*'❷ 區塊定義'!U121) | P9: =IF(A9="","",IF(B9="",0,B9)*'❷ 區塊定義'!V25+IF(C9="",0,C9)*'❷ 區塊定義'!V49+IF(D9="",0,D9)*'❷ 區塊定義'!V73+IF(E9="",0,E9)*'❷ 區塊定義'!V97+IF(F9="",0,F9)*'❷ 區塊定義'!V121) | Q9: =IF(A9="","",IF(B9="",0,B9)*'❷ 區塊定義'!W25+IF(C9="",0,C9)*'❷ 區塊定義'!W49+IF(D9="",0,D9)*'❷ 區塊定義'!W73+IF(E9="",0,E9)*'❷ 區塊定義'!W97+IF(F9="",0,F9)*'❷ 區塊定義'!W121) | R9: =IF(A9="","",IF(B9="",0,B9)*'❷ 區塊定義'!X25+IF(C9="",0,C9)*'❷ 區塊定義'!X49+IF(D9="",0,D9)*'❷ 區塊定義'!X73+IF(E9="",0,E9)*'❷ 區塊定義'!X97+IF(F9="",0,F9)*'❷ 區塊定義'!X121)
G10: =IF(A10="","",IF(B10="",0,B10)*'❷ 區塊定義'!L25+IF(C10="",0,C10)*'❷ 區塊定義'!L49+IF(D10="",0,D10)*'❷ 區塊定義'!L73+IF(E10="",0,E10)*'❷ 區塊定義'!L97+IF(F10="",0,F10)*'❷ 區塊定義'!L121) | H10: =IF(A10="","",IF(B10="",0,B10)*'❷ 區塊定義'!O25+IF(C10="",0,C10)*'❷ 區塊定義'!O49+IF(D10="",0,D10)*'❷ 區塊定義'!O73+IF(E10="",0,E10)*'❷ 區塊定義'!O97+IF(F10="",0,F10)*'❷ 區塊定義'!O121) | I10: =IF(A10="","",IF(B10="",0,B10)*'❷ 區塊定義'!P25+IF(C10="",0,C10)*'❷ 區塊定義'!P49+IF(D10="",0,D10)*'❷ 區塊定義'!P73+IF(E10="",0,E10)*'❷ 區塊定義'!P97+IF(F10="",0,F10)*'❷ 區塊定義'!P121) | J10: =IF(A10="","",IF(B10="",0,B10)*'❷ 區塊定義'!Q25+IF(C10="",0,C10)*'❷ 區塊定義'!Q49+IF(D10="",0,D10)*'❷ 區塊定義'!Q73+IF(E10="",0,E10)*'❷ 區塊定義'!Q97+IF(F10="",0,F10)*'❷ 區塊定義'!Q121) | K10: =IF(A10="","",IF(B10="",0,B10)*'❷ 區塊定義'!R25+IF(C10="",0,C10)*'❷ 區塊定義'!R49+IF(D10="",0,D10)*'❷ 區塊定義'!R73+IF(E10="",0,E10)*'❷ 區塊定義'!R97+IF(F10="",0,F10)*'❷ 區塊定義'!R121) | L10: =IF(A10="","",H10+I10+J10+K10) | M10: =IF(A10="","",IF(B10="",0,B10)*'❷ 區塊定義'!S25+IF(C10="",0,C10)*'❷ 區塊定義'!S49+IF(D10="",0,D10)*'❷ 區塊定義'!S73+IF(E10="",0,E10)*'❷ 區塊定義'!S97+IF(F10="",0,F10)*'❷ 區塊定義'!S121) | N10: =IF(A10="","",IF(B10="",0,B10)*'❷ 區塊定義'!T25+IF(C10="",0,C10)*'❷ 區塊定義'!T49+IF(D10="",0,D10)*'❷ 區塊定義'!T73+IF(E10="",0,E10)*'❷ 區塊定義'!T97+IF(F10="",0,F10)*'❷ 區塊定義'!T121) | O10: =IF(A10="","",IF(B10="",0,B10)*'❷ 區塊定義'!U25+IF(C10="",0,C10)*'❷ 區塊定義'!U49+IF(D10="",0,D10)*'❷ 區塊定義'!U73+IF(E10="",0,E10)*'❷ 區塊定義'!U97+IF(F10="",0,F10)*'❷ 區塊定義'!U121) | P10: =IF(A10="","",IF(B10="",0,B10)*'❷ 區塊定義'!V25+IF(C10="",0,C10)*'❷ 區塊定義'!V49+IF(D10="",0,D10)*'❷ 區塊定義'!V73+IF(E10="",0,E10)*'❷ 區塊定義'!V97+IF(F10="",0,F10)*'❷ 區塊定義'!V121) | Q10: =IF(A10="","",IF(B10="",0,B10)*'❷ 區塊定義'!W25+IF(C10="",0,C10)*'❷ 區塊定義'!W49+IF(D10="",0,D10)*'❷ 區塊定義'!W73+IF(E10="",0,E10)*'❷ 區塊定義'!W97+IF(F10="",0,F10)*'❷ 區塊定義'!W121) | R10: =IF(A10="","",IF(B10="",0,B10)*'❷ 區塊定義'!X25+IF(C10="",0,C10)*'❷ 區塊定義'!X49+IF(D10="",0,D10)*'❷ 區塊定義'!X73+IF(E10="",0,E10)*'❷ 區塊定義'!X97+IF(F10="",0,F10)*'❷ 區塊定義'!X121)
G11: =IF(A11="","",IF(B11="",0,B11)*'❷ 區塊定義'!L25+IF(C11="",0,C11)*'❷ 區塊定義'!L49+IF(D11="",0,D11)*'❷ 區塊定義'!L73+IF(E11="",0,E11)*'❷ 區塊定義'!L97+IF(F11="",0,F11)*'❷ 區塊定義'!L121) | H11: =IF(A11="","",IF(B11="",0,B11)*'❷ 區塊定義'!O25+IF(C11="",0,C11)*'❷ 區塊定義'!O49+IF(D11="",0,D11)*'❷ 區塊定義'!O73+IF(E11="",0,E11)*'❷ 區塊定義'!O97+IF(F11="",0,F11)*'❷ 區塊定義'!O121) | I11: =IF(A11="","",IF(B11="",0,B11)*'❷ 區塊定義'!P25+IF(C11="",0,C11)*'❷ 區塊定義'!P49+IF(D11="",0,D11)*'❷ 區塊定義'!P73+IF(E11="",0,E11)*'❷ 區塊定義'!P97+IF(F11="",0,F11)*'❷ 區塊定義'!P121) | J11: =IF(A11="","",IF(B11="",0,B11)*'❷ 區塊定義'!Q25+IF(C11="",0,C11)*'❷ 區塊定義'!Q49+IF(D11="",0,D11)*'❷ 區塊定義'!Q73+IF(E11="",0,E11)*'❷ 區塊定義'!Q97+IF(F11="",0,F11)*'❷ 區塊定義'!Q121) | K11: =IF(A11="","",IF(B11="",0,B11)*'❷ 區塊定義'!R25+IF(C11="",0,C11)*'❷ 區塊定義'!R49+IF(D11="",0,D11)*'❷ 區塊定義'!R73+IF(E11="",0,E11)*'❷ 區塊定義'!R97+IF(F11="",0,F11)*'❷ 區塊定義'!R121) | L11: =IF(A11="","",H11+I11+J11+K11) | M11: =IF(A11="","",IF(B11="",0,B11)*'❷ 區塊定義'!S25+IF(C11="",0,C11)*'❷ 區塊定義'!S49+IF(D11="",0,D11)*'❷ 區塊定義'!S73+IF(E11="",0,E11)*'❷ 區塊定義'!S97+IF(F11="",0,F11)*'❷ 區塊定義'!S121) | N11: =IF(A11="","",IF(B11="",0,B11)*'❷ 區塊定義'!T25+IF(C11="",0,C11)*'❷ 區塊定義'!T49+IF(D11="",0,D11)*'❷ 區塊定義'!T73+IF(E11="",0,E11)*'❷ 區塊定義'!T97+IF(F11="",0,F11)*'❷ 區塊定義'!T121) | O11: =IF(A11="","",IF(B11="",0,B11)*'❷ 區塊定義'!U25+IF(C11="",0,C11)*'❷ 區塊定義'!U49+IF(D11="",0,D11)*'❷ 區塊定義'!U73+IF(E11="",0,E11)*'❷ 區塊定義'!U97+IF(F11="",0,F11)*'❷ 區塊定義'!U121) | P11: =IF(A11="","",IF(B11="",0,B11)*'❷ 區塊定義'!V25+IF(C11="",0,C11)*'❷ 區塊定義'!V49+IF(D11="",0,D11)*'❷ 區塊定義'!V73+IF(E11="",0,E11)*'❷ 區塊定義'!V97+IF(F11="",0,F11)*'❷ 區塊定義'!V121) | Q11: =IF(A11="","",IF(B11="",0,B11)*'❷ 區塊定義'!W25+IF(C11="",0,C11)*'❷ 區塊定義'!W49+IF(D11="",0,D11)*'❷ 區塊定義'!W73+IF(E11="",0,E11)*'❷ 區塊定義'!W97+IF(F11="",0,F11)*'❷ 區塊定義'!W121) | R11: =IF(A11="","",IF(B11="",0,B11)*'❷ 區塊定義'!X25+IF(C11="",0,C11)*'❷ 區塊定義'!X49+IF(D11="",0,D11)*'❷ 區塊定義'!X73+IF(E11="",0,E11)*'❷ 區塊定義'!X97+IF(F11="",0,F11)*'❷ 區塊定義'!X121)
G12: =IF(A12="","",IF(B12="",0,B12)*'❷ 區塊定義'!L25+IF(C12="",0,C12)*'❷ 區塊定義'!L49+IF(D12="",0,D12)*'❷ 區塊定義'!L73+IF(E12="",0,E12)*'❷ 區塊定義'!L97+IF(F12="",0,F12)*'❷ 區塊定義'!L121) | H12: =IF(A12="","",IF(B12="",0,B12)*'❷ 區塊定義'!O25+IF(C12="",0,C12)*'❷ 區塊定義'!O49+IF(D12="",0,D12)*'❷ 區塊定義'!O73+IF(E12="",0,E12)*'❷ 區塊定義'!O97+IF(F12="",0,F12)*'❷ 區塊定義'!O121) | I12: =IF(A12="","",IF(B12="",0,B12)*'❷ 區塊定義'!P25+IF(C12="",0,C12)*'❷ 區塊定義'!P49+IF(D12="",0,D12)*'❷ 區塊定義'!P73+IF(E12="",0,E12)*'❷ 區塊定義'!P97+IF(F12="",0,F12)*'❷ 區塊定義'!P121) | J12: =IF(A12="","",IF(B12="",0,B12)*'❷ 區塊定義'!Q25+IF(C12="",0,C12)*'❷ 區塊定義'!Q49+IF(D12="",0,D12)*'❷ 區塊定義'!Q73+IF(E12="",0,E12)*'❷ 區塊定義'!Q97+IF(F12="",0,F12)*'❷ 區塊定義'!Q121) | K12: =IF(A12="","",IF(B12="",0,B12)*'❷ 區塊定義'!R25+IF(C12="",0,C12)*'❷ 區塊定義'!R49+IF(D12="",0,D12)*'❷ 區塊定義'!R73+IF(E12="",0,E12)*'❷ 區塊定義'!R97+IF(F12="",0,F12)*'❷ 區塊定義'!R121) | L12: =IF(A12="","",H12+I12+J12+K12) | M12: =IF(A12="","",IF(B12="",0,B12)*'❷ 區塊定義'!S25+IF(C12="",0,C12)*'❷ 區塊定義'!S49+IF(D12="",0,D12)*'❷ 區塊定義'!S73+IF(E12="",0,E12)*'❷ 區塊定義'!S97+IF(F12="",0,F12)*'❷ 區塊定義'!S121) | N12: =IF(A12="","",IF(B12="",0,B12)*'❷ 區塊定義'!T25+IF(C12="",0,C12)*'❷ 區塊定義'!T49+IF(D12="",0,D12)*'❷ 區塊定義'!T73+IF(E12="",0,E12)*'❷ 區塊定義'!T97+IF(F12="",0,F12)*'❷ 區塊定義'!T121) | O12: =IF(A12="","",IF(B12="",0,B12)*'❷ 區塊定義'!U25+IF(C12="",0,C12)*'❷ 區塊定義'!U49+IF(D12="",0,D12)*'❷ 區塊定義'!U73+IF(E12="",0,E12)*'❷ 區塊定義'!U97+IF(F12="",0,F12)*'❷ 區塊定義'!U121) | P12: =IF(A12="","",IF(B12="",0,B12)*'❷ 區塊定義'!V25+IF(C12="",0,C12)*'❷ 區塊定義'!V49+IF(D12="",0,D12)*'❷ 區塊定義'!V73+IF(E12="",0,E12)*'❷ 區塊定義'!V97+IF(F12="",0,F12)*'❷ 區塊定義'!V121) | Q12: =IF(A12="","",IF(B12="",0,B12)*'❷ 區塊定義'!W25+IF(C12="",0,C12)*'❷ 區塊定義'!W49+IF(D12="",0,D12)*'❷ 區塊定義'!W73+IF(E12="",0,E12)*'❷ 區塊定義'!W97+IF(F12="",0,F12)*'❷ 區塊定義'!W121) | R12: =IF(A12="","",IF(B12="",0,B12)*'❷ 區塊定義'!X25+IF(C12="",0,C12)*'❷ 區塊定義'!X49+IF(D12="",0,D12)*'❷ 區塊定義'!X73+IF(E12="",0,E12)*'❷ 區塊定義'!X97+IF(F12="",0,F12)*'❷ 區塊定義'!X121)
G13: =IF(A13="","",IF(B13="",0,B13)*'❷ 區塊定義'!L25+IF(C13="",0,C13)*'❷ 區塊定義'!L49+IF(D13="",0,D13)*'❷ 區塊定義'!L73+IF(E13="",0,E13)*'❷ 區塊定義'!L97+IF(F13="",0,F13)*'❷ 區塊定義'!L121) | H13: =IF(A13="","",IF(B13="",0,B13)*'❷ 區塊定義'!O25+IF(C13="",0,C13)*'❷ 區塊定義'!O49+IF(D13="",0,D13)*'❷ 區塊定義'!O73+IF(E13="",0,E13)*'❷ 區塊定義'!O97+IF(F13="",0,F13)*'❷ 區塊定義'!O121) | I13: =IF(A13="","",IF(B13="",0,B13)*'❷ 區塊定義'!P25+IF(C13="",0,C13)*'❷ 區塊定義'!P49+IF(D13="",0,D13)*'❷ 區塊定義'!P73+IF(E13="",0,E13)*'❷ 區塊定義'!P97+IF(F13="",0,F13)*'❷ 區塊定義'!P121) | J13: =IF(A13="","",IF(B13="",0,B13)*'❷ 區塊定義'!Q25+IF(C13="",0,C13)*'❷ 區塊定義'!Q49+IF(D13="",0,D13)*'❷ 區塊定義'!Q73+IF(E13="",0,E13)*'❷ 區塊定義'!Q97+IF(F13="",0,F13)*'❷ 區塊定義'!Q121) | K13: =IF(A13="","",IF(B13="",0,B13)*'❷ 區塊定義'!R25+IF(C13="",0,C13)*'❷ 區塊定義'!R49+IF(D13="",0,D13)*'❷ 區塊定義'!R73+IF(E13="",0,E13)*'❷ 區塊定義'!R97+IF(F13="",0,F13)*'❷ 區塊定義'!R121) | L13: =IF(A13="","",H13+I13+J13+K13) | M13: =IF(A13="","",IF(B13="",0,B13)*'❷ 區塊定義'!S25+IF(C13="",0,C13)*'❷ 區塊定義'!S49+IF(D13="",0,D13)*'❷ 區塊定義'!S73+IF(E13="",0,E13)*'❷ 區塊定義'!S97+IF(F13="",0,F13)*'❷ 區塊定義'!S121) | N13: =IF(A13="","",IF(B13="",0,B13)*'❷ 區塊定義'!T25+IF(C13="",0,C13)*'❷ 區塊定義'!T49+IF(D13="",0,D13)*'❷ 區塊定義'!T73+IF(E13="",0,E13)*'❷ 區塊定義'!T97+IF(F13="",0,F13)*'❷ 區塊定義'!T121) | O13: =IF(A13="","",IF(B13="",0,B13)*'❷ 區塊定義'!U25+IF(C13="",0,C13)*'❷ 區塊定義'!U49+IF(D13="",0,D13)*'❷ 區塊定義'!U73+IF(E13="",0,E13)*'❷ 區塊定義'!U97+IF(F13="",0,F13)*'❷ 區塊定義'!U121) | P13: =IF(A13="","",IF(B13="",0,B13)*'❷ 區塊定義'!V25+IF(C13="",0,C13)*'❷ 區塊定義'!V49+IF(D13="",0,D13)*'❷ 區塊定義'!V73+IF(E13="",0,E13)*'❷ 區塊定義'!V97+IF(F13="",0,F13)*'❷ 區塊定義'!V121) | Q13: =IF(A13="","",IF(B13="",0,B13)*'❷ 區塊定義'!W25+IF(C13="",0,C13)*'❷ 區塊定義'!W49+IF(D13="",0,D13)*'❷ 區塊定義'!W73+IF(E13="",0,E13)*'❷ 區塊定義'!W97+IF(F13="",0,F13)*'❷ 區塊定義'!W121) | R13: =IF(A13="","",IF(B13="",0,B13)*'❷ 區塊定義'!X25+IF(C13="",0,C13)*'❷ 區塊定義'!X49+IF(D13="",0,D13)*'❷ 區塊定義'!X73+IF(E13="",0,E13)*'❷ 區塊定義'!X97+IF(F13="",0,F13)*'❷ 區塊定義'!X121)
G14: =IF(A14="","",IF(B14="",0,B14)*'❷ 區塊定義'!L25+IF(C14="",0,C14)*'❷ 區塊定義'!L49+IF(D14="",0,D14)*'❷ 區塊定義'!L73+IF(E14="",0,E14)*'❷ 區塊定義'!L97+IF(F14="",0,F14)*'❷ 區塊定義'!L121) | H14: =IF(A14="","",IF(B14="",0,B14)*'❷ 區塊定義'!O25+IF(C14="",0,C14)*'❷ 區塊定義'!O49+IF(D14="",0,D14)*'❷ 區塊定義'!O73+IF(E14="",0,E14)*'❷ 區塊定義'!O97+IF(F14="",0,F14)*'❷ 區塊定義'!O121) | I14: =IF(A14="","",IF(B14="",0,B14)*'❷ 區塊定義'!P25+IF(C14="",0,C14)*'❷ 區塊定義'!P49+IF(D14="",0,D14)*'❷ 區塊定義'!P73+IF(E14="",0,E14)*'❷ 區塊定義'!P97+IF(F14="",0,F14)*'❷ 區塊定義'!P121) | J14: =IF(A14="","",IF(B14="",0,B14)*'❷ 區塊定義'!Q25+IF(C14="",0,C14)*'❷ 區塊定義'!Q49+IF(D14="",0,D14)*'❷ 區塊定義'!Q73+IF(E14="",0,E14)*'❷ 區塊定義'!Q97+IF(F14="",0,F14)*'❷ 區塊定義'!Q121) | K14: =IF(A14="","",IF(B14="",0,B14)*'❷ 區塊定義'!R25+IF(C14="",0,C14)*'❷ 區塊定義'!R49+IF(D14="",0,D14)*'❷ 區塊定義'!R73+IF(E14="",0,E14)*'❷ 區塊定義'!R97+IF(F14="",0,F14)*'❷ 區塊定義'!R121) | L14: =IF(A14="","",H14+I14+J14+K14) | M14: =IF(A14="","",IF(B14="",0,B14)*'❷ 區塊定義'!S25+IF(C14="",0,C14)*'❷ 區塊定義'!S49+IF(D14="",0,D14)*'❷ 區塊定義'!S73+IF(E14="",0,E14)*'❷ 區塊定義'!S97+IF(F14="",0,F14)*'❷ 區塊定義'!S121) | N14: =IF(A14="","",IF(B14="",0,B14)*'❷ 區塊定義'!T25+IF(C14="",0,C14)*'❷ 區塊定義'!T49+IF(D14="",0,D14)*'❷ 區塊定義'!T73+IF(E14="",0,E14)*'❷ 區塊定義'!T97+IF(F14="",0,F14)*'❷ 區塊定義'!T121) | O14: =IF(A14="","",IF(B14="",0,B14)*'❷ 區塊定義'!U25+IF(C14="",0,C14)*'❷ 區塊定義'!U49+IF(D14="",0,D14)*'❷ 區塊定義'!U73+IF(E14="",0,E14)*'❷ 區塊定義'!U97+IF(F14="",0,F14)*'❷ 區塊定義'!U121) | P14: =IF(A14="","",IF(B14="",0,B14)*'❷ 區塊定義'!V25+IF(C14="",0,C14)*'❷ 區塊定義'!V49+IF(D14="",0,D14)*'❷ 區塊定義'!V73+IF(E14="",0,E14)*'❷ 區塊定義'!V97+IF(F14="",0,F14)*'❷ 區塊定義'!V121) | Q14: =IF(A14="","",IF(B14="",0,B14)*'❷ 區塊定義'!W25+IF(C14="",0,C14)*'❷ 區塊定義'!W49+IF(D14="",0,D14)*'❷ 區塊定義'!W73+IF(E14="",0,E14)*'❷ 區塊定義'!W97+IF(F14="",0,F14)*'❷ 區塊定義'!W121) | R14: =IF(A14="","",IF(B14="",0,B14)*'❷ 區塊定義'!X25+IF(C14="",0,C14)*'❷ 區塊定義'!X49+IF(D14="",0,D14)*'❷ 區塊定義'!X73+IF(E14="",0,E14)*'❷ 區塊定義'!X97+IF(F14="",0,F14)*'❷ 區塊定義'!X121)
G15: =IF(A15="","",IF(B15="",0,B15)*'❷ 區塊定義'!L25+IF(C15="",0,C15)*'❷ 區塊定義'!L49+IF(D15="",0,D15)*'❷ 區塊定義'!L73+IF(E15="",0,E15)*'❷ 區塊定義'!L97+IF(F15="",0,F15)*'❷ 區塊定義'!L121) | H15: =IF(A15="","",IF(B15="",0,B15)*'❷ 區塊定義'!O25+IF(C15="",0,C15)*'❷ 區塊定義'!O49+IF(D15="",0,D15)*'❷ 區塊定義'!O73+IF(E15="",0,E15)*'❷ 區塊定義'!O97+IF(F15="",0,F15)*'❷ 區塊定義'!O121) | I15: =IF(A15="","",IF(B15="",0,B15)*'❷ 區塊定義'!P25+IF(C15="",0,C15)*'❷ 區塊定義'!P49+IF(D15="",0,D15)*'❷ 區塊定義'!P73+IF(E15="",0,E15)*'❷ 區塊定義'!P97+IF(F15="",0,F15)*'❷ 區塊定義'!P121) | J15: =IF(A15="","",IF(B15="",0,B15)*'❷ 區塊定義'!Q25+IF(C15="",0,C15)*'❷ 區塊定義'!Q49+IF(D15="",0,D15)*'❷ 區塊定義'!Q73+IF(E15="",0,E15)*'❷ 區塊定義'!Q97+IF(F15="",0,F15)*'❷ 區塊定義'!Q121) | K15: =IF(A15="","",IF(B15="",0,B15)*'❷ 區塊定義'!R25+IF(C15="",0,C15)*'❷ 區塊定義'!R49+IF(D15="",0,D15)*'❷ 區塊定義'!R73+IF(E15="",0,E15)*'❷ 區塊定義'!R97+IF(F15="",0,F15)*'❷ 區塊定義'!R121) | L15: =IF(A15="","",H15+I15+J15+K15) | M15: =IF(A15="","",IF(B15="",0,B15)*'❷ 區塊定義'!S25+IF(C15="",0,C15)*'❷ 區塊定義'!S49+IF(D15="",0,D15)*'❷ 區塊定義'!S73+IF(E15="",0,E15)*'❷ 區塊定義'!S97+IF(F15="",0,F15)*'❷ 區塊定義'!S121) | N15: =IF(A15="","",IF(B15="",0,B15)*'❷ 區塊定義'!T25+IF(C15="",0,C15)*'❷ 區塊定義'!T49+IF(D15="",0,D15)*'❷ 區塊定義'!T73+IF(E15="",0,E15)*'❷ 區塊定義'!T97+IF(F15="",0,F15)*'❷ 區塊定義'!T121) | O15: =IF(A15="","",IF(B15="",0,B15)*'❷ 區塊定義'!U25+IF(C15="",0,C15)*'❷ 區塊定義'!U49+IF(D15="",0,D15)*'❷ 區塊定義'!U73+IF(E15="",0,E15)*'❷ 區塊定義'!U97+IF(F15="",0,F15)*'❷ 區塊定義'!U121) | P15: =IF(A15="","",IF(B15="",0,B15)*'❷ 區塊定義'!V25+IF(C15="",0,C15)*'❷ 區塊定義'!V49+IF(D15="",0,D15)*'❷ 區塊定義'!V73+IF(E15="",0,E15)*'❷ 區塊定義'!V97+IF(F15="",0,F15)*'❷ 區塊定義'!V121) | Q15: =IF(A15="","",IF(B15="",0,B15)*'❷ 區塊定義'!W25+IF(C15="",0,C15)*'❷ 區塊定義'!W49+IF(D15="",0,D15)*'❷ 區塊定義'!W73+IF(E15="",0,E15)*'❷ 區塊定義'!W97+IF(F15="",0,F15)*'❷ 區塊定義'!W121) | R15: =IF(A15="","",IF(B15="",0,B15)*'❷ 區塊定義'!X25+IF(C15="",0,C15)*'❷ 區塊定義'!X49+IF(D15="",0,D15)*'❷ 區塊定義'!X73+IF(E15="",0,E15)*'❷ 區塊定義'!X97+IF(F15="",0,F15)*'❷ 區塊定義'!X121)
G16: =IF(A16="","",IF(B16="",0,B16)*'❷ 區塊定義'!L25+IF(C16="",0,C16)*'❷ 區塊定義'!L49+IF(D16="",0,D16)*'❷ 區塊定義'!L73+IF(E16="",0,E16)*'❷ 區塊定義'!L97+IF(F16="",0,F16)*'❷ 區塊定義'!L121) | H16: =IF(A16="","",IF(B16="",0,B16)*'❷ 區塊定義'!O25+IF(C16="",0,C16)*'❷ 區塊定義'!O49+IF(D16="",0,D16)*'❷ 區塊定義'!O73+IF(E16="",0,E16)*'❷ 區塊定義'!O97+IF(F16="",0,F16)*'❷ 區塊定義'!O121) | I16: =IF(A16="","",IF(B16="",0,B16)*'❷ 區塊定義'!P25+IF(C16="",0,C16)*'❷ 區塊定義'!P49+IF(D16="",0,D16)*'❷ 區塊定義'!P73+IF(E16="",0,E16)*'❷ 區塊定義'!P97+IF(F16="",0,F16)*'❷ 區塊定義'!P121) | J16: =IF(A16="","",IF(B16="",0,B16)*'❷ 區塊定義'!Q25+IF(C16="",0,C16)*'❷ 區塊定義'!Q49+IF(D16="",0,D16)*'❷ 區塊定義'!Q73+IF(E16="",0,E16)*'❷ 區塊定義'!Q97+IF(F16="",0,F16)*'❷ 區塊定義'!Q121) | K16: =IF(A16="","",IF(B16="",0,B16)*'❷ 區塊定義'!R25+IF(C16="",0,C16)*'❷ 區塊定義'!R49+IF(D16="",0,D16)*'❷ 區塊定義'!R73+IF(E16="",0,E16)*'❷ 區塊定義'!R97+IF(F16="",0,F16)*'❷ 區塊定義'!R121) | L16: =IF(A16="","",H16+I16+J16+K16) | M16: =IF(A16="","",IF(B16="",0,B16)*'❷ 區塊定義'!S25+IF(C16="",0,C16)*'❷ 區塊定義'!S49+IF(D16="",0,D16)*'❷ 區塊定義'!S73+IF(E16="",0,E16)*'❷ 區塊定義'!S97+IF(F16="",0,F16)*'❷ 區塊定義'!S121) | N16: =IF(A16="","",IF(B16="",0,B16)*'❷ 區塊定義'!T25+IF(C16="",0,C16)*'❷ 區塊定義'!T49+IF(D16="",0,D16)*'❷ 區塊定義'!T73+IF(E16="",0,E16)*'❷ 區塊定義'!T97+IF(F16="",0,F16)*'❷ 區塊定義'!T121) | O16: =IF(A16="","",IF(B16="",0,B16)*'❷ 區塊定義'!U25+IF(C16="",0,C16)*'❷ 區塊定義'!U49+IF(D16="",0,D16)*'❷ 區塊定義'!U73+IF(E16="",0,E16)*'❷ 區塊定義'!U97+IF(F16="",0,F16)*'❷ 區塊定義'!U121) | P16: =IF(A16="","",IF(B16="",0,B16)*'❷ 區塊定義'!V25+IF(C16="",0,C16)*'❷ 區塊定義'!V49+IF(D16="",0,D16)*'❷ 區塊定義'!V73+IF(E16="",0,E16)*'❷ 區塊定義'!V97+IF(F16="",0,F16)*'❷ 區塊定義'!V121) | Q16: =IF(A16="","",IF(B16="",0,B16)*'❷ 區塊定義'!W25+IF(C16="",0,C16)*'❷ 區塊定義'!W49+IF(D16="",0,D16)*'❷ 區塊定義'!W73+IF(E16="",0,E16)*'❷ 區塊定義'!W97+IF(F16="",0,F16)*'❷ 區塊定義'!W121) | R16: =IF(A16="","",IF(B16="",0,B16)*'❷ 區塊定義'!X25+IF(C16="",0,C16)*'❷ 區塊定義'!X49+IF(D16="",0,D16)*'❷ 區塊定義'!X73+IF(E16="",0,E16)*'❷ 區塊定義'!X97+IF(F16="",0,F16)*'❷ 區塊定義'!X121)
G17: =IF(A17="","",IF(B17="",0,B17)*'❷ 區塊定義'!L25+IF(C17="",0,C17)*'❷ 區塊定義'!L49+IF(D17="",0,D17)*'❷ 區塊定義'!L73+IF(E17="",0,E17)*'❷ 區塊定義'!L97+IF(F17="",0,F17)*'❷ 區塊定義'!L121) | H17: =IF(A17="","",IF(B17="",0,B17)*'❷ 區塊定義'!O25+IF(C17="",0,C17)*'❷ 區塊定義'!O49+IF(D17="",0,D17)*'❷ 區塊定義'!O73+IF(E17="",0,E17)*'❷ 區塊定義'!O97+IF(F17="",0,F17)*'❷ 區塊定義'!O121) | I17: =IF(A17="","",IF(B17="",0,B17)*'❷ 區塊定義'!P25+IF(C17="",0,C17)*'❷ 區塊定義'!P49+IF(D17="",0,D17)*'❷ 區塊定義'!P73+IF(E17="",0,E17)*'❷ 區塊定義'!P97+IF(F17="",0,F17)*'❷ 區塊定義'!P121) | J17: =IF(A17="","",IF(B17="",0,B17)*'❷ 區塊定義'!Q25+IF(C17="",0,C17)*'❷ 區塊定義'!Q49+IF(D17="",0,D17)*'❷ 區塊定義'!Q73+IF(E17="",0,E17)*'❷ 區塊定義'!Q97+IF(F17="",0,F17)*'❷ 區塊定義'!Q121) | K17: =IF(A17="","",IF(B17="",0,B17)*'❷ 區塊定義'!R25+IF(C17="",0,C17)*'❷ 區塊定義'!R49+IF(D17="",0,D17)*'❷ 區塊定義'!R73+IF(E17="",0,E17)*'❷ 區塊定義'!R97+IF(F17="",0,F17)*'❷ 區塊定義'!R121) | L17: =IF(A17="","",H17+I17+J17+K17) | M17: =IF(A17="","",IF(B17="",0,B17)*'❷ 區塊定義'!S25+IF(C17="",0,C17)*'❷ 區塊定義'!S49+IF(D17="",0,D17)*'❷ 區塊定義'!S73+IF(E17="",0,E17)*'❷ 區塊定義'!S97+IF(F17="",0,F17)*'❷ 區塊定義'!S121) | N17: =IF(A17="","",IF(B17="",0,B17)*'❷ 區塊定義'!T25+IF(C17="",0,C17)*'❷ 區塊定義'!T49+IF(D17="",0,D17)*'❷ 區塊定義'!T73+IF(E17="",0,E17)*'❷ 區塊定義'!T97+IF(F17="",0,F17)*'❷ 區塊定義'!T121) | O17: =IF(A17="","",IF(B17="",0,B17)*'❷ 區塊定義'!U25+IF(C17="",0,C17)*'❷ 區塊定義'!U49+IF(D17="",0,D17)*'❷ 區塊定義'!U73+IF(E17="",0,E17)*'❷ 區塊定義'!U97+IF(F17="",0,F17)*'❷ 區塊定義'!U121) | P17: =IF(A17="","",IF(B17="",0,B17)*'❷ 區塊定義'!V25+IF(C17="",0,C17)*'❷ 區塊定義'!V49+IF(D17="",0,D17)*'❷ 區塊定義'!V73+IF(E17="",0,E17)*'❷ 區塊定義'!V97+IF(F17="",0,F17)*'❷ 區塊定義'!V121) | Q17: =IF(A17="","",IF(B17="",0,B17)*'❷ 區塊定義'!W25+IF(C17="",0,C17)*'❷ 區塊定義'!W49+IF(D17="",0,D17)*'❷ 區塊定義'!W73+IF(E17="",0,E17)*'❷ 區塊定義'!W97+IF(F17="",0,F17)*'❷ 區塊定義'!W121) | R17: =IF(A17="","",IF(B17="",0,B17)*'❷ 區塊定義'!X25+IF(C17="",0,C17)*'❷ 區塊定義'!X49+IF(D17="",0,D17)*'❷ 區塊定義'!X73+IF(E17="",0,E17)*'❷ 區塊定義'!X97+IF(F17="",0,F17)*'❷ 區塊定義'!X121)
G18: =IF(A18="","",IF(B18="",0,B18)*'❷ 區塊定義'!L25+IF(C18="",0,C18)*'❷ 區塊定義'!L49+IF(D18="",0,D18)*'❷ 區塊定義'!L73+IF(E18="",0,E18)*'❷ 區塊定義'!L97+IF(F18="",0,F18)*'❷ 區塊定義'!L121) | H18: =IF(A18="","",IF(B18="",0,B18)*'❷ 區塊定義'!O25+IF(C18="",0,C18)*'❷ 區塊定義'!O49+IF(D18="",0,D18)*'❷ 區塊定義'!O73+IF(E18="",0,E18)*'❷ 區塊定義'!O97+IF(F18="",0,F18)*'❷ 區塊定義'!O121) | I18: =IF(A18="","",IF(B18="",0,B18)*'❷ 區塊定義'!P25+IF(C18="",0,C18)*'❷ 區塊定義'!P49+IF(D18="",0,D18)*'❷ 區塊定義'!P73+IF(E18="",0,E18)*'❷ 區塊定義'!P97+IF(F18="",0,F18)*'❷ 區塊定義'!P121) | J18: =IF(A18="","",IF(B18="",0,B18)*'❷ 區塊定義'!Q25+IF(C18="",0,C18)*'❷ 區塊定義'!Q49+IF(D18="",0,D18)*'❷ 區塊定義'!Q73+IF(E18="",0,E18)*'❷ 區塊定義'!Q97+IF(F18="",0,F18)*'❷ 區塊定義'!Q121) | K18: =IF(A18="","",IF(B18="",0,B18)*'❷ 區塊定義'!R25+IF(C18="",0,C18)*'❷ 區塊定義'!R49+IF(D18="",0,D18)*'❷ 區塊定義'!R73+IF(E18="",0,E18)*'❷ 區塊定義'!R97+IF(F18="",0,F18)*'❷ 區塊定義'!R121) | L18: =IF(A18="","",H18+I18+J18+K18) | M18: =IF(A18="","",IF(B18="",0,B18)*'❷ 區塊定義'!S25+IF(C18="",0,C18)*'❷ 區塊定義'!S49+IF(D18="",0,D18)*'❷ 區塊定義'!S73+IF(E18="",0,E18)*'❷ 區塊定義'!S97+IF(F18="",0,F18)*'❷ 區塊定義'!S121) | N18: =IF(A18="","",IF(B18="",0,B18)*'❷ 區塊定義'!T25+IF(C18="",0,C18)*'❷ 區塊定義'!T49+IF(D18="",0,D18)*'❷ 區塊定義'!T73+IF(E18="",0,E18)*'❷ 區塊定義'!T97+IF(F18="",0,F18)*'❷ 區塊定義'!T121) | O18: =IF(A18="","",IF(B18="",0,B18)*'❷ 區塊定義'!U25+IF(C18="",0,C18)*'❷ 區塊定義'!U49+IF(D18="",0,D18)*'❷ 區塊定義'!U73+IF(E18="",0,E18)*'❷ 區塊定義'!U97+IF(F18="",0,F18)*'❷ 區塊定義'!U121) | P18: =IF(A18="","",IF(B18="",0,B18)*'❷ 區塊定義'!V25+IF(C18="",0,C18)*'❷ 區塊定義'!V49+IF(D18="",0,D18)*'❷ 區塊定義'!V73+IF(E18="",0,E18)*'❷ 區塊定義'!V97+IF(F18="",0,F18)*'❷ 區塊定義'!V121) | Q18: =IF(A18="","",IF(B18="",0,B18)*'❷ 區塊定義'!W25+IF(C18="",0,C18)*'❷ 區塊定義'!W49+IF(D18="",0,D18)*'❷ 區塊定義'!W73+IF(E18="",0,E18)*'❷ 區塊定義'!W97+IF(F18="",0,F18)*'❷ 區塊定義'!W121) | R18: =IF(A18="","",IF(B18="",0,B18)*'❷ 區塊定義'!X25+IF(C18="",0,C18)*'❷ 區塊定義'!X49+IF(D18="",0,D18)*'❷ 區塊定義'!X73+IF(E18="",0,E18)*'❷ 區塊定義'!X97+IF(F18="",0,F18)*'❷ 區塊定義'!X121)
A19: 區塊合計 | G19: =SUM(G4:G18) -> 287437.73 | H19: =SUM(H4:H18) -> 1999.164 | I19: =SUM(I4:I18) -> 338.88 | J19: =SUM(J4:J18) -> 1209.6 | K19: =SUM(K4:K18) -> 0 | L19: =SUM(L4:L18) -> 3547.644 | M19: =SUM(M4:M18) -> 274933.73 | N19: =SUM(N4:N18) -> 12504 | ... R19: =SUM(R4:R18) -> 0
A22: ▎ 零星構件
A23: ▼快速篩選 | B23: 構件名稱 | C23: ▼規格 | D23: ▼材質 | E23: 長度(mm) | F23: 數量 | G23: ▼塗裝類型 | H23: 塗裝長度 (mm)空白=全塗 | I23: ▼扣梁上面積 | J23: 單位重 | K23: 表面積 (m²/m) | L23: 重量(kg) | M23: 塗裝面積 (m²)
J24: =IFERROR(VLOOKUP(C24,規格資料庫!$A$2:$E$162,3,FALSE()),"") | K24: =IFERROR(VLOOKUP(C24,規格資料庫!$A$2:$E$162,4,FALSE()),"") | L24: =IF(J24="","",J24*E24/1000*F24) | M24: =IF(OR(C24="",G24="",G24="無"),"",IFERROR(K24*IF(OR(H24="",H24=0),E24,H24)/1000*F24-IF(I24="是",VLOOKUP(C24,規格資料庫!$A$2:$E$162,5,FALSE())/1000*IF(OR(H24="",H24=0),E24,H24)/1000*F24,0),"")) | N24: =IFERROR(VLOOKUP(C24,規格資料庫!$A$2:$B$162,2,FALSE()),"")
J25: =IFERROR(VLOOKUP(C25,規格資料庫!$A$2:$E$162,3,FALSE()),"") | K25: =IFERROR(VLOOKUP(C25,規格資料庫!$A$2:$E$162,4,FALSE()),"") | L25: =IF(J25="","",J25*E25/1000*F25) | M25: =IF(OR(C25="",G25="",G25="無"),"",IFERROR(K25*IF(OR(H25="",H25=0),E25,H25)/1000*F25-IF(I25="是",VLOOKUP(C25,規格資料庫!$A$2:$E$162,5,FALSE())/1000*IF(OR(H25="",H25=0),E25,H25)/1000*F25,0),"")) | N25: =IFERROR(VLOOKUP(C25,規格資料庫!$A$2:$B$162,2,FALSE()),"")
J26: =IFERROR(VLOOKUP(C26,規格資料庫!$A$2:$E$162,3,FALSE()),"") | K26: =IFERROR(VLOOKUP(C26,規格資料庫!$A$2:$E$162,4,FALSE()),"") | L26: =IF(J26="","",J26*E26/1000*F26) | M26: =IF(OR(C26="",G26="",G26="無"),"",IFERROR(K26*IF(OR(H26="",H26=0),E26,H26)/1000*F26-IF(I26="是",VLOOKUP(C26,規格資料庫!$A$2:$E$162,5,FALSE())/1000*IF(OR(H26="",H26=0),E26,H26)/1000*F26,0),"")) | N26: =IFERROR(VLOOKUP(C26,規格資料庫!$A$2:$B$162,2,FALSE()),"")
J27: =IFERROR(VLOOKUP(C27,規格資料庫!$A$2:$E$162,3,FALSE()),"") | K27: =IFERROR(VLOOKUP(C27,規格資料庫!$A$2:$E$162,4,FALSE()),"") | L27: =IF(J27="","",J27*E27/1000*F27) | M27: =IF(OR(C27="",G27="",G27="無"),"",IFERROR(K27*IF(OR(H27="",H27=0),E27,H27)/1000*F27-IF(I27="是",VLOOKUP(C27,規格資料庫!$A$2:$E$162,5,FALSE())/1000*IF(OR(H27="",H27=0),E27,H27)/1000*F27,0),"")) | N27: =IFERROR(VLOOKUP(C27,規格資料庫!$A$2:$B$162,2,FALSE()),"")
J28: =IFERROR(VLOOKUP(C28,規格資料庫!$A$2:$E$162,3,FALSE()),"") | K28: =IFERROR(VLOOKUP(C28,規格資料庫!$A$2:$E$162,4,FALSE()),"") | L28: =IF(J28="","",J28*E28/1000*F28) | M28: =IF(OR(C28="",G28="",G28="無"),"",IFERROR(K28*IF(OR(H28="",H28=0),E28,H28)/1000*F28-IF(I28="是",VLOOKUP(C28,規格資料庫!$A$2:$E$162,5,FALSE())/1000*IF(OR(H28="",H28=0),E28,H28)/1000*F28,0),"")) | N28: =IFERROR(VLOOKUP(C28,規格資料庫!$A$2:$B$162,2,FALSE()),"")
J29: =IFERROR(VLOOKUP(C29,規格資料庫!$A$2:$E$162,3,FALSE()),"") | K29: =IFERROR(VLOOKUP(C29,規格資料庫!$A$2:$E$162,4,FALSE()),"") | L29: =IF(J29="","",J29*E29/1000*F29) | M29: =IF(OR(C29="",G29="",G29="無"),"",IFERROR(K29*IF(OR(H29="",H29=0),E29,H29)/1000*F29-IF(I29="是",VLOOKUP(C29,規格資料庫!$A$2:$E$162,5,FALSE())/1000*IF(OR(H29="",H29=0),E29,H29)/1000*F29,0),"")) | N29: =IFERROR(VLOOKUP(C29,規格資料庫!$A$2:$B$162,2,FALSE()),"")
J30: =IFERROR(VLOOKUP(C30,規格資料庫!$A$2:$E$162,3,FALSE()),"") | K30: =IFERROR(VLOOKUP(C30,規格資料庫!$A$2:$E$162,4,FALSE()),"") | L30: =IF(J30="","",J30*E30/1000*F30) | M30: =IF(OR(C30="",G30="",G30="無"),"",IFERROR(K30*IF(OR(H30="",H30=0),E30,H30)/1000*F30-IF(I30="是",VLOOKUP(C30,規格資料庫!$A$2:$E$162,5,FALSE())/1000*IF(OR(H30="",H30=0),E30,H30)/1000*F30,0),"")) | N30: =IFERROR(VLOOKUP(C30,規格資料庫!$A$2:$B$162,2,FALSE()),"")
J31: =IFERROR(VLOOKUP(C31,規格資料庫!$A$2:$E$162,3,FALSE()),"") | K31: =IFERROR(VLOOKUP(C31,規格資料庫!$A$2:$E$162,4,FALSE()),"") | L31: =IF(J31="","",J31*E31/1000*F31) | M31: =IF(OR(C31="",G31="",G31="無"),"",IFERROR(K31*IF(OR(H31="",H31=0),E31,H31)/1000*F31-IF(I31="是",VLOOKUP(C31,規格資料庫!$A$2:$E$162,5,FALSE())/1000*IF(OR(H31="",H31=0),E31,H31)/1000*F31,0),"")) | N31: =IFERROR(VLOOKUP(C31,規格資料庫!$A$2:$B$162,2,FALSE()),"")
J32: =IFERROR(VLOOKUP(C32,規格資料庫!$A$2:$E$162,3,FALSE()),"") | K32: =IFERROR(VLOOKUP(C32,規格資料庫!$A$2:$E$162,4,FALSE()),"") | L32: =IF(J32="","",J32*E32/1000*F32) | M32: =IF(OR(C32="",G32="",G32="無"),"",IFERROR(K32*IF(OR(H32="",H32=0),E32,H32)/1000*F32-IF(I32="是",VLOOKUP(C32,規格資料庫!$A$2:$E$162,5,FALSE())/1000*IF(OR(H32="",H32=0),E32,H32)/1000*F32,0),"")) | N32: =IFERROR(VLOOKUP(C32,規格資料庫!$A$2:$B$162,2,FALSE()),"")
J33: =IFERROR(VLOOKUP(C33,規格資料庫!$A$2:$E$162,3,FALSE()),"") | K33: =IFERROR(VLOOKUP(C33,規格資料庫!$A$2:$E$162,4,FALSE()),"") | L33: =IF(J33="","",J33*E33/1000*F33) | M33: =IF(OR(C33="",G33="",G33="無"),"",IFERROR(K33*IF(OR(H33="",H33=0),E33,H33)/1000*F33-IF(I33="是",VLOOKUP(C33,規格資料庫!$A$2:$E$162,5,FALSE())/1000*IF(OR(H33="",H33=0),E33,H33)/1000*F33,0),"")) | N33: =IFERROR(VLOOKUP(C33,規格資料庫!$A$2:$B$162,2,FALSE()),"")
J34: =IFERROR(VLOOKUP(C34,規格資料庫!$A$2:$E$162,3,FALSE()),"") | K34: =IFERROR(VLOOKUP(C34,規格資料庫!$A$2:$E$162,4,FALSE()),"") | L34: =IF(J34="","",J34*E34/1000*F34) | M34: =IF(OR(C34="",G34="",G34="無"),"",IFERROR(K34*IF(OR(H34="",H34=0),E34,H34)/1000*F34-IF(I34="是",VLOOKUP(C34,規格資料庫!$A$2:$E$162,5,FALSE())/1000*IF(OR(H34="",H34=0),E34,H34)/1000*F34,0),"")) | N34: =IFERROR(VLOOKUP(C34,規格資料庫!$A$2:$B$162,2,FALSE()),"")
J35: =IFERROR(VLOOKUP(C35,規格資料庫!$A$2:$E$162,3,FALSE()),"") | K35: =IFERROR(VLOOKUP(C35,規格資料庫!$A$2:$E$162,4,FALSE()),"") | L35: =IF(J35="","",J35*E35/1000*F35) | M35: =IF(OR(C35="",G35="",G35="無"),"",IFERROR(K35*IF(OR(H35="",H35=0),E35,H35)/1000*F35-IF(I35="是",VLOOKUP(C35,規格資料庫!$A$2:$E$162,5,FALSE())/1000*IF(OR(H35="",H35=0),E35,H35)/1000*F35,0),"")) | N35: =IFERROR(VLOOKUP(C35,規格資料庫!$A$2:$B$162,2,FALSE()),"")
... J38: =IFERROR(VLOOKUP(C38,規格資料庫!$A$2:$E$162,3,FALSE()),"") | K38: =IFERROR(VLOOKUP(C38,規格資料庫!$A$2:$E$162,4,FALSE()),"") | L38: =IF(J38="","",J38*E38/1000*F38) | M38: =IF(OR(C38="",G38="",G38="無"),"",IFERROR(K38*IF(OR(H38="",H38=0),E38,H38)/1000*F38-IF(I38="是",VLOOKUP(C38,規格資料庫!$A$2:$E$162,5,FALSE())/1000*IF(OR(H38="",H38=0),E38,H38)/1000*F38,0),"")) | N38: =IFERROR(VLOOKUP(C38,規格資料庫!$A$2:$B$162,2,FALSE()),"")
A39: 零星合計 | L39: =SUM(L24:L38) -> 0 | M39: =SUM(M24:M38) -> 0 | O39: =SUMIF(G24:G38,"油漆",M24:M38) -> 0 | P39: =SUMIF(G24:G38,"防火漆1hr",M24:M38) -> 0 | Q39: =SUMIF(G24:G38,"防火漆2hr",M24:M38) -> 0 | R39: =SUMIF(G24:G38,"防火批覆",M24:M38) -> 0 | S39: =SUMPRODUCT((D24:D38="SN400B")*IF(ISNUMBER(L24:L38),L24:L38,0)) -> 0 | T39: =SUMPRODUCT((D24:D38="A36")*IF(ISNUMBER(L24:L38),L24:L38,0)) -> 0 | U39: =SUMPRODUCT((D24:D38="SN490B")*IF(ISNUMBER(L24:L38),L24:L38,0)) -> 0 | V39: =SUMPRODUCT((D24:D38="A572 Gr.50")*IF(ISNUMBER(L24:L38),L24:L38,0)) -> 0 | W39: =SUMPRODUCT((N24:N38="GR")*IF(ISNUMBER(L24:L38),L24:L38,0)) -> 0 | X39: =SUMPRODUCT((N24:N38="CP")*IF(ISNUMBER(L24:L38),L24:L38,0)) -> 0

Sheet ❹ Deck樓板
A1: Deck鋼板+底層筋+WWM+RC灌漿+粉光。防火漆可選1hr/2hr。
A2: 樓層 | B2: ▼Deck型號 | C2: 面積(m²) | D2: 總版厚T(mm) 波谷→頂面 | E2: ▼底層筋 | F2: ▼WWM規格 | G2: ▼防火漆 | H2: ▼粉光 | I2: 波高hr (mm) | J2: 浪距 (mm) | K2: Deck鋼板 重(kg) | L2: 底層筋 重(kg) | M2: WWM 重(kg) | N2: RC體積 (m³) | O2: 粉光面積 (m²) | P2: 防火漆面積 (m²)
A3: 1F | B3: 3.0W-1.2mm | C3: 500 | D3: 150 | E3: #4(D13) | F3: φ4.0@150×150 | G3: 防火漆2hr | H3: 是 | I3: =IFERROR(VLOOKUP(B3,規格資料庫!$A$2:$E$162,4,FALSE()),"") -> 76 | J3: =IFERROR(VLOOKUP(B3,規格資料庫!$A$2:$E$162,5,FALSE()),"") -> 305 | K3: =IF(B3="","",VLOOKUP(B3,規格資料庫!$A$2:$E$162,3,FALSE())*C3) -> 8800 | L3: =IF(OR(E3="",J3="",J3=0),"",VLOOKUP(E3,規格資料庫!$A$2:$E$162,3,FALSE())*(1000/J3)*C3) -> 1629.5082 | M3: =IF(F3="","",VLOOKUP(F3,規格資料庫!$A$2:$E$162,3,FALSE())*C3) -> 660 | N3: =IF(OR(B3="",D3=""),"",C3*(D3-I3/2)/1000) -> 56 | O3: =IF(OR(B3="",H3="否",H3=""),"",C3) -> 500 | P3: =IF(OR(B3="",G3="無",G3=""),"",C3) -> 500
A4: 2F | B4: 3.0W-1.2mm | C4: 500 | D4: 150 | E4: #4(D13) | F4: φ4.0@150×150 | G4: 防火漆2hr | H4: 是 | I4: =IFERROR(VLOOKUP(B4,規格資料庫!$A$2:$E$162,4,FALSE()),"") -> 76 | J4: =IFERROR(VLOOKUP(B4,規格資料庫!$A$2:$E$162,5,FALSE()),"") -> 305 | K4: =IF(B4="","",VLOOKUP(B4,規格資料庫!$A$2:$E$162,3,FALSE())*C4) -> 8800 | L4: =IF(OR(E4="",J4="",J4=0),"",VLOOKUP(E4,規格資料庫!$A$2:$E$162,3,FALSE())*(1000/J4)*C4) -> 1629.5082 | M4: =IF(F4="","",VLOOKUP(F4,規格資料庫!$A$2:$E$162,3,FALSE())*C4) -> 660 | N4: =IF(OR(B4="",D4=""),"",C4*(D4-I4/2)/1000) -> 56 | O4: =IF(OR(B4="",H4="否",H4=""),"",C4) -> 500 | P4: =IF(OR(B4="",G4="無",G4=""),"",C4) -> 500
A5: 3F | B5: 3.0W-1.2mm | C5: 500 | D5: 120 | E5: #3(D10) | F5: φ4.0@150×150 | G5: 防火漆1hr | H5: 是 | I5: =IFERROR(VLOOKUP(B5,規格資料庫!$A$2:$E$162,4,FALSE()),"") -> 76 | J5: =IFERROR(VLOOKUP(B5,規格資料庫!$A$2:$E$162,5,FALSE()),"") -> 305 | K5: =IF(B5="","",VLOOKUP(B5,規格資料庫!$A$2:$E$162,3,FALSE())*C5) -> 8800 | L5: =IF(OR(E5="",J5="",J5=0),"",VLOOKUP(E5,規格資料庫!$A$2:$E$162,3,FALSE())*(1000/J5)*C5) -> 918.03279 | M5: =IF(F5="","",VLOOKUP(F5,規格資料庫!$A$2:$E$162,3,FALSE())*C5) -> 660 | N5: =IF(OR(B5="",D5=""),"",C5*(D5-I5/2)/1000) -> 41 | O5: =IF(OR(B5="",H5="否",H5=""),"",C5) -> 500 | P5: =IF(OR(B5="",G5="無",G5=""),"",C5) -> 500
A6: RF | B6: 3.0W-1.2mm | C6: 300 | D6: 100 | E6: #3(D10) | F6: φ3.2@150×150 | G6: 無 | H6: 否 | I6: =IFERROR(VLOOKUP(B6,規格資料庫!$A$2:$E$162,4,FALSE()),"") -> 76 | J6: =IFERROR(VLOOKUP(B6,規格資料庫!$A$2:$E$162,5,FALSE()),"") -> 305 | K6: =IF(B6="","",VLOOKUP(B6,規格資料庫!$A$2:$E$162,3,FALSE())*C6) -> 5280 | L6: =IF(OR(E6="",J6="",J6=0),"",VLOOKUP(E6,規格資料庫!$A$2:$E$162,3,FALSE())*(1000/J6)*C6) -> 550.81967 | M6: =IF(F6="","",VLOOKUP(F6,規格資料庫!$A$2:$E$162,3,FALSE())*C6) -> 252 | N6: =IF(OR(B6="",D6=""),"",C6*(D6-I6/2)/1000) -> 18.6 | O6: =IF(OR(B6="",H6="否",H6=""),"",C6) | P6: =IF(OR(B6="",G6="無",G6=""),"",C6)
I7: =IFERROR(VLOOKUP(B7,規格資料庫!$A$2:$E$162,4,FALSE()),"") | J7: =IFERROR(VLOOKUP(B7,規格資料庫!$A$2:$E$162,5,FALSE()),"") | K7: =IF(B7="","",VLOOKUP(B7,規格資料庫!$A$2:$E$162,3,FALSE())*C7) | L7: =IF(OR(E7="",J7="",J7=0),"",VLOOKUP(E7,規格資料庫!$A$2:$E$162,3,FALSE())*(1000/J7)*C7) | M7: =IF(F7="","",VLOOKUP(F7,規格資料庫!$A$2:$E$162,3,FALSE())*C7) | N7: =IF(OR(B7="",D7=""),"",C7*(D7-I7/2)/1000) | O7: =IF(OR(B7="",H7="否",H7=""),"",C7) | P7: =IF(OR(B7="",G7="無",G7=""),"",C7)
I8: =IFERROR(VLOOKUP(B8,規格資料庫!$A$2:$E$162,4,FALSE()),"") | J8: =IFERROR(VLOOKUP(B8,規格資料庫!$A$2:$E$162,5,FALSE()),"") | K8: =IF(B8="","",VLOOKUP(B8,規格資料庫!$A$2:$E$162,3,FALSE())*C8) | L8: =IF(OR(E8="",J8="",J8=0),"",VLOOKUP(E8,規格資料庫!$A$2:$E$162,3,FALSE())*(1000/J8)*C8) | M8: =IF(F8="","",VLOOKUP(F8,規格資料庫!$A$2:$E$162,3,FALSE())*C8) | N8: =IF(OR(B8="",D8=""),"",C8*(D8-I8/2)/1000) | O8: =IF(OR(B8="",H8="否",H8=""),"",C8) | P8: =IF(OR(B8="",G8="無",G8=""),"",C8)
I9: =IFERROR(VLOOKUP(B9,規格資料庫!$A$2:$E$162,4,FALSE()),"") | J9: =IFERROR(VLOOKUP(B9,規格資料庫!$A$2:$E$162,5,FALSE()),"") | K9: =IF(B9="","",VLOOKUP(B9,規格資料庫!$A$2:$E$162,3,FALSE())*C9) | L9: =IF(OR(E9="",J9="",J9=0),"",VLOOKUP(E9,規格資料庫!$A$2:$E$162,3,FALSE())*(1000/J9)*C9) | M9: =IF(F9="","",VLOOKUP(F9,規格資料庫!$A$2:$E$162,3,FALSE())*C9) | N9: =IF(OR(B9="",D9=""),"",C9*(D9-I9/2)/1000) | O9: =IF(OR(B9="",H9="否",H9=""),"",C9) | P9: =IF(OR(B9="",G9="無",G9=""),"",C9)
I10: =IFERROR(VLOOKUP(B10,規格資料庫!$A$2:$E$162,4,FALSE()),"") | J10: =IFERROR(VLOOKUP(B10,規格資料庫!$A$2:$E$162,5,FALSE()),"") | K10: =IF(B10="","",VLOOKUP(B10,規格資料庫!$A$2:$E$162,3,FALSE())*C10) | L10: =IF(OR(E10="",J10="",J10=0),"",VLOOKUP(E10,規格資料庫!$A$2:$E$162,3,FALSE())*(1000/J10)*C10) | M10: =IF(F10="","",VLOOKUP(F10,規格資料庫!$A$2:$E$162,3,FALSE())*C10) | N10: =IF(OR(B10="",D10=""),"",C10*(D10-I10/2)/1000) | O10: =IF(OR(B10="",H10="否",H10=""),"",C10) | P10: =IF(OR(B10="",G10="無",G10=""),"",C10)
I11: =IFERROR(VLOOKUP(B11,規格資料庫!$A$2:$E$162,4,FALSE()),"") | J11: =IFERROR(VLOOKUP(B11,規格資料庫!$A$2:$E$162,5,FALSE()),"") | K11: =IF(B11="","",VLOOKUP(B11,規格資料庫!$A$2:$E$162,3,FALSE())*C11) | L11: =IF(OR(E11="",J11="",J11=0),"",VLOOKUP(E11,規格資料庫!$A$2:$E$162,3,FALSE())*(1000/J11)*C11) | M11: =IF(F11="","",VLOOKUP(F11,規格資料庫!$A$2:$E$162,3,FALSE())*C11) | N11: =IF(OR(B11="",D11=""),"",C11*(D11-I11/2)/1000) | O11: =IF(OR(B11="",H11="否",H11=""),"",C11) | P11: =IF(OR(B11="",G11="無",G11=""),"",C11)
I12: =IFERROR(VLOOKUP(B12,規格資料庫!$A$2:$E$162,4,FALSE()),"") | J12: =IFERROR(VLOOKUP(B12,規格資料庫!$A$2:$E$162,5,FALSE()),"") | K12: =IF(B12="","",VLOOKUP(B12,規格資料庫!$A$2:$E$162,3,FALSE())*C12) | L12: =IF(OR(E12="",J12="",J12=0),"",VLOOKUP(E12,規格資料庫!$A$2:$E$162,3,FALSE())*(1000/J12)*C12) | M12: =IF(F12="","",VLOOKUP(F12,規格資料庫!$A$2:$E$162,3,FALSE())*C12) | N12: =IF(OR(B12="",D12=""),"",C12*(D12-I12/2)/1000) | O12: =IF(OR(B12="",H12="否",H12=""),"",C12) | P12: =IF(OR(B12="",G12="無",G12=""),"",C12)
I13: =IFERROR(VLOOKUP(B13,規格資料庫!$A$2:$E$162,4,FALSE()),"") | J13: =IFERROR(VLOOKUP(B13,規格資料庫!$A$2:$E$162,5,FALSE()),"") | K13: =IF(B13="","",VLOOKUP(B13,規格資料庫!$A$2:$E$162,3,FALSE())*C13) | L13: =IF(OR(E13="",J13="",J13=0),"",VLOOKUP(E13,規格資料庫!$A$2:$E$162,3,FALSE())*(1000/J13)*C13) | M13: =IF(F13="","",VLOOKUP(F13,規格資料庫!$A$2:$E$162,3,FALSE())*C13) | N13: =IF(OR(B13="",D13=""),"",C13*(D13-I13/2)/1000) | O13: =IF(OR(B13="",H13="否",H13=""),"",C13) | P13: =IF(OR(B13="",G13="無",G13=""),"",C13)
I14: =IFERROR(VLOOKUP(B14,規格資料庫!$A$2:$E$162,4,FALSE()),"") | J14: =IFERROR(VLOOKUP(B14,規格資料庫!$A$2:$E$162,5,FALSE()),"") | K14: =IF(B14="","",VLOOKUP(B14,規格資料庫!$A$2:$E$162,3,FALSE())*C14) | L14: =IF(OR(E14="",J14="",J14=0),"",VLOOKUP(E14,規格資料庫!$A$2:$E$162,3,FALSE())*(1000/J14)*C14) | M14: =IF(F14="","",VLOOKUP(F14,規格資料庫!$A$2:$E$162,3,FALSE())*C14) | N14: =IF(OR(B14="",D14=""),"",C14*(D14-I14/2)/1000) | O14: =IF(OR(B14="",H14="否",H14=""),"",C14) | P14: =IF(OR(B14="",G14="無",G14=""),"",C14)
A15: Deck合計 | K15: =SUM(K3:K14) -> 31680 | L15: =SUM(L3:L14) -> 4727.8689 | M15: =SUM(M3:M14) -> 2232 | N15: =SUM(N3:N14) -> 171.6 | O15: =SUM(O3:O14) -> 1500 | P15: =SUM(P3:P14) -> 1500 | Q15: =SUMIF(G3:G14,"防火漆1hr",P3:P14) -> 500 | R15: =SUMIF(G3:G14,"防火漆2hr",P3:P14) -> 1000

Sheet ❺ 鋼樓梯
A1: 線性件填長度(寬度留空)→kg/m。面積件填長度+寬度→kg/m²。塗裝長度留空=全塗。
A2: 樓梯編號 | B2: 構件名稱 | C2: ▼快速篩選 | D2: ▼規格 | E2: ▼材質 | F2: 長度(mm) | G2: 寬度(mm) 面積件填 | H2: 數量 | I2: ▼塗裝類型 | J2: 塗裝長度 (mm)空白=全塗 | K2: 單位重 | L2: 重量(kg) | M2: 塗裝面積 (m²)
