Workbook

Sheet 使用說明
B1: 鋼構荷重計算表 — 新手操作指南
B3: 顏色對照表 — 看顏色就知道哪裡該動
B4: 藍色字 + 淺藍底 | C4: ← 你要填的（用下拉選單選 或 直接打數字）
B5: 灰色底 | C5: ← 電腦自動算的（千萬不要改！改了會壞掉）
B6: 粉紅底 | C6: ← 判定結果：OK = 安全 ✅；NG = 不安全 ❌
B7: 綠色底 | C7: ← 控制模式：告訴你「哪個先壞」
B8: 橘色底 | C8: ← 白話翻譯：用日常語言告訴你結果的意思
B10: 這張表在做什麼？
B11: 這張表幫你回答三個問題：
B12: ❶ 這根鋼梁（柱、格柵、樓板）最多能承受多重？
B13: ❷ 放了你的荷重後，安不安全？（看 OK 或 NG）
B14: ❸ 如果不安全，是「彎斷」「剪斷」還是「彎太多」先壞？
B16: 你不需要懂工程公式，只要：
B17: ✅ 用下拉選單選好鋼材種類和尺寸
B18: ✅ 填上長度（mm）和重量（kg）
B19: ✅ 看最下面的「白話翻譯」欄位
B22: 各頁面怎麼用？
B23: 📐 鋼梁（鋼梁_天車計算） — 架在兩根柱子間的橫梁
B24: → 選鋼材形狀和尺寸（下拉選單）
... B54: 📖 計算公式速查（進階參考）
B55: 容許彎曲應力 | C55: Fb = 0.66 × Fy
B56: 容許剪應力 | C56: Fv = 0.40 × Fy
B57: 容許彎矩 | C57: M_allow = Fb × Sx
B58: 容許剪力 | C58: V_allow = Fv × Aw
B59: 簡支梁 集中荷重 | C59: M=PL/4, V=P/2, Δ=PL³/48EI
B60: 簡支梁 均佈荷重 | C60: M=wL²/8, V=wL/2, Δ=5wL⁴/384EI
B61: 懸臂梁 集中荷重 | C61: M=PL, V=P, Δ=PL³/3EI
B62: 懸臂梁 均佈荷重 | C62: M=wL²/2, V=wL, Δ=wL⁴/8EI
B63: 柱容許壓應力 | C63: KL/r≤Cc → AISC主公式；KL/r>Cc → Euler
B64: 梁柱組合 | C64: fa/Fa + fbx/Fbx + fby/Fby ≤ 1.0
B65: Deck正彎矩 | C65: φMn = φ × As × fy × (d - a/2)
B66: Deck剪力 | C66: φVc = φ × 0.17√f'c × b × d
B67: 容許撓度 | C67: Δa = L/n（有絕對上限取較小值）

Sheet 鋼梁_天車計算
A1: 鋼梁 / 天車梁 容許荷重與撓度檢核表
K2: =IFERROR(INDEX(DB_Settings!$K$2:$K$7,MATCH($B$7,DB_Settings!$J$2:$J$7,0)),"") -> Shape_H
A3: 輸入條件 | D3: 斷面性質 | G3: 容許撓度基準
A4: 梁別 | B4: 一般鋼梁 | C4: 選鋼梁用途：一般鋼梁 = 普通的梁，天車梁 = 吊車軌道梁 | D4: 鋼構形式 | E4: =IF($B$8="","",VLOOKUP($B$8,DB_Sections!$A$2:$N$500,2,0)) -> H形鋼 | G4: 梁類別 | H4: =IF($B$16="","",VLOOKUP($B$16,DB_Deflection!$A$2:$G$100,2,0)) -> 一般鋼梁
A5: 支承條件 | B5: 簡支梁 | C5: 兩端搭在柱子上 → 簡支梁；一端固定一端懸空 → 懸臂梁 | D5: H / d (mm) | E5: =IF($B$8="","",VLOOKUP($B$8,DB_Sections!$A$2:$N$500,3,0)) -> 100 | G5: L/n | H5: =IF($B$16="","",VLOOKUP($B$16,DB_Deflection!$A$2:$G$100,3,0)) -> 240
A6: 荷重型式 | B6: 集中荷重 | C6: 一個點的重量 → 集中荷重；整根梁平均受力 → 均佈荷重 | D6: B / bf (mm) | E6: =IF($B$8="","",VLOOKUP($B$8,DB_Sections!$A$2:$N$500,4,0)) -> 50 | G6: 絕對上限 (mm) | H6: =IF($B$16="","",VLOOKUP($B$16,DB_Deflection!$A$2:$G$100,4,0)) -> 0
A7: 鋼構形式 | B7: H形鋼 | C7: 天車梁通常用 I型梁。選天車梁時建議手動選 I型梁 | D7: tw (mm) | E7: =IF($B$8="","",VLOOKUP($B$8,DB_Sections!$A$2:$N$500,5,0)) -> 5 | G7: 撓度檢核項目 | H7: =IF($B$16="","",VLOOKUP($B$16,DB_Deflection!$A$2:$G$100,5,0)) -> 總載重撓度
A8: 斷面規格 | B8: H-100x50x5x7 | C8: 鋼材尺寸。數字越大 = 越粗越重 = 能撐越多 | D8: tf / t (mm) | E8: =IF($B$8="","",VLOOKUP($B$8,DB_Sections!$A$2:$N$500,6,0)) -> 7 | G8: 容許撓度 Δa (mm) | H8: =IF(AND(OR(H5="",H5<=0),OR(H6="",H6<=0)),"",IF(OR(H5="",H5<=0),H6,IF(OR(H6="",H6<=0),$B$10/H5,MIN($B$10/H5,H6)))) -> 25
A9: 鋼材類別 | B9: CNS SN400B / SM400 (t≤40) | C9: 鋼材材質等級。不確定就選預設的 CNS SN400B | D9: 附加尺寸 (mm) | E9: =IF($B$8="","",VLOOKUP($B$8,DB_Sections!$A$2:$N$500,7,0)) -> 0 | G9: 說明 | H9: =IF($B$16="","",VLOOKUP($B$16,DB_Deflection!$A$2:$G$100,6,0)) -> 容許撓度 Δa = L/240
A10: 跨距 L (mm) | B10: 6000 | C10: 兩個支撐點之間的距離（mm），1公尺 = 1000mm | D10: A (mm²) | E10: =IF($B$8="","",VLOOKUP($B$8,DB_Sections!$A$2:$N$500,8,0)) -> 1130
A11: 是否納入自重 | B11: 是 | C11: 把鋼梁自身重量也算進去？通常選「是」 | D11: 單位重 (kg/m) | E11: =IF($B$8="","",VLOOKUP($B$8,DB_Sections!$A$2:$N$500,9,0)) -> 8.8705 | G11: 設計邊界
A12: 附加靜載重 wD,add (kg/m) | B12: 0 | C12: 固定在梁上的額外東西重量（如管線），沒有就填 0 | D12: Ix (mm⁴) | E12: =IF($B$8="","",VLOOKUP($B$8,DB_Sections!$A$2:$N$500,10,0)) -> 1781456.7 | G12: 1. 本表以單跨梁之強軸彎曲初估為主。
A13: 集中荷重 P (kg) | B13: 10 | C13: 放在梁上的單點重量（kg），例如一台設備 500kg | D13: Sx (mm³) | E13: =IF($B$8="","",VLOOKUP($B$8,DB_Sections!$A$2:$N$500,11,0)) -> 35629.133 | G13: 2. 容許應力法採 Fb = 0.66Fy、Fv = 0.40Fy。
A14: 均佈活載重 wL (kg/m) | B14: 1.5 | C14: 平均分佈在整根梁上的重量（kg/m） | D14: Aw (mm²) | E14: =IF($B$8="","",VLOOKUP($B$8,DB_Sections!$A$2:$N$500,12,0)) -> 430 | G14: 3. 未另檢核側向扭轉挫屈、局部挫屈、疲勞與接頭。
A15: 載重倍率 | B15: 1.25 | C15: 安全係數。天車梁用 1.25，一般梁用 1.0 | D15: 降伏強度 Fy (MPa) | E15: =IF($B$9="","",VLOOKUP($B$9,DB_Settings!$A$2:$C$6,2,0)) -> 235.36 | G15: 4. 天車梁(Monorail) 建議以集中荷重模式輸入，倍率可採 1.25。
A16: 容許撓度基準 | B16: 一般鋼梁｜總載重撓度 L/240 | C16: 允許的最大變形標準。不確定就選預設值 | D16: 彈性模數 E (MPa) | E16: =IF($B$9="","",VLOOKUP($B$9,DB_Settings!$A$2:$C$6,3,0)) -> 200000 | G16: 5. P 型鋼與 L 型鋼之斷面性質為初估近似值。
D17: 容許應力 | E17: =IF(E15="","","Fb="&ROUND(E15*DB_Settings!$G$3,1)&" MPa；Fv="&ROUND(E15*DB_Settings!$G$4,1)&" MPa") -> Fb=155.3 MPa；Fv=94.1 MPa
A19: 容許值計算 | D19: 實際荷重檢核 | I19: 白話翻譯（看這欄就好！）
A20: 容許彎矩 M_allow (kg·m) | B20: =IF(E13="","",E15*DB_Settings!$G$3*E13/(DB_Settings!$G$2*1000)) -> 564.36643 | D20: 服務集中荷重 Ps,act (kg) | E20: =IF($B$6="集中荷重",$B$13*$B$15,0) -> 12.5 | I20: =IF(B20="","","🔧 這根梁最多能承受 "&ROUND(B20,0)&" kg·m 的彎曲力") -> 🔧 這根梁最多能承受 564 kg·m 的彎曲力
A21: 容許剪力 V_allow (kg) | B21: =IF(E14="","",E15*DB_Settings!$G$4*E14/DB_Settings!$G$2) -> 4128.007 | D21: 服務均佈活載 qs,act (kg/m) | E21: =IF($B$6="均佈荷重",$B$14*$B$15,0) -> 0 | I21: =IF(B21="","","🔧 這根梁最多能承受 "&ROUND(B21,0)&" kg 的剪切力") -> 🔧 這根梁最多能承受 4128 kg 的剪切力
A22: 固定靜載重 wD (kg/m) | B22: =IF($B$11="是",E11,0)+$B$12 -> 8.8705 | D22: 實際彎矩 M_act (kg·m) | E22: =IF($B$5="簡支梁",E20*($B$10/1000)/4 + (B22+E21)*($B$10/1000)^2/8, E20*($B$10/1000) + (B22+E21)*($B$10/1000)^2/2) -> 58.66725 | I22: =IF(B22="","","📌 固定重量（自重+附加）= "&ROUND(B22,2)&" kg/m") -> 📌 固定重量（自重+附加）= 8.87 kg/m
A23: 固定靜載彎矩 MD (kg·m) | B23: =IF($B$5="簡支梁",B22*($B$10/1000)^2/8,B22*($B$10/1000)^2/2) -> 39.91725 | D23: 實際剪力 V_act (kg) | E23: =IF($B$5="簡支梁",E20/2 + (B22+E21)*($B$10/1000)/2, E20 + (B22+E21)*($B$10/1000)) -> 32.8615
A24: 固定靜載剪力 VD (kg) | B24: =IF($B$5="簡支梁",B22*($B$10/1000)/2,B22*($B$10/1000)) -> 26.6115 | D24: 實際撓度 Δ_act (mm) | E24: =IF($B$5="簡支梁",E20*DB_Settings!$G$2*$B$10^3/(48*E16*E12)+5*(B22+E21)*DB_Settings!$G$2*$B$10^4/(384*E16*E12*1000), E20*DB_Settings!$G$2*$B$10^3/(3*E16*E12)+(B22+E21)*DB_Settings!$G$2*$B$10^4/(8*E16*E12*1000)) -> 5.6683344
A25: 固定靜載撓度 ΔD (mm) | B25: =IF($B$5="簡支梁",5*B22*DB_Settings!$G$2*$B$10^4/(384*E16*E12*1000),B22*DB_Settings!$G$2*$B$10^4/(8*E16*E12*1000)) -> 4.1200957 | D25: 彎矩利用率 | E25: =IF(OR(B20="",B20<=0,E22=""),"",E22/B20) -> 0.10395241 | I25: =IF(E25="","","📊 彎矩用了 "&ROUND(E25*100,1)&"% → "&IF(E25<=1,"還有餘裕","已超標！")) -> 📊 彎矩用了 10.4% → 還有餘裕
A26: 剩餘容許彎矩 (kg·m) | B26: =MAX(0,B20-B23) -> 524.44918 | D26: 剪力利用率 | E26: =IF(OR(B21="",B21<=0,E23=""),"",E23/B21) -> 0.0079606212 | I26: =IF(E26="","","📊 剪力用了 "&ROUND(E26*100,1)&"% → "&IF(E26<=1,"還有餘裕","已超標！")) -> 📊 剪力用了 0.8% → 還有餘裕
A27: 剩餘容許剪力 (kg) | B27: =MAX(0,B21-B24) -> 4101.3955 | D27: 撓度利用率 | E27: =IF(E24="","",IF(OR(H8="",H8<=0),IF(E24>0,999,0),E24/H8)) -> 0.22673338 | I27: =IF(E27="","","📊 撓度用了 "&ROUND(E27*100,1)&"% → "&IF(E27<=1,"還有餘裕","已超標！")) -> 📊 撓度用了 22.7% → 還有餘裕
A28: 剩餘容許撓度 (mm) | B28: =MAX(0,H8-IF(OR(H7="總載重撓度",H7="服務性撓度"),B25,0)) -> 20.879904 | D28: 彎曲判定 | E28: =IF(E25="","",IF(E25<=1,"OK","NG")) -> OK | I28: =IF(E28="","",IF(E28="OK","✅ 不會被彎斷","❌ 有彎斷風險！")) -> ✅ 不會被彎斷
D29: 剪力判定 | E29: =IF(E26="","",IF(E26<=1,"OK","NG")) -> OK | I29: =IF(E29="","",IF(E29="OK","✅ 不會被剪斷","❌ 有剪斷風險！")) -> ✅ 不會被剪斷
A30: 集中荷重容許｜彎矩控制 Ps,M (kg) | B30: =IF($B$5="簡支梁",4*B26/($B$10/1000),B26/($B$10/1000)) -> 349.63279 | D30: 撓度判定 | E30: =IF(E27="","",IF(E27<=1,"OK","NG")) -> OK | I30: =IF(E30="","",IF(E30="OK","✅ 變形在容許範圍","❌ 會彎太多！")) -> ✅ 變形在容許範圍
A31: 集中荷重容許｜剪力控制 Ps,V (kg) | B31: =IF($B$5="簡支梁",2*B27,B27) -> 8202.791 | D31: 超標項目 | E31: =IF(COUNTA(E28:E30)=0,"",IF(AND(E28<>"NG",E29<>"NG",E30<>"NG"),"無",IF(AND(E28="NG",E29<>"NG",E30<>"NG"),"彎曲超標",IF(AND(E28<>"NG",E29="NG",E30<>"NG"),"剪力超標",IF(AND(E28<>"NG",E29<>"NG",E30="NG"),"撓度超標",IF(AND(E28="NG",E29="NG",E30<>"NG"),"彎曲、剪力超標",IF(AND(E28="NG",E29<>"NG",E30="NG"),"彎曲、撓度超標",IF(AND(E28<>"NG",E29="NG",E30="NG"),"剪力、撓度超標","彎曲、剪力、撓度超標")))))))) -> 無 | I31: =IF(E31="","",IF(E31="無","✅ 全部通過","⚠ "&E31&" — 請換大一號斷面")) -> ✅ 全部通過
A32: 集中荷重容許｜撓度控制 Ps,Δ (kg) | B32: =IF($B$5="簡支梁",48*E16*E12*B28/(DB_Settings!$G$2*$B$10^3),3*E16*E12*B28/(DB_Settings!$G$2*$B$10^3)) -> 168.57787 | D32: 控制準則 | E32: =IF(COUNTA(E25:E27)=0,"",IF(E27>=MAX(E25:E27),"撓度",IF(E25>=MAX(E25:E27),"彎曲","剪力"))) -> 撓度 | I32: =IF(E32="","","💡 「"&E32&"」決定上限 → "&IF(E32="撓度","梁會彎太多",IF(E32="彎曲","梁會被彎斷","梁會被剪斷"))) -> 💡 「撓度」決定上限 → 梁會彎太多
A33: 集中荷重容許｜服務值 Ps (kg) | B33: =MIN(B30,B31,B32) -> 168.57787 | D33: 總判定 | E33: =IF(COUNTA(E28:E30)=0,"",IF(OR(E28="NG",E29="NG",E30="NG"),"NG","OK")) -> OK | I33: =IF(E33="","",IF(E33="OK","🟢 安全！可以使用","🔴 不安全！你填的荷重 "&B13&" kg 超過額定值 "&ROUND(B34,0)&" kg，請減少荷重或換大斷面")) -> 🟢 安全！可以使用
A34: 集中荷重容許｜額定值 Pr (kg) | B34: =IF($B$15>0,B33/$B$15,0) -> 134.8623 | I34: =IF(B34="","",IF(B15>1,"🏋 你填的集中荷重（B13）不要超過 "&ROUND(B34,0)&" kg（已扣除 "&B15&" 倍安全係數）","🏋 集中荷重不要超過 "&ROUND(B33,0)&" kg")) -> 🏋 你填的集中荷重（B13）不要超過 135 kg（已扣除 1.25 倍安全係數）
A36: 均佈活載容許｜彎矩控制 qs,M (kg/m) | B36: =IF($B$5="簡支梁",8*B26/($B$10/1000)^2,2*B26/($B$10/1000)^2) -> 116.54426
A37: 均佈活載容許｜剪力控制 qs,V (kg/m) | B37: =IF($B$5="簡支梁",2*B27/($B$10/1000),B27/($B$10/1000)) -> 1367.1318
A38: 均佈活載容許｜撓度控制 qs,Δ (kg/m) | B38: =IF($B$5="簡支梁",384*E16*E12*B28*1000/(5*DB_Settings!$G$2*$B$10^4),8*E16*E12*B28*1000/(DB_Settings!$G$2*$B$10^4)) -> 44.9541
A39: 均佈活載容許｜服務值 qs (kg/m) | B39: =MIN(B36,B37,B38) -> 44.9541 | I39: =IF(B39="","",IF(B15>1,"🏋 均佈活載不要超過 "&ROUND(B39/B15,1)&" kg/m（已扣除 "&B15&" 倍安全係數）","🏋 均佈活載不要超過 "&ROUND(B39,1)&" kg/m")) -> 🏋 均佈活載不要超過 36 kg/m（已扣除 1.25 倍安全係數）
A42: 自動計算方式與公式說明
A43: 服務集中荷重 | B43: '= 集中荷重 P × 載重倍率
A44: 服務均佈活載 | B44: '= 均佈活載重 wL × 載重倍率
...

Sheet 鋼柱計算
A1: 鋼柱 容許軸力與梁柱組合檢核表
A2: 💡 藍字格子 = 你要填的 | 灰底 = 自動計算 | 粉紅底 = 判定結果 | 橘底 = 白話翻譯
A3: ▼ 輸入條件（填藍色格子） | D3: 斷面性質（自動帶入） | F3: 白話說明 | G3: Fy | H3: E(MPa)
A4: 鋼構形式 | B4: H形鋼 | D4: H / d (mm) | E4: =IF($B$6="","",VLOOKUP($B$6,DB_Settings!$A$2:$C$6,2,0)) -> 235.36 | F4: 選鋼材截面形狀，最常用 H形鋼 | G4: =IF($B$6="","",VLOOKUP($B$6,DB_Settings!$A$2:$C$6,2,0)) -> 235.36 | H4: =IF($B$6="","",VLOOKUP($B$6,DB_Settings!$A$2:$C$6,3,0)) -> 200000
A5: 斷面規格 | B5: H-200x200x8x12 | D5: B / bf (mm) | E5: =IF($B$5="","",VLOOKUP($B$5,DB_Sections!$A$2:$Q$500,4,0)) -> 200 | F5: 選柱子尺寸。數字越大越粗壯
A6: 鋼材類別 | B6: CNS SN400B / SM400 (t≤40) | D6: tw (mm) | E6: =IF($B$5="","",VLOOKUP($B$5,DB_Sections!$A$2:$Q$500,5,0)) -> 8 | F6: 材質等級，不確定就用預設
A7: 柱淨高 H (mm) | B7: 3000 | D7: tf (mm) | E7: =IF($B$5="","",VLOOKUP($B$5,DB_Sections!$A$2:$Q$500,6,0)) -> 12 | F7: 柱子高度（mm），3公尺 = 3000
A8: 有效長度係數 K | B8: 1 | D8: A (mm²) | E8: =IF($B$5="","",VLOOKUP($B$5,DB_Sections!$A$2:$Q$500,8,0)) -> 6208 | F8: 不確定就填 1.0（最安全算法）
A9: 軸力 P (kg) | B9: 5000 | C9: 從上面壓下來的重量（全部加總）。 例：樓板反力+梁反力+設備重量 不確定就先估大一點 | D9: 單位重 (kg/m) | E9: =IF($B$5="","",VLOOKUP($B$5,DB_Sections!$A$2:$Q$500,9,0)) -> 48.7328 | F9: 從上面壓下來的全部重量（公斤）
A10: 彎矩 Mx (kg·m) | B10: 200 | C10: 有「橫向推力」或「偏心」才填。 算法：力×距離。例：風力500kg在3m處→500×3=1500 沒有側向力就填 0 | D10: Ix (mm⁴) | E10: =IF($B$5="","",VLOOKUP($B$5,DB_Sections!$A$2:$Q$500,10,0)) -> 46104917 | F10: 側向推力造成的彎矩，沒有就填 0
A11: 彎矩 My (kg·m) | B11: 0 | C11: 弱方向彎矩。大部分填 0。 只有雙向受力才需要填 | D11: Sx (mm³) | E11: =IF($B$5="","",VLOOKUP($B$5,DB_Sections!$A$2:$Q$500,11,0)) -> 461049.17 | F11: 弱方向彎矩，通常填 0
A12: 是否納入自重 | B12: 是 | D12: Iy (mm⁴) | E12: =IF($B$5="","",VLOOKUP($B$5,DB_Sections!$A$2:$Q$500,15,0)) -> 16007509 | F12: 把柱子自重算進去？通常選「是」
D13: rx (mm) | E13: =IF($B$5="","",VLOOKUP($B$5,DB_Sections!$A$2:$Q$500,16,0)) -> 86.17827
D14: ry (mm) | E14: =IF($B$5="","",VLOOKUP($B$5,DB_Sections!$A$2:$Q$500,17,0)) -> 50.77922
A15: 材料常數 | B15: =IF(G4="","","Fy="&ROUND(G4,1)&" MPa, E="&ROUND(H4,0)&" MPa, Fb="&ROUND(G4*0.66,1)&" MPa") -> Fy=235.4 MPa, E=200000 MPa, Fb=155.3 MPa
A16: ▼ 計算結果 | F16: 白話翻譯（看這欄！）
A17: 自重 (kg) | B17: =IF($B$12="是",E9*$B$7/1000,0) -> 146.1984 | F17: =IF(B17="","","📌 柱子自重 = "&ROUND(B17,1)&" kg") -> 📌 柱子自重 = 146.2 kg
A18: 總壓力 (kg) | B18: =$B$9+B17 -> 5146.1984 | F18: =IF(B18="","","📌 柱子承受的總壓力 = "&ROUND(B18,0)&" kg") -> 📌 柱子承受的總壓力 = 5146 kg
A19: 有效細長比 KL/r | B19: =IF(E14="","",$B$8*$B$7/E14) -> 59.079284
A20: 容許壓應力 Fa (MPa) | B20: =IF(OR(B19="",G4="",H4=""),"",IF(B19<=SQRT(2*PI()^2*H4/G4),G4*(1-(B19^2)/(2*SQRT(2*PI()^2*H4/G4)^2))/(5/3+3*B19/(8*SQRT(2*PI()^2*H4/G4))-B19^3/(8*SQRT(2*PI()^2*H4/G4)^3)),12*PI()^2*H4/(23*B19^2))) -> 115.4919
A21: 容許軸力 Pa (kg) | B21: =IF(B20="","",B20*E8/DB_Settings!$G$2) -> 73110.971 | F21: =IF(B21="","","🔧 這根柱子最多能撐 "&ROUND(B21,0)&" kg") -> 🔧 這根柱子最多能撐 73111 kg
A22: 軸力利用率 | B22: =IF(OR(B20="",B20<=0),"",B18*DB_Settings!$G$2/E8/B20) -> 0.070388867 | F22: =IF(B22="","","📊 軸力用了 "&ROUND(B22*100,1)&"% 的容許值") -> 📊 軸力用了 7% 的容許值
A23: 組合應力比 | B23: =IF(OR(B20="",G4*DB_Settings!$G$3=0),"",B18*DB_Settings!$G$2/E8/B20+$B$10*DB_Settings!$G$2*1000/E11/G4*DB_Settings!$G$3+IF($B$11=0,0,$B$11*DB_Settings!$G$2*1000/(E12/(E5/2))/G4*DB_Settings!$G$3)) -> 0.08231816 | F23: =IF(B23="","","📊 組合應力比 = "&ROUND(B23,3)&IF(B23<=1," → 安全"," → 超標！")) -> 📊 組合應力比 = 0.082 → 安全
A25: ▼ 最終判定
A26: 軸力判定 | B26: =IF(B22="","",IF(B22<=1,"OK","NG")) -> OK | F26: =IF(B26="","",IF(B26="OK","✅ 純壓力方面安全","❌ 壓力太大，會被壓壞")) -> ✅ 純壓力方面安全
A27: 組合應力判定 | B27: =IF(B23="","",IF(B23<=1,"OK","NG")) -> OK | F27: =IF(B27="","",IF(B27="OK","✅ 壓力+彎矩綜合安全","❌ 組合應力超標")) -> ✅ 壓力+彎矩綜合安全
A28: 總判定 | B28: =IF(OR(B26="",B27=""),"",IF(OR(B26="NG",B27="NG"),"NG","OK")) -> OK | F28: =IF(B28="","",IF(B28="OK","🟢 柱子可以安全使用！","🔴 不安全，請加大斷面或減少荷重")) -> 🟢 柱子可以安全使用！
A29: 控制模式 | B29: =IF(OR(B22="",B23=""),"",IF(B22>=B23,"軸力控制","梁柱組合控制")) -> 梁柱組合控制 | F29: =IF(B29="","","💡 「"&B29&"」決定了柱子的強度上限") -> 💡 「梁柱組合控制」決定了柱子的強度上限
A30: 最大容許軸力 (kg) | B30: =B21 -> 73110.971 | F30: =IF(B30="","","🏋 最多可承受 "&ROUND(B30,0)&" kg") -> 🏋 最多可承受 73111 kg

Sheet 格柵計算
A1: 格柵 (Steel Grating) 容許荷重檢核表
A2: 💡 藍字格子 = 你要填的 | 灰底 = 自動算 | 橘底 = 白話翻譯
A3: ▼ 輸入條件 | C3: 白話說明
A4: 格柵型號 | B4: 25×3 @30 溝距200 | C4: 從下拉選單選取格柵規格（h×t @間距 溝距）
A5: 承載條高 h (mm) | B5: =IFERROR(VLOOKUP($B$4,DB_Grating!$A$2:$G$21,2,0),"") -> 25 | C5: 自動帶入（由型號決定）
A6: 承載條厚 t (mm) | B6: =IFERROR(VLOOKUP($B$4,DB_Grating!$A$2:$G$21,3,0),"") -> 3 | C6: 自動帶入（由型號決定）
A7: 承載條間距 c/c (mm) | B7: =IFERROR(VLOOKUP($B$4,DB_Grating!$A$2:$G$21,4,0),"") -> 30 | C7: 自動帶入（由型號決定）
A8: 跨距 L (mm) | B8: 1000 | C8: 格柵下方兩根支撐梁的距離（mm）
A9: 支承條件 | B9: 簡支梁 | C9: 兩端搭著 → 簡支梁
A10: 容許撓度 L/n | B10: 200 | C10: 允許彎多少。走道一般填 200
A11: 集中荷重 P (kg) | B11: 100 | C11: 一個人站上去多重（kg），一般 75-100
A12: 均佈荷重 w (kg/m²) | B12: 500 | C12: 每平方公尺放多少公斤，走道一般 300-500
A13: 集中荷重分佈寬 (mm) | B13: 225 | C13: 腳踩面積寬度，用 225mm（鞋底）
A14: 鋼材 Fy (MPa) | B14: 235.36 | C14: 材料強度，一般格柵用 235
A16: ▼ 承載條斷面（自動算）
A17: 單條慣性矩 I (mm⁴) | B17: =B6*B5^3/12 -> 3906.25
A18: 單條斷面模數 S (mm³) | B18: =B6*B5^2/6 -> 312.5
A19: 單條面積 A (mm²) | B19: =B5*B6 -> 75
A20: Fb (MPa) | B20: =B14*0.66 -> 155.3376
A21: Fv (MPa) | B21: =B14*0.4 -> 94.144
A22: 容許彎矩/條 (kg·mm) | B22: =B20*B18/DB_Settings!$G$2 -> 4950.0084
A23: 容許剪力/條 (kg) | B23: =B21*B19/DB_Settings!$G$2 -> 720.00122
A24: 容許撓度 (mm) | B24: =B8/B10 -> 5
A25: 每公尺承載條數 | B25: =1000/B7 -> 33.333333
A27: ▼ 均佈荷重檢核 | C27: 白話翻譯
A28: 彎矩利用率 | B28: =IF(B9="簡支梁",(B12/1000000*B7)*B8^2/8/B22,(B12/1000000*B7)*B8^2/2/B22) -> 0.37878724 | C28: =IF(B28="","","📊 彎矩用了 "&ROUND(B28*100,1)&"% → "&IF(B28<=1,"安全","超標！")) -> 📊 彎矩用了 37.9% → 安全
A29: 剪力利用率 | B29: =IF(B9="簡支梁",(B12/1000000*B7)*B8/2/B23,(B12/1000000*B7)*B8/B23) -> 0.010416649 | C29: =IF(B29="","","📊 剪力用了 "&ROUND(B29*100,1)&"%") -> 📊 剪力用了 1%
A30: 撓度利用率 | B30: =IF(B9="簡支梁",5*(B12/1000000*B7)*DB_Settings!$G$2*B8^4/(384*200000*B17)/B24,(B12/1000000*B7)*DB_Settings!$G$2*B8^4/(8*200000*B17)/B24) -> 0.4903325 | C30: =IF(B30="","","📊 撓度用了 "&ROUND(B30*100,1)&"%") -> 📊 撓度用了 49%
A32: ▼ 集中荷重檢核
A33: 受力條數 | B33: =MIN(FLOOR(B13/B7,1)+1,B25) -> 8 | C33: 腳踩範圍內有幾根承載條
A34: 單條分擔力 (kg) | B34: =B11/B33 -> 12.5
A35: 彎矩利用率 | B35: =IF(B9="簡支梁",B34*B8/4/B22,B34*B8/B22) -> 0.63131206 | C35: =IF(B35="","","📊 彎矩用了 "&ROUND(B35*100,1)&"%") -> 📊 彎矩用了 63.1%
A36: 剪力利用率 | B36: =IF(B9="簡支梁",B34/2/B23,B34/B23) -> 0.0086805408
A37: 撓度利用率 | B37: =IF(B9="簡支梁",B34*DB_Settings!$G$2*B8^3/(48*200000*B17)/B24,B34*DB_Settings!$G$2*B8^3/(3*200000*B17)/B24) -> 0.65377667 | C37: =IF(B37="","","📊 撓度用了 "&ROUND(B37*100,1)&"%") -> 📊 撓度用了 65.4%
A39: ▼ 最終判定 | C39: 白話翻譯
A40: 均佈荷重判定 | B40: =IF(MAX(B28,B29,B30)<=1,"OK","NG") -> OK | C40: =IF(B40="OK","✅ 地板可以安全承載 "&B12&" kg/m²","❌ 超載了！需減少荷重或換更密的格柵") -> ✅ 地板可以安全承載 500 kg/m²
A41: 集中荷重判定 | B41: =IF(MAX(B35,B36,B37)<=1,"OK","NG") -> OK | C41: =IF(B41="OK","✅ 站 "&B11&" kg 的人上去安全","❌ 踩上去會壞！需加強") -> ✅ 站 100 kg 的人上去安全
A42: 均佈控制模式 | B42: =IF(B30>=MAX(B28,B29,B30),"撓度",IF(B28>=MAX(B28,B29,B30),"彎矩","剪力")) -> 撓度 | C42: =IF(B42="","","💡 均佈荷重下「"&B42&"」最嚴格") -> 💡 均佈荷重下「撓度」最嚴格
A43: 集中控制模式 | B43: =IF(B37>=MAX(B35,B36,B37),"撓度",IF(B35>=MAX(B35,B36,B37),"彎矩","剪力")) -> 撓度
A44: 最大均佈容許 (kg/m²) | B44: =ROUND(B12/MAX(B28,B29,B30),0) -> 1020 | C44: =IF(B44="","","🏋 均佈荷重最多可放 "&B44&" kg/m²") -> 🏋 均佈荷重最多可放 1020 kg/m²
...

Sheet Deck樓板
A1: Composite Deck 樓板 — 使用階段荷重檢核表
A2: 💡 藍字 = 你要填 | 灰底 = 自動算 | 橘底 = 白話翻譯
A3: ▼ 鋼浪板 Deck
A4: Deck 型號 | B4: 3.0W-1.2mm | C4: 鋼浪板型號。波越高越大號 = 越強
A5: 波高 hr (mm) | B5: =IFERROR(VLOOKUP($B$4,DB_Deck!$A$2:$H$20,2,0),"") -> 100
A6: Deck As (mm²/m) | B6: =IFERROR(VLOOKUP($B$4,DB_Deck!$A$2:$H$20,5,0),"") -> 1525
A7: Deck 自重 (kg/m²) | B7: =IFERROR(VLOOKUP($B$4,DB_Deck!$A$2:$H$20,7,0),"") -> 17.6
A8: Deck fy (MPa) | B8: 250 | C8: Deck 鋼板的強度，一般用 250
A9: 底層鋼筋 As (mm²/m) | B9: 0 | C9: 額外底筋面積。沒有填 0。 #3@200≈355, #4@200≈633, #4@150≈845, #5@200≈990
A10: ▼ 混凝土
A11: 混凝土 f'c (psi) | B11: 3000 | C11: 混凝土強度（psi）。常用 3000/4000/5000 psi
A12: 波頂以上淨厚 tc (mm) | B12: 80 | C12: 浪板最高點以上灌多厚混凝土（mm）
A13: 混凝土密度 (kg/m³) | B13: 2400
A14: 總版厚 (mm) | B14: =B5+B12 -> 180
A15: 混凝土自重 (kg/m²) | B15: =ROUND(B13*(B12+B5/2)/1000,1) -> 312
A16: f'c 換算 (MPa) | B16: =B11/145.038 -> 20.684234 | C16: 1 MPa = 145.038 psi，自動換算
A17: ▼ 電焊鋼絲網 (WWM) | C17: 鋪在混凝土裡面防裂用的鋼絲網
A18: WWM 規格 | B18: φ4.0@150×150 | C18: 選鋼絲網規格。φ=鋼絲粗細，@=間距
A19: WWM As (mm²/m) | B19: =IFERROR(VLOOKUP($B$18,DB_Deck!$A$17:$G$30,5,0),"") -> 83.8
A20: WWM fy (MPa) | B20: =IFERROR(VLOOKUP($B$18,DB_Deck!$A$17:$G$30,7,0),"") -> 490
A21: WWM 保護層 (mm) | B21: 20 | C21: 鋼絲網離版頂面多深（mm）
A22: 底筋 fy (MPa) | B22: 420 | C22: 底筋鋼材強度。SD280=280, SD420=420（最常用）。 無底筋時此欄不影響計算
A23: ▼ 荷重與跨度
A24: 跨距 L (mm) | B24: 2000 | C24: 兩根支撐梁之間距離（mm）
A25: 支承條件 | B25: 單跨 | C25: 單跨 = 兩端搭著；連續 = 中間還有支撐
A26: 活載重 wL (kg/m²) | B26: 500 | C26: 樓板上面要放多重（kg/m²）。辦公 250，倉庫 500-1000
A27: 附加靜載 wD_add (kg/m²) | B27: 50 | C27: 地磚、管線等固定載重（kg/m²）
A28: 容許撓度 L/n | B28: 240
A29: 強度折減 φ | B29: 0.9
A31: ▼ 計算結果 | C31: 白話翻譯
A32: 總靜載 wD (kg/m²) | B32: =(B7+B15+B27) -> 379.6
A33: 設計載重 wu (kg/m²) | B33: =(1.2*(B7+B15+B27)+1.6*B26) -> 1255.52 | C33: 📌 1.2×靜載 + 1.6×活載 的安全組合
A34: 正彎矩強度 φMn+ (kg·m/m) | B34: =B29*(B6*B8*((B14-B5/2)-(B6*B8+B9*B22)/(0.85*B16*1000)/2)+B9*B22*((B14-25)-(B6*B8+B9*B22)/(0.85*B16*1000)/2))/(DB_Settings!$G$2*1000) -> 4169.2102 | C34: =IF(B9>0,"🔧 含底筋，正向最多撐 "&ROUND(B34,0)&" kg·m/m","🔧 純 Deck，正向最多撐 "&ROUND(B34,0)&" kg·m/m") -> 🔧 純 Deck，正向最多撐 4169 kg·m/m
A35: 負彎矩強度 φMn- (kg·m/m) | B35: =B29*B19*B20*((B14-B21)-B19*B20/(0.85*B16*1000)/2)/(DB_Settings!$G$2*1000) -> 598.55024
A36: 剪力強度 φVn (kg/m) | B36: =B29*0.17*SQRT(B16)*1000*(B14-B5/2)/DB_Settings!$G$2 -> 9224.3088
A37: 正彎矩 Mu+ (kg·m/m) | B37: =IF(B25="單跨",B33*(B24/1000)^2/8,IF(B25="雙跨連續",B33*(B24/1000)^2/8,B33*(B24/1000)^2/10)) -> 627.76
A38: 負彎矩 Mu- (kg·m/m) | B38: =IF(B25="單跨",0,IF(B25="雙跨連續",B33*(B24/1000)^2/8,B33*(B24/1000)^2/9)) -> 0
A39: 剪力 Vu (kg/m) | B39: =IF(B25="單跨",B33*(B24/1000)/2,IF(B25="雙跨連續",5*B33*(B24/1000)/8,B33*(B24/1000)/2)) -> 1255.52
A40: 撓度 Δ (mm) | B40: =IF(B25="單跨",5*((B7+B15+B27)+B26)*DB_Settings!$G$2*B24^4/(384*4700*SQRT(B16)*(1000*B12^3/12+200000/(4700*SQRT(B16))*(B6*((B14-B5/2)-(B6*B8+B9*B22)/(0.85*B16*1000)/2)^2+IF(B9>0,B9*((B14-25)-(B6*B8+B9*B22)/(0.85*B16*1000)/2)^2,0)))*1000),5*((B7+B15+B27)+B26)*DB_Settings!$G$2*B24^4/(384*4700*SQRT(B16)*(1000*B12^3/12+200000/(4700*SQRT(B16))*(B6*((B14-B5/2)-(B6*B8+B9*B22)/(0.85*B16*1000)/2)^2+IF(B9>0,B9*((B14-25)-(B6*B8+B9*B22)/(0.85*B16*1000)/2)^2,0)))*1000)*0.4) -> 0.34278299
A42: ▼ 利用率
...

Sheet Summary
A1: 構件綜合檢核總表 — 一次看完所有構件是否安全
A3: No. | B3: 構件 | C3: 斷面/型號 | D3: 彎矩 利用率 | E3: 剪力 利用率 | F3: 撓度 利用率 | G3: 最大 利用率 | H3: 判定 | I3: 控制模式 | J3: 最大容許 荷重 | K3: 白話翻譯
A4: 1 | B4: 鋼梁 | C4: =鋼梁_天車計算!B8 -> H-100x50x5x7 | D4: =鋼梁_天車計算!E25 -> 0.10395241 | E4: =鋼梁_天車計算!E26 -> 0.0079606212 | F4: =鋼梁_天車計算!E27 -> 0.22673338 | G4: =IFERROR(MAX(D4,E4,F4),"") -> 0.22673338 | H4: =鋼梁_天車計算!E33 -> OK | I4: =鋼梁_天車計算!E32 -> 撓度 | J4: =IF(鋼梁_天車計算!B6="集中荷重",ROUND(鋼梁_天車計算!B33,0)&" kg",ROUND(鋼梁_天車計算!B39,1)&" kg/m") -> 169 kg | K4: =IF(H4="OK","✅ 鋼梁安全（用了 "&ROUND(G4*100,1)&"%）","❌ 鋼梁超標！"&I4&"先壞") -> ✅ 鋼梁安全（用了 22.7%）
A5: 2 | B5: 鋼柱 | C5: =鋼柱計算!B5 -> H-200x200x8x12 | D5: =鋼柱計算!B23 -> 0.08231816 | E5: ="—" -> — | F5: ="—" -> — | G5: =IFERROR(MAX(鋼柱計算!B22,鋼柱計算!B23),"") -> 0.08231816 | H5: =鋼柱計算!B28 -> OK | I5: =鋼柱計算!B29 -> 梁柱組合控制 | J5: =ROUND(鋼柱計算!B30,0)&" kg" -> 73111 kg | K5: =IF(H5="OK","✅ 鋼柱安全（用了 "&ROUND(G5*100,1)&"%）","❌ 鋼柱超標！") -> ✅ 鋼柱安全（用了 8.2%）
A6: 3 | B6: 格柵(均佈) | C6: =格柵計算!B4 -> 25×3 @30 溝距200 | D6: =格柵計算!B28 -> 0.37878724 | E6: =格柵計算!B29 -> 0.010416649 | F6: =格柵計算!B30 -> 0.4903325 | G6: =IFERROR(MAX(D6,E6,F6),"") -> 0.4903325 | H6: =格柵計算!B40 -> OK | I6: =格柵計算!B42 -> 撓度 | J6: =格柵計算!B44&" kg/m²" -> 1020 kg/m² | K6: =IF(H6="OK","✅ 格柵均佈安全","❌ 格柵超載！") -> ✅ 格柵均佈安全
A7: 4 | B7: 格柵(集中) | C7: =格柵計算!B4 -> 25×3 @30 溝距200 | D7: =格柵計算!B35 -> 0.63131206 | E7: =格柵計算!B36 -> 0.0086805408 | F7: =格柵計算!B37 -> 0.65377667 | G7: =IFERROR(MAX(D7,E7,F7),"") -> 0.65377667 | H7: =格柵計算!B41 -> OK | I7: =格柵計算!B43 -> 撓度 | J7: =格柵計算!B45&" kg" -> 153 kg | K7: =IF(H7="OK","✅ 踩上去安全","❌ 會踩壞！") -> ✅ 踩上去安全
A8: 5 | B8: Deck樓板 | C8: =Deck樓板!B4 -> 3.0W-1.2mm | D8: =Deck樓板!B43 -> 0.15057048 | E8: =Deck樓板!B44 -> 0.13610993 | F8: =Deck樓板!B45 -> 7.1413123e-07 | G8: =IFERROR(MAX(D8,E8,F8),"") -> 0.15057048 | H8: =Deck樓板!B48 -> OK | I8: =Deck樓板!B49 -> 正彎矩 | J8: =Deck樓板!B50&" kg/m²" -> 3321 kg/m² | K8: =IF(H8="OK","✅ 樓板安全","❌ 樓板超標！") -> ✅ 樓板安全
A10: ▼ 整體評估
B11: 最危險構件 | C11: =IFERROR(INDEX(B4:B8,MATCH(MAX(G4:G8),G4:G8,0)),"") -> 格柵(集中) | K11: =IF(C11="","","⚠ 「"&C11&"」最接近極限，要優先注意！") -> ⚠ 「格柵(集中)」最接近極限，要優先注意！
B12: 最高利用率 | C12: =IFERROR(MAX(G4:G8),"") -> 0.65377667 | K12: =IF(C12="","","📊 最高 "&ROUND(C12*100,1)&"% — "&IF(C12<=0.6,"很安全",IF(C12<=0.85,"尚可，有餘裕",IF(C12<=1,"接近極限，要小心","已超標！")))) -> 📊 最高 65.4% — 尚可，有餘裕
B13: 整體判定 | C13: =IF(OR(H4="NG",H5="NG",H6="NG",H7="NG",H8="NG"),"NG","OK") -> OK | K13: =IF(C13="OK","🟢 恭喜！所有構件都安全","🔴 有構件超標，需處理！看上面哪個是 NG") -> 🟢 恭喜！所有構件都安全

Sheet DB_Settings
A1: 鋼材類別 | B1: Fy (MPa) | C1: E (MPa) | D1: Fy (kg/cm²) | F1: 常數 | G1: 值 | H1: 說明 | J1: 鋼構形式 | K1: 名稱範圍
A2: CNS SN400B / SM400 (t≤40) | B2: 235.36 | C2: 200000 | D2: 2400 | E2: 一般型鋼、鋼板 | F2: N_per_kg | G2: 9.80665 | H2: kg 近似力值換算為 N：1 kgf = 9.80665 N | J2: H形鋼 | K2: Shape_H
A3: CNS SN400B / SM400 (t>40) | B3: 215.75 | C3: 200000 | D3: 2200 | E3: 一般型鋼、鋼板 | F3: Fb係數 | G3: 0.66 | H3: 容許彎曲應力 = 0.66Fy | J3: I形梁 | K3: Shape_I
A4: CNS SN490B | B4: 323.62 | C4: 200000 | D4: 3300 | E4: BH型鋼 | F4: Fv係數 | G4: 0.4 | H4: 容許剪應力 = 0.40Fy | J4: 槽鋼 | K4: Shape_C
A5: ASTM A572 Gr.50 | B5: 338.33 | C5: 200000 | D5: 3450 | E5: BH型鋼 | F5: 密度換算(kg/m)/(mm²) | G5: 0.00785 | J5: P型鋼 | K5: Shape_P
A6: A36（C型鋼、角鋼） | B6: 235.36 | C6: 200000 | D6: 2400 | E6: C型鋼、角鋼 | F6: 說明 | G6: A(mm²)×0.00785=kg/m | J6: L型鋼 | K6: Shape_L
J7: BOX柱 | K7: Shape_BOX

Sheet DB_Sections
A1: 斷面規格 | B1: 鋼構形式 | C1: H / d (mm) | D1: B / bf (mm) | E1: tw (mm) | F1: tf / t (mm) | G1: 附加尺寸 (mm) | H1: A (mm²) | I1: 單位重 (kg/m) | J1: Ix (mm⁴) | K1: Sx (mm³) | L1: Aw (mm²) | M1: 備註 | N1: 資料來源 | O1: Iy (mm⁴) | P1: rx (mm) | Q1: ry (mm)
A2: H-100x50x5x7 | B2: H形鋼 | C2: 100 | D2: 50 | E2: 5 | F2: 7 | G2: 0 | H2: =2*D2*F2+(C2-2*F2)*E2 -> 1130 | I2: =H2*DB_Settings!$G$5 -> 8.8705 | J2: =(D2*C2^3-(D2-E2)*(C2-2*F2)^3)/12 -> 1781456.7 | K2: =J2/(C2/2) -> 35629.133 | L2: =E2*(C2-2*F2) -> 430 | M2: 以理想化 H形鋼/槽鋼 斷面矩形近似，未含圓角。 | N2: 斷面選項依使用者提供之常用鋼構截圖整理。 | O2: =(2*F2*D2^3+(C2-2*F2)*E2^3)/12 -> 146729.17 | P2: =IFERROR(SQRT(J2/H2),"") -> 39.705293 | Q2: =IFERROR(SQRT(O2/H2),"") -> 11.395123
A3: H-100x100x6x8 | B3: H形鋼 | C3: 100 | D3: 100 | E3: 6 | F3: 8 | G3: 0 | H3: =2*D3*F3+(C3-2*F3)*E3 -> 2104 | I3: =H3*DB_Settings!$G$5 -> 16.5164 | J3: =(D3*C3^3-(D3-E3)*(C3-2*F3)^3)/12 -> 3690485.3 | K3: =J3/(C3/2) -> 73809.707 | L3: =E3*(C3-2*F3) -> 504 | M3: 以理想化 H形鋼/槽鋼 斷面矩形近似，未含圓角。 | O3: =(2*F3*D3^3+(C3-2*F3)*E3^3)/12 -> 1334845.3 | P3: =IFERROR(SQRT(J3/H3),"") -> 41.881177 | Q3: =IFERROR(SQRT(O3/H3),"") -> 25.187937
A4: H-125x60x6x8 | B4: H形鋼 | C4: 125 | D4: 60 | E4: 6 | F4: 8 | G4: 0 | H4: =2*D4*F4+(C4-2*F4)*E4 -> 1614 | I4: =H4*DB_Settings!$G$5 -> 12.6699 | J4: =(D4*C4^3-(D4-E4)*(C4-2*F4)^3)/12 -> 3937994.5 | K4: =J4/(C4/2) -> 63007.912 | L4: =E4*(C4-2*F4) -> 654 | M4: 以理想化 H形鋼/槽鋼 斷面矩形近似，未含圓角。 | O4: =(2*F4*D4^3+(C4-2*F4)*E4^3)/12 -> 289962 | P4: =IFERROR(SQRT(J4/H4),"") -> 49.395318 | Q4: =IFERROR(SQRT(O4/H4),"") -> 13.403517
A5: H-125x125x6.5x9 | B5: H形鋼 | C5: 125 | D5: 125 | E5: 6.5 | F5: 9 | G5: 0 | H5: =2*D5*F5+(C5-2*F5)*E5 -> 2945.5 | I5: =H5*DB_Settings!$G$5 -> 23.122175 | J5: =(D5*C5^3-(D5-E5)*(C5-2*F5)^3)/12 -> 8247752.5 | K5: =J5/(C5/2) -> 131964.04 | L5: =E5*(C5-2*F5) -> 695.5 | M5: 以理想化 H形鋼/槽鋼 斷面矩形近似，未含圓角。 | O5: =(2*F5*D5^3+(C5-2*F5)*E5^3)/12 -> 2932136.2 | P5: =IFERROR(SQRT(J5/H5),"") -> 52.916157 | Q5: =IFERROR(SQRT(O5/H5),"") -> 31.550959
A6: H-150x75x5x7 | B6: H形鋼 | C6: 150 | D6: 75 | E6: 5 | F6: 7 | G6: 0 | H6: =2*D6*F6+(C6-2*F6)*E6 -> 1730 | I6: =H6*DB_Settings!$G$5 -> 13.5805 | J6: =(D6*C6^3-(D6-E6)*(C6-2*F6)^3)/12 -> 6420256.7 | K6: =J6/(C6/2) -> 85603.422 | L6: =E6*(C6-2*F6) -> 680 | M6: 以理想化 H形鋼/槽鋼 斷面矩形近似，未含圓角。 | O6: =(2*F6*D6^3+(C6-2*F6)*E6^3)/12 -> 493604.17 | P6: =IFERROR(SQRT(J6/H6),"") -> 60.919053 | Q6: =IFERROR(SQRT(O6/H6),"") -> 16.891428
A7: H-150x100x6x9 | B7: H形鋼 | C7: 150 | D7: 100 | E7: 6 | F7: 9 | G7: 0 | H7: =2*D7*F7+(C7-2*F7)*E7 -> 2592 | I7: =H7*DB_Settings!$G$5 -> 20.3472 | J7: =(D7*C7^3-(D7-E7)*(C7-2*F7)^3)/12 -> 10108584 | K7: =J7/(C7/2) -> 134781.12 | L7: =E7*(C7-2*F7) -> 792 | M7: 以理想化 H形鋼/槽鋼 斷面矩形近似，未含圓角。 | O7: =(2*F7*D7^3+(C7-2*F7)*E7^3)/12 -> 1502376 | P7: =IFERROR(SQRT(J7/H7),"") -> 62.449313 | Q7: =IFERROR(SQRT(O7/H7),"") -> 24.075306
A8: H-150x150x7x10 | B8: H形鋼 | C8: 150 | D8: 150 | E8: 7 | F8: 10 | G8: 0 | H8: =2*D8*F8+(C8-2*F8)*E8 -> 3910 | I8: =H8*DB_Settings!$G$5 -> 30.6935 | J8: =(D8*C8^3-(D8-E8)*(C8-2*F8)^3)/12 -> 16006583 | K8: =J8/(C8/2) -> 213421.11 | L8: =E8*(C8-2*F8) -> 910 | M8: 以理想化 H形鋼/槽鋼 斷面矩形近似，未含圓角。 | O8: =(2*F8*D8^3+(C8-2*F8)*E8^3)/12 -> 5628715.8 | P8: =IFERROR(SQRT(J8/H8),"") -> 63.982461 | Q8: =IFERROR(SQRT(O8/H8),"") -> 37.941656
A9: H-175x90x5x8 | B9: H形鋼 | C9: 175 | D9: 90 | E9: 5 | F9: 8 | G9: 0 | H9: =2*D9*F9+(C9-2*F9)*E9 -> 2235 | I9: =H9*DB_Settings!$G$5 -> 17.54475 | J9: =(D9*C9^3-(D9-E9)*(C9-2*F9)^3)/12 -> 11722586 | K9: =J9/(C9/2) -> 133972.41 | L9: =E9*(C9-2*F9) -> 795 | M9: 以理想化 H形鋼/槽鋼 斷面矩形近似，未含圓角。 | O9: =(2*F9*D9^3+(C9-2*F9)*E9^3)/12 -> 973656.25 | P9: =IFERROR(SQRT(J9/H9),"") -> 72.422407 | Q9: =IFERROR(SQRT(O9/H9),"") -> 20.872
A10: H-175x175x7.5x11 | B10: H形鋼 | C10: 175 | D10: 175 | E10: 7.5 | F10: 11 | G10: 0 | H10: =2*D10*F10+(C10-2*F10)*E10 -> 4997.5 | I10: =H10*DB_Settings!$G$5 -> 39.230375 | J10: =(D10*C10^3-(D10-E10)*(C10-2*F10)^3)/12 -> 28164706 | K10: =J10/(C10/2) -> 321882.36 | L10: =E10*(C10-2*F10) -> 1147.5 | M10: 以理想化 H形鋼/槽鋼 斷面矩形近似，未含圓角。 | O10: =(2*F10*D10^3+(C10-2*F10)*E10^3)/12 -> 9830899.7 | P10: =IFERROR(SQRT(J10/H10),"") -> 75.071694 | Q10: =IFERROR(SQRT(O10/H10),"") -> 44.352717
A11: H-200x100x4.5x7 | B11: H形鋼 | C11: 200 | D11: 100 | E11: 4.5 | F11: 7 | G11: 0 | H11: =2*D11*F11+(C11-2*F11)*E11 -> 2237 | I11: =H11*DB_Settings!$G$5 -> 17.56045 | J11: =(D11*C11^3-(D11-E11)*(C11-2*F11)^3)/12 -> 15455938 | K11: =J11/(C11/2) -> 154559.38 | L11: =E11*(C11-2*F11) -> 837 | M11: 以理想化 H形鋼/槽鋼 斷面矩形近似，未含圓角。 | O11: =(2*F11*D11^3+(C11-2*F11)*E11^3)/12 -> 1168079.1 | P11: =IFERROR(SQRT(J11/H11),"") -> 83.121752 | Q11: =IFERROR(SQRT(O11/H11),"") -> 22.850891
A12: H-200x100x5.5x8 | B12: H形鋼 | C12: 200 | D12: 100 | E12: 5.5 | F12: 8 | G12: 0 | H12: =2*D12*F12+(C12-2*F12)*E12 -> 2612 | I12: =H12*DB_Settings!$G$5 -> 20.5042 | J12: =(D12*C12^3-(D12-E12)*(C12-2*F12)^3)/12 -> 17609323 | K12: =J12/(C12/2) -> 176093.23 | L12: =E12*(C12-2*F12) -> 1012 | M12: 以理想化 H形鋼/槽鋼 斷面矩形近似，未含圓角。 | O12: =(2*F12*D12^3+(C12-2*F12)*E12^3)/12 -> 1335884.4 | P12: =IFERROR(SQRT(J12/H12),"") -> 82.107861 | Q12: =IFERROR(SQRT(O12/H12),"") -> 22.615066
A13: H-200x150x6x9 | B13: H形鋼 | C13: 200 | D13: 150 | E13: 6 | F13: 9 | G13: 0 | H13: =2*D13*F13+(C13-2*F13)*E13 -> 3792 | I13: =H13*DB_Settings!$G$5 -> 29.7672 | J13: =(D13*C13^3-(D13-E13)*(C13-2*F13)^3)/12 -> 27657184 | K13: =J13/(C13/2) -> 276571.84 | L13: =E13*(C13-2*F13) -> 1092 | M13: 以理想化 H形鋼/槽鋼 斷面矩形近似，未含圓角。 | O13: =(2*F13*D13^3+(C13-2*F13)*E13^3)/12 -> 5065776 | P13: =IFERROR(SQRT(J13/H13),"") -> 85.402349 | Q13: =IFERROR(SQRT(O13/H13),"") -> 36.550122
A14: H-200x200x8x12 | B14: H形鋼 | C14: 200 | D14: 200 | E14: 8 | F14: 12 | G14: 0 | H14: =2*D14*F14+(C14-2*F14)*E14 -> 6208 | I14: =H14*DB_Settings!$G$5 -> 48.7328 | J14: =(D14*C14^3-(D14-E14)*(C14-2*F14)^3)/12 -> 46104917 | K14: =J14/(C14/2) -> 461049.17 | L14: =E14*(C14-2*F14) -> 1408 | M14: 以理想化 H形鋼/槽鋼 斷面矩形近似，未含圓角。 | O14: =(2*F14*D14^3+(C14-2*F14)*E14^3)/12 -> 16007509 | P14: =IFERROR(SQRT(J14/H14),"") -> 86.17827 | Q14: =IFERROR(SQRT(O14/H14),"") -> 50.77922
... A157: C-380x100x13x20 | B157: 槽鋼 | C157: 380 | D157: 100 | E157: 13 | F157: 20 | G157: 0 | H157: =2*D157*F157+(C157-2*F157)*E157 -> 8420 | I157: =H157*DB_Settings!$G$5 -> 66.097 | J157: =(D157*C157^3-(D157-E157)*(C157-2*F157)^3)/12 -> 1.7231267e+08 | K157: =J157/(C157/2) -> 906908.77 | L157: =E157*(C157-2*F157) -> 4420 | M157: 以理想化 H形鋼/槽鋼 斷面矩形近似，未含圓角。 | O157: =(2*F157*D157^3+(C157-2*F157)*E157^3)/12 -> 3395581.7 | P157: =IFERROR(SQRT(J157/H157),"") -> 143.05484 | Q157: =IFERROR(SQRT(O157/H157),"") -> 20.081726
A158: P-60x30x10x1.6 | B158: P型鋼 | C158: 60 | D158: 30 | E158: 1.6 | F158: 1.6 | G158: 10 | H158: =E158*(C158-2*F158)+2*D158*F158+2*G158*F158 -> 218.88 | I158: =H158*DB_Settings!$G$5 -> 1.718208 | J158: =E158*(C158-2*F158)^3/12+2*(D158*F158^3/12+D158*F158*(C158/2-F158/2)^2)+2*(F158*G158^3/12+F158*G158*(C158/2-F158-G158/2)^2) -> 124095.9 | K158: =J158/(C158/2) -> 4136.5299 | L158: =E158*(C158-2*F158) -> 90.88 | M158: P 型以帶唇 C 形冷彎斷面近似。 | O158: =(2*F158*D158^3+(C158-2*F158)*E158^3)/12 -> 7219.3877 | P158: =IFERROR(SQRT(J158/H158),"") -> 23.810892 | Q158: =IFERROR(SQRT(O158/H158),"") -> 5.7431101
A159: P-60x30x10x2 | B159: P型鋼 | C159: 60 | D159: 30 | E159: 2 | F159: 2 | G159: 10 | H159: =E159*(C159-2*F159)+2*D159*F159+2*G159*F159 -> 272 | I159: =H159*DB_Settings!$G$5 -> 2.1352 | J159: =E159*(C159-2*F159)^3/12+2*(D159*F159^3/12+D159*F159*(C159/2-F159/2)^2)+2*(F159*G159^3/12+F159*G159*(C159/2-F159-G159/2)^2) -> 151722.67 | K159: =J159/(C159/2) -> 5057.4222 | L159: =E159*(C159-2*F159) -> 112 | M159: P 型以帶唇 C 形冷彎斷面近似。 | O159: =(2*F159*D159^3+(C159-2*F159)*E159^3)/12 -> 9037.3333 | P159: =IFERROR(SQRT(J159/H159),"") -> 23.617873 | Q159: =IFERROR(SQRT(O159/H159),"") -> 5.7641556
A160: P-60x30x10x2.3 | B160: P型鋼 | C160: 60 | D160: 30 | E160: 2.3 | F160: 2.3 | G160: 10 | H160: =E160*(C160-2*F160)+2*D160*F160+2*G160*F160 -> 311.42 | I160: =H160*DB_Settings!$G$5 -> 2.444647 | J160: =E160*(C160-2*F160)^3/12+2*(D160*F160^3/12+D160*F160*(C160/2-F160/2)^2)+2*(F160*G160^3/12+F160*G160*(C160/2-F160-G160/2)^2) -> 171597.38 | K160: =J160/(C160/2) -> 5719.9126 | L160: =E160*(C160-2*F160) -> 127.42 | M160: P 型以帶唇 C 形冷彎斷面近似。 | O160: =(2*F160*D160^3+(C160-2*F160)*E160^3)/12 -> 10406.171 | P160: =IFERROR(SQRT(J160/H160),"") -> 23.473728 | Q160: =IFERROR(SQRT(O160/H160),"") -> 5.7805908
A161: P-70x40x25x1.6 | B161: P型鋼 | C161: 70 | D161: 40 | E161: 1.6 | F161: 1.6 | G161: 25 | H161: =E161*(C161-2*F161)+2*D161*F161+2*G161*F161 -> 314.88 | I161: =H161*DB_Settings!$G$5 -> 2.471808 | J161: =E161*(C161-2*F161)^3/12+2*(D161*F161^3/12+D161*F161*(C161/2-F161/2)^2)+2*(F161*G161^3/12+F161*G161*(C161/2-F161-G161/2)^2) -> 228596.38 | K161: =J161/(C161/2) -> 6531.3251 | L161: =E161*(C161-2*F161) -> 106.88 | M161: P 型以帶唇 C 形冷彎斷面近似。 | O161: =(2*F161*D161^3+(C161-2*F161)*E161^3)/12 -> 17089.468 | P161: =IFERROR(SQRT(J161/H161),"") -> 26.944004 | Q161: =IFERROR(SQRT(O161/H161),"") -> 7.367018
A162: P-75x35x15x2.3 | B162: P型鋼 | C162: 75 | D162: 35 | E162: 2.3 | F162: 2.3 | G162: 15 | H162: =E162*(C162-2*F162)+2*D162*F162+2*G162*F162 -> 391.92 | I162: =H162*DB_Settings!$G$5 -> 3.076572 | J162: =E162*(C162-2*F162)^3/12+2*(D162*F162^3/12+D162*F162*(C162/2-F162/2)^2)+2*(F162*G162^3/12+F162*G162*(C162/2-F162-G162/2)^2) -> 333915.78 | K162: =J162/(C162/2) -> 8904.4207 | L162: =E162*(C162-2*F162) -> 161.92 | M162: P 型以帶唇 C 形冷彎斷面近似。 | O162: =(2*F162*D162^3+(C162-2*F162)*E162^3)/12 -> 16506.796 | P162: =IFERROR(SQRT(J162/H162),"") -> 29.189036 | Q162: =IFERROR(SQRT(O162/H162),"") -> 6.4898205
A163: P-75x45x15x1.6 | B163: P型鋼 | C163: 75 | D163: 45 | E163: 1.6 | F163: 1.6 | G163: 15 | H163: =E163*(C163-2*F163)+2*D163*F163+2*G163*F163 -> 306.88 | I163: =H163*DB_Settings!$G$5 -> 2.409008 | J163: =E163*(C163-2*F163)^3/12+2*(D163*F163^3/12+D163*F163*(C163/2-F163/2)^2)+2*(F163*G163^3/12+F163*G163*(C163/2-F163-G163/2)^2) -> 282950.59 | K163: =J163/(C163/2) -> 7545.3491 | L163: =E163*(C163-2*F163) -> 114.88 | M163: P 型以帶唇 C 形冷彎斷面近似。 | O163: =(2*F163*D163^3+(C163-2*F163)*E163^3)/12 -> 24324.508 | P163: =IFERROR(SQRT(J163/H163),"") -> 30.364841 | Q163: =IFERROR(SQRT(O163/H163),"") -> 8.903028
A164: P-75x45x15x2 | B164: P型鋼 | C164: 75 | D164: 45 | E164: 2 | F164: 2 | G164: 15 | H164: =E164*(C164-2*F164)+2*D164*F164+2*G164*F164 -> 382 | I164: =H164*DB_Settings!$G$5 -> 2.9987 | J164: =E164*(C164-2*F164)^3/12+2*(D164*F164^3/12+D164*F164*(C164/2-F164/2)^2)+2*(F164*G164^3/12+F164*G164*(C164/2-F164-G164/2)^2) -> 347681.83 | K164: =J164/(C164/2) -> 9271.5156 | L164: =E164*(C164-2*F164) -> 142 | M164: P 型以帶唇 C 形冷彎斷面近似。 | O164: =(2*F164*D164^3+(C164-2*F164)*E164^3)/12 -> 30422.333 | P164: =IFERROR(SQRT(J164/H164),"") -> 30.168889 | Q164: =IFERROR(SQRT(O164/H164),"") -> 8.9241031
A165: P-75x45x15x2.3 | B165: P型鋼 | C165: 75 | D165: 45 | E165: 2.3 | F165: 2.3 | G165: 15 | H165: =E165*(C165-2*F165)+2*D165*F165+2*G165*F165 -> 437.92 | I165: =H165*DB_Settings!$G$5 -> 3.437672 | J165: =E165*(C165-2*F165)^3/12+2*(D165*F165^3/12+D165*F165*(C165/2-F165/2)^2)+2*(F165*G165^3/12+F165*G165*(C165/2-F165-G165/2)^2) -> 394716.89 | K165: =J165/(C165/2) -> 10525.784 | L165: =E165*(C165-2*F165) -> 161.92 | M165: P 型以帶唇 C 形冷彎斷面近似。 | O165: =(2*F165*D165^3+(C165-2*F165)*E165^3)/12 -> 35002.63 | P165: =IFERROR(SQRT(J165/H165),"") -> 30.022404 | Q165: =IFERROR(SQRT(O165/H165),"") -> 8.9403176
A166: P-90x45x20x1.6 | B166: P型鋼 | C166: 90 | D166: 45 | E166: 1.6 | F166: 1.6 | G166: 20 | H166: =E166*(C166-2*F166)+2*D166*F166+2*G166*F166 -> 346.88 | I166: =H166*DB_Settings!$G$5 -> 2.723008 | J166: =E166*(C166-2*F166)^3/12+2*(D166*F166^3/12+D166*F166*(C166/2-F166/2)^2)+2*(F166*G166^3/12+F166*G166*(C166/2-F166-G166/2)^2) -> 442080.32 | K166: =J166/(C166/2) -> 9824.0072 | L166: =E166*(C166-2*F166) -> 138.88 | M166: P 型以帶唇 C 形冷彎斷面近似。 | O166: =(2*F166*D166^3+(C166-2*F166)*E166^3)/12 -> 24329.628 | P166: =IFERROR(SQRT(J166/H166),"") -> 35.699404 | Q166: =IFERROR(SQRT(O166/H166),"") -> 8.3748705
A167: P-90x45x20x2.3 | B167: P型鋼 | C167: 90 | D167: 45 | E167: 2.3 | F167: 2.3 | G167: 20 | H167: =E167*(C167-2*F167)+2*D167*F167+2*G167*F167 -> 495.42 | I167: =H167*DB_Settings!$G$5 -> 3.889047 | J167: =E167*(C167-2*F167)^3/12+2*(D167*F167^3/12+D167*F167*(C167/2-F167/2)^2)+2*(F167*G167^3/12+F167*G167*(C167/2-F167-G167/2)^2) -> 618933.73 | K167: =J167/(C167/2) -> 13754.083 | L167: =E167*(C167-2*F167) -> 196.42 | M167: P 型以帶唇 C 形冷彎斷面近似。 | O167: =(2*F167*D167^3+(C167-2*F167)*E167^3)/12 -> 35017.838 | P167: =IFERROR(SQRT(J167/H167),"") -> 35.345596 | Q167: =IFERROR(SQRT(O167/H167),"") -> 8.4073262
A168: P-90x45x20x3.2 | B168: P型鋼 | C168: 90 | D168: 45 | E168: 3.2 | F168: 3.2 | G168: 20 | H168: =E168*(C168-2*F168)+2*D168*F168+2*G168*F168 -> 683.52 | I168: =H168*DB_Settings!$G$5 -> 5.365632 | J168: =E168*(C168-2*F168)^3/12+2*(D168*F168^3/12+D168*F168*(C168/2-F168/2)^2)+2*(F168*G168^3/12+F168*G168*(C168/2-F168-G168/2)^2) -> 832223.64 | K168: =J168/(C168/2) -> 18493.859 | L168: =E168*(C168-2*F168) -> 267.52 | M168: P 型以帶唇 C 形冷彎斷面近似。 | O168: =(2*F168*D168^3+(C168-2*F168)*E168^3)/12 -> 48828.284 | P168: =IFERROR(SQRT(J168/H168),"") -> 34.89349 | Q168: =IFERROR(SQRT(O168/H168),"") -> 8.4520122
A169: P-100x50x20x1.6 | B169: P型鋼 | C169: 100 | D169: 50 | E169: 1.6 | F169: 1.6 | G169: 20 | H169: =E169*(C169-2*F169)+2*D169*F169+2*G169*F169 -> 378.88 | I169: =H169*DB_Settings!$G$5 -> 2.974208 | J169: =E169*(C169-2*F169)^3/12+2*(D169*F169^3/12+D169*F169*(C169/2-F169/2)^2)+2*(F169*G169^3/12+F169*G169*(C169/2-F169-G169/2)^2) -> 604780.27 | K169: =J169/(C169/2) -> 12095.605 | L169: =E169*(C169-2*F169) -> 154.88 | M169: P 型以帶唇 C 形冷彎斷面近似。 | O169: =(2*F169*D169^3+(C169-2*F169)*E169^3)/12 -> 33366.374 | P169: =IFERROR(SQRT(J169/H169),"") -> 39.952869 | Q169: =IFERROR(SQRT(O169/H169),"") -> 9.3843386
... A202: P-250x75x25x4.5 | B202: P型鋼 | C202: 250 | D202: 75 | E202: 4.5 | F202: 4.5 | G202: 25 | H202: =E202*(C202-2*F202)+2*D202*F202+2*G202*F202 -> 1984.5 | I202: =H202*DB_Settings!$G$5 -> 15.578325 | J202: =E202*(C202-2*F202)^3/12+2*(D202*F202^3/12+D202*F202*(C202/2-F202/2)^2)+2*(F202*G202^3/12+F202*G202*(C202/2-F202-G202/2)^2) -> 18056933 | K202: =J202/(C202/2) -> 144455.46 | L202: =E202*(C202-2*F202) -> 1084.5 | M202: P 型以帶唇 C 形冷彎斷面近似。 | O202: =(2*F202*D202^3+(C202-2*F202)*E202^3)/12 -> 318236.34 | P202: =IFERROR(SQRT(J202/H202),"") -> 95.388592 | Q202: =IFERROR(SQRT(O202/H202),"") -> 12.663371
A203: L-25x25x3 | B203: L型鋼 | C203: 25 | D203: 25 | E203: 3 | F203: 3 | G203: 0 | H203: =C203*E203+D203*F203-E203^2 -> 141 | I203: =H203*DB_Settings!$G$5 -> 1.10685 | J203: =(E203*C203^3/12+E203*C203*(C203/2-((E203*C203*(C203/2)+D203*F203*(F203/2)-E203^2*(F203/2))/(E203*C203+D203*F203-E203^2)))^2)+(D203*F203^3/12+D203*F203*(F203/2-((E203*C203*(C203/2)+D203*F203*(F203/2)-E203^2*(F203/2))/(E203*C203+D203*F203-E203^2)))^2)-(E203^4/12+E203^2*(F203/2-((E203*C203*(C203/2)+D203*F203*(F203/2)-E203^2*(F203/2))/(E203*C203+D203*F203-E203^2)))^2) -> 8203.6223 | K203: =J203/MAX(((E203*C203*(C203/2)+D203*F203*(F203/2)-E203^2*(F203/2))/(E203*C203+D203*F203-E203^2)),C203-((E203*C203*(C203/2)+D203*F203*(F203/2)-E203^2*(F203/2))/(E203*C203+D203*F203-E203^2))) -> 464.82248 | L203: =E203*(C203-F203) -> 66 | M203: L 型以單角鋼一腿垂直擺放近似；僅供初估。 | O203: =(2*F203*D203^3+(C203-2*F203)*E203^3)/12 -> 7855.25 | P203: =IFERROR(SQRT(J203/H203),"") -> 7.6276942 | Q203: =IFERROR(SQRT(O203/H203),"") -> 7.4639797
A204: L-30x30x3 | B204: L型鋼 | C204: 30 | D204: 30 | E204: 3 | F204: 3 | G204: 0 | H204: =C204*E204+D204*F204-E204^2 -> 171 | I204: =H204*DB_Settings!$G$5 -> 1.34235 | J204: =(E204*C204^3/12+E204*C204*(C204/2-((E204*C204*(C204/2)+D204*F204*(F204/2)-E204^2*(F204/2))/(E204*C204+D204*F204-E204^2)))^2)+(D204*F204^3/12+D204*F204*(F204/2-((E204*C204*(C204/2)+D204*F204*(F204/2)-E204^2*(F204/2))/(E204*C204+D204*F204-E204^2)))^2)-(E204^4/12+E204^2*(F204/2-((E204*C204*(C204/2)+D204*F204*(F204/2)-E204^2*(F204/2))/(E204*C204+D204*F204-E204^2)))^2) -> 14580.355 | K204: =J204/MAX(((E204*C204*(C204/2)+D204*F204*(F204/2)-E204^2*(F204/2))/(E204*C204+D204*F204-E204^2)),C204-((E204*C204*(C204/2)+D204*F204*(F204/2)-E204^2*(F204/2))/(E204*C204+D204*F204-E204^2))) -> 681.49262 | L204: =E204*(C204-F204) -> 81 | M204: L 型以單角鋼一腿垂直擺放近似；僅供初估。 | O204: =(2*F204*D204^3+(C204-2*F204)*E204^3)/12 -> 13554 | P204: =IFERROR(SQRT(J204/H204),"") -> 9.2339177 | Q204: =IFERROR(SQRT(O204/H204),"") -> 8.9029859
A205: L-40x40x3 | B205: L型鋼 | C205: 40 | D205: 40 | E205: 3 | F205: 3 | G205: 0 | H205: =C205*E205+D205*F205-E205^2 -> 231 | I205: =H205*DB_Settings!$G$5 -> 1.81335 | J205: =(E205*C205^3/12+E205*C205*(C205/2-((E205*C205*(C205/2)+D205*F205*(F205/2)-E205^2*(F205/2))/(E205*C205+D205*F205-E205^2)))^2)+(D205*F205^3/12+D205*F205*(F205/2-((E205*C205*(C205/2)+D205*F205*(F205/2)-E205^2*(F205/2))/(E205*C205+D205*F205-E205^2)))^2)-(E205^4/12+E205^2*(F205/2-((E205*C205*(C205/2)+D205*F205*(F205/2)-E205^2*(F205/2))/(E205*C205+D205*F205-E205^2)))^2) -> 35818.185 | K205: =J205/MAX(((E205*C205*(C205/2)+D205*F205*(F205/2)-E205^2*(F205/2))/(E205*C205+D205*F205-E205^2)),C205-((E205*C205*(C205/2)+D205*F205*(F205/2)-E205^2*(F205/2))/(E205*C205+D205*F205-E205^2))) -> 1239.8293 | L205: =E205*(C205-F205) -> 111 | M205: L 型以單角鋼一腿垂直擺放近似；僅供初估。 | O205: =(2*F205*D205^3+(C205-2*F205)*E205^3)/12 -> 32076.5 | P205: =IFERROR(SQRT(J205/H205),"") -> 12.452192 | Q205: =IFERROR(SQRT(O205/H205),"") -> 11.783858
A206: L-40x40x5 | B206: L型鋼 | C206: 40 | D206: 40 | E206: 5 | F206: 5 | G206: 0 | H206: =C206*E206+D206*F206-E206^2 -> 375 | I206: =H206*DB_Settings!$G$5 -> 2.94375 | J206: =(E206*C206^3/12+E206*C206*(C206/2-((E206*C206*(C206/2)+D206*F206*(F206/2)-E206^2*(F206/2))/(E206*C206+D206*F206-E206^2)))^2)+(D206*F206^3/12+D206*F206*(F206/2-((E206*C206*(C206/2)+D206*F206*(F206/2)-E206^2*(F206/2))/(E206*C206+D206*F206-E206^2)))^2)-(E206^4/12+E206^2*(F206/2-((E206*C206*(C206/2)+D206*F206*(F206/2)-E206^2*(F206/2))/(E206*C206+D206*F206-E206^2)))^2) -> 55614.583 | K206: =J206/MAX(((E206*C206*(C206/2)+D206*F206*(F206/2)-E206^2*(F206/2))/(E206*C206+D206*F206-E206^2)),C206-((E206*C206*(C206/2)+D206*F206*(F206/2)-E206^2*(F206/2))/(E206*C206+D206*F206-E206^2))) -> 1974.4822 | L206: =E206*(C206-F206) -> 175 | M206: L 型以單角鋼一腿垂直擺放近似；僅供初估。 | O206: =(2*F206*D206^3+(C206-2*F206)*E206^3)/12 -> 53645.833 | P206: =IFERROR(SQRT(J206/H206),"") -> 12.178077 | Q206: =IFERROR(SQRT(O206/H206),"") -> 11.960583
A207: L-45x45x4 | B207: L型鋼 | C207: 45 | D207: 45 | E207: 4 | F207: 4 | G207: 0 | H207: =C207*E207+D207*F207-E207^2 -> 344 | I207: =H207*DB_Settings!$G$5 -> 2.7004 | J207: =(E207*C207^3/12+E207*C207*(C207/2-((E207*C207*(C207/2)+D207*F207*(F207/2)-E207^2*(F207/2))/(E207*C207+D207*F207-E207^2)))^2)+(D207*F207^3/12+D207*F207*(F207/2-((E207*C207*(C207/2)+D207*F207*(F207/2)-E207^2*(F207/2))/(E207*C207+D207*F207-E207^2)))^2)-(E207^4/12+E207^2*(F207/2-((E207*C207*(C207/2)+D207*F207*(F207/2)-E207^2*(F207/2))/(E207*C207+D207*F207-E207^2)))^2) -> 66656.981 | K207: =J207/MAX(((E207*C207*(C207/2)+D207*F207*(F207/2)-E207^2*(F207/2))/(E207*C207+D207*F207-E207^2)),C207-((E207*C207*(C207/2)+D207*F207*(F207/2)-E207^2*(F207/2))/(E207*C207+D207*F207-E207^2))) -> 2065.3937 | L207: =E207*(C207-F207) -> 164 | M207: L 型以單角鋼一腿垂直擺放近似；僅供初估。 | O207: =(2*F207*D207^3+(C207-2*F207)*E207^3)/12 -> 60947.333 | P207: =IFERROR(SQRT(J207/H207),"") -> 13.92014 | Q207: =IFERROR(SQRT(O207/H207),"") -> 13.310615
A208: L-45x45x5 | B208: L型鋼 | C208: 45 | D208: 45 | E208: 5 | F208: 5 | G208: 0 | H208: =C208*E208+D208*F208-E208^2 -> 425 | I208: =H208*DB_Settings!$G$5 -> 3.33625 | J208: =(E208*C208^3/12+E208*C208*(C208/2-((E208*C208*(C208/2)+D208*F208*(F208/2)-E208^2*(F208/2))/(E208*C208+D208*F208-E208^2)))^2)+(D208*F208^3/12+D208*F208*(F208/2-((E208*C208*(C208/2)+D208*F208*(F208/2)-E208^2*(F208/2))/(E208*C208+D208*F208-E208^2)))^2)-(E208^4/12+E208^2*(F208/2-((E208*C208*(C208/2)+D208*F208*(F208/2)-E208^2*(F208/2))/(E208*C208+D208*F208-E208^2)))^2) -> 80738.358 | K208: =J208/MAX(((E208*C208*(C208/2)+D208*F208*(F208/2)-E208^2*(F208/2))/(E208*C208+D208*F208-E208^2)),C208-((E208*C208*(C208/2)+D208*F208*(F208/2)-E208^2*(F208/2))/(E208*C208+D208*F208-E208^2))) -> 2530.0499 | L208: =E208*(C208-F208) -> 200 | M208: L 型以單角鋼一腿垂直擺放近似；僅供初估。 | O208: =(2*F208*D208^3+(C208-2*F208)*E208^3)/12 -> 76302.083 | P208: =IFERROR(SQRT(J208/H208),"") -> 13.783055 | Q208: =IFERROR(SQRT(O208/H208),"") -> 13.399042
A209: L-50x50x4 | B209: L型鋼 | C209: 50 | D209: 50 | E209: 4 | F209: 4 | G209: 0 | H209: =C209*E209+D209*F209-E209^2 -> 384 | I209: =H209*DB_Settings!$G$5 -> 3.0144 | J209: =(E209*C209^3/12+E209*C209*(C209/2-((E209*C209*(C209/2)+D209*F209*(F209/2)-E209^2*(F209/2))/(E209*C209+D209*F209-E209^2)))^2)+(D209*F209^3/12+D209*F209*(F209/2-((E209*C209*(C209/2)+D209*F209*(F209/2)-E209^2*(F209/2))/(E209*C209+D209*F209-E209^2)))^2)-(E209^4/12+E209^2*(F209/2-((E209*C209*(C209/2)+D209*F209*(F209/2)-E209^2*(F209/2))/(E209*C209+D209*F209-E209^2)))^2) -> 92607.833 | K209: =J209/MAX(((E209*C209*(C209/2)+D209*F209*(F209/2)-E209^2*(F209/2))/(E209*C209+D209*F209-E209^2)),C209-((E209*C209*(C209/2)+D209*F209*(F209/2)-E209^2*(F209/2))/(E209*C209+D209*F209-E209^2))) -> 2570.952 | L209: =E209*(C209-F209) -> 184 | M209: L 型以單角鋼一腿垂直擺放近似；僅供初估。 | O209: =(2*F209*D209^3+(C209-2*F209)*E209^3)/12 -> 83557.333 | P209: =IFERROR(SQRT(J209/H209),"") -> 15.529528 | Q209: =IFERROR(SQRT(O209/H209),"") -> 14.751177
A210: L-50x50x5 | B210: L型鋼 | C210: 50 | D210: 50 | E210: 5 | F210: 5 | G210: 0 | H210: =C210*E210+D210*F210-E210^2 -> 475 | I210: =H210*DB_Settings!$G$5 -> 3.72875 | J210: =(E210*C210^3/12+E210*C210*(C210/2-((E210*C210*(C210/2)+D210*F210*(F210/2)-E210^2*(F210/2))/(E210*C210+D210*F210-E210^2)))^2)+(D210*F210^3/12+D210*F210*(F210/2-((E210*C210*(C210/2)+D210*F210*(F210/2)-E210^2*(F210/2))/(E210*C210+D210*F210-E210^2)))^2)-(E210^4/12+E210^2*(F210/2-((E210*C210*(C210/2)+D210*F210*(F210/2)-E210^2*(F210/2))/(E210*C210+D210*F210-E210^2)))^2) -> 112502.74 | K210: =J210/MAX(((E210*C210*(C210/2)+D210*F210*(F210/2)-E210^2*(F210/2))/(E210*C210+D210*F210-E210^2)),C210-((E210*C210*(C210/2)+D210*F210*(F210/2)-E210^2*(F210/2))/(E210*C210+D210*F210-E210^2))) -> 3155.0584 | L210: =E210*(C210-F210) -> 225 | M210: L 型以單角鋼一腿垂直擺放近似；僅供初估。 | O210: =(2*F210*D210^3+(C210-2*F210)*E210^3)/12 -> 104583.33 | P210: =IFERROR(SQRT(J210/H210),"") -> 15.389863 | Q210: =IFERROR(SQRT(O210/H210),"") -> 14.83831
A211: L-50x50x6 | B211: L型鋼 | C211: 50 | D211: 50 | E211: 6 | F211: 6 | G211: 0 | H211: =C211*E211+D211*F211-E211^2 -> 564 | I211: =H211*DB_Settings!$G$5 -> 4.4274 | J211: =(E211*C211^3/12+E211*C211*(C211/2-((E211*C211*(C211/2)+D211*F211*(F211/2)-E211^2*(F211/2))/(E211*C211+D211*F211-E211^2)))^2)+(D211*F211^3/12+D211*F211*(F211/2-((E211*C211*(C211/2)+D211*F211*(F211/2)-E211^2*(F211/2))/(E211*C211+D211*F211-E211^2)))^2)-(E211^4/12+E211^2*(F211/2-((E211*C211*(C211/2)+D211*F211*(F211/2)-E211^2*(F211/2))/(E211*C211+D211*F211-E211^2)))^2) -> 131257.96 | K211: =J211/MAX(((E211*C211*(C211/2)+D211*F211*(F211/2)-E211^2*(F211/2))/(E211*C211+D211*F211-E211^2)),C211-((E211*C211*(C211/2)+D211*F211*(F211/2)-E211^2*(F211/2))/(E211*C211+D211*F211-E211^2))) -> 3718.5799 | L211: =E211*(C211-F211) -> 264 | M211: L 型以單角鋼一腿垂直擺放近似；僅供初估。 | O211: =(2*F211*D211^3+(C211-2*F211)*E211^3)/12 -> 125684 | P211: =IFERROR(SQRT(J211/H211),"") -> 15.255388 | Q211: =IFERROR(SQRT(O211/H211),"") -> 14.927959
A212: L-60x60x4 | B212: L型鋼 | C212: 60 | D212: 60 | E212: 4 | F212: 4 | G212: 0 | H212: =C212*E212+D212*F212-E212^2 -> 464 | I212: =H212*DB_Settings!$G$5 -> 3.6424 | J212: =(E212*C212^3/12+E212*C212*(C212/2-((E212*C212*(C212/2)+D212*F212*(F212/2)-E212^2*(F212/2))/(E212*C212+D212*F212-E212^2)))^2)+(D212*F212^3/12+D212*F212*(F212/2-((E212*C212*(C212/2)+D212*F212*(F212/2)-E212^2*(F212/2))/(E212*C212+D212*F212-E212^2)))^2)-(E212^4/12+E212^2*(F212/2-((E212*C212*(C212/2)+D212*F212*(F212/2)-E212^2*(F212/2))/(E212*C212+D212*F212-E212^2)))^2) -> 163134.53 | K212: =J212/MAX(((E212*C212*(C212/2)+D212*F212*(F212/2)-E212^2*(F212/2))/(E212*C212+D212*F212-E212^2)),C212-((E212*C212*(C212/2)+D212*F212*(F212/2)-E212^2*(F212/2))/(E212*C212+D212*F212-E212^2))) -> 3748.7332 | L212: =E212*(C212-F212) -> 224 | M212: L 型以單角鋼一腿垂直擺放近似；僅供初估。 | O212: =(2*F212*D212^3+(C212-2*F212)*E212^3)/12 -> 144277.33 | P212: =IFERROR(SQRT(J212/H212),"") -> 18.750548 | Q212: =IFERROR(SQRT(O212/H212),"") -> 17.633563
A213: L-60x60x5 | B213: L型鋼 | C213: 60 | D213: 60 | E213: 5 | F213: 5 | G213: 0 | H213: =C213*E213+D213*F213-E213^2 -> 575 | I213: =H213*DB_Settings!$G$5 -> 4.51375 | J213: =(E213*C213^3/12+E213*C213*(C213/2-((E213*C213*(C213/2)+D213*F213*(F213/2)-E213^2*(F213/2))/(E213*C213+D213*F213-E213^2)))^2)+(D213*F213^3/12+D213*F213*(F213/2-((E213*C213*(C213/2)+D213*F213*(F213/2)-E213^2*(F213/2))/(E213*C213+D213*F213-E213^2)))^2)-(E213^4/12+E213^2*(F213/2-((E213*C213*(C213/2)+D213*F213*(F213/2)-E213^2*(F213/2))/(E213*C213+D213*F213-E213^2)))^2) -> 199078.35 | K213: =J213/MAX(((E213*C213*(C213/2)+D213*F213*(F213/2)-E213^2*(F213/2))/(E213*C213+D213*F213-E213^2)),C213-((E213*C213*(C213/2)+D213*F213*(F213/2)-E213^2*(F213/2))/(E213*C213+D213*F213-E213^2))) -> 4613.4026 | L213: =E213*(C213-F213) -> 275 | M213: L 型以單角鋼一腿垂直擺放近似；僅供初估。 | O213: =(2*F213*D213^3+(C213-2*F213)*E213^3)/12 -> 180520.83 | P213: =IFERROR(SQRT(J213/H213),"") -> 18.607074 | Q213: =IFERROR(SQRT(O213/H213),"") -> 17.718614
A214: L-65x65x5 | B214: L型鋼 | C214: 65 | D214: 65 | E214: 5 | F214: 5 | G214: 0 | H214: =C214*E214+D214*F214-E214^2 -> 625 | I214: =H214*DB_Settings!$G$5 -> 4.90625 | J214: =(E214*C214^3/12+E214*C214*(C214/2-((E214*C214*(C214/2)+D214*F214*(F214/2)-E214^2*(F214/2))/(E214*C214+D214*F214-E214^2)))^2)+(D214*F214^3/12+D214*F214*(F214/2-((E214*C214*(C214/2)+D214*F214*(F214/2)-E214^2*(F214/2))/(E214*C214+D214*F214-E214^2)))^2)-(E214^4/12+E214^2*(F214/2-((E214*C214*(C214/2)+D214*F214*(F214/2)-E214^2*(F214/2))/(E214*C214+D214*F214-E214^2)))^2) -> 255452.08 | K214: =J214/MAX(((E214*C214*(C214/2)+D214*F214*(F214/2)-E214^2*(F214/2))/(E214*C214+D214*F214-E214^2)),C214-((E214*C214*(C214/2)+D214*F214*(F214/2)-E214^2*(F214/2))/(E214*C214+D214*F214-E214^2))) -> 5446.7395 | L214: =E214*(C214-F214) -> 300 | M214: L 型以單角鋼一腿垂直擺放近似；僅供初估。 | O214: =(2*F214*D214^3+(C214-2*F214)*E214^3)/12 -> 229427.08 | P214: =IFERROR(SQRT(J214/H214),"") -> 20.216907 | Q214: =IFERROR(SQRT(O214/H214),"") -> 19.159419
...

Sheet DB_Deflection
A1: 選項 | B1: 梁類別 | C1: L/n | D1: 絕對上限(mm) | E1: 撓度檢核項目 | F1: 說明 | G1: 資料來源
A2: 一般鋼梁｜總載重撓度 L/240 | B2: 一般鋼梁 | C2: 240 | E2: 總載重撓度 | F2: 容許撓度 Δa = L/240 | G2: 依使用者提供公司規範與鋼構實務慣用表示法整理。
A3: 一般鋼梁｜活載重撓度 L/360 | B3: 一般鋼梁 | C3: 360 | E3: 活載重撓度 | F3: 容許撓度 Δa = L/360
A4: 平台梁／走道梁｜L/360 且 ≤ 25 mm | B4: 平台梁／走道梁 | C4: 360 | D4: 25 | E4: 活載重撓度 | F4: 取 Min(L/360, 25 mm)
A5: 格柵板/花紋鋼板/面板｜≤ 6 mm | B5: 面板 | C5: 0 | D5: 6 | E5: 總載重撓度 | F5: 容許撓度 Δa = 6 mm
A6: 天車梁(Monorail)｜簡支單軌 L/800 | B6: 天車梁(Monorail) | C6: 800 | E6: 服務性撓度 | F6: 依單軌天車梁簡支條件
A7: 天車梁｜簡支雙軌 L/1000 | B7: 天車梁 | C7: 1000 | E7: 服務性撓度 | F7: 依雙軌天車梁簡支條件
A8: 天車梁(Monorail)｜懸臂梁 L/500 | B8: 天車梁(Monorail) | C8: 500 | E8: 服務性撓度 | F8: 依單軌天車懸臂梁條件
A9: 設備支承梁｜熱交換器 L/400 且 ≤ 21 mm | B9: 設備支承梁 | C9: 400 | D9: 21 | E9: 總載重撓度 | F9: 取 Min(L/400, 21 mm)
A10: 設備支承梁｜高塔槽體 L/600 且 ≤ 21 mm | B10: 設備支承梁 | C10: 600 | D10: 21 | E10: 總載重撓度 | F10: 取 Min(L/600, 21 mm)
A11: 設備支承梁｜轉動或振動設備 L/900 且 ≤ 21 mm | B11: 設備支承梁 | C11: 900 | D11: 21 | E11: 總載重撓度 | F11: 取 Min(L/900, 21 mm)
A12: 設備支承梁｜其他設備 L/400 且 ≤ 21 mm | B12: 設備支承梁 | C12: 400 | D12: 21 | E12: 總載重撓度 | F12: 取 Min(L/400, 21 mm)
A13: 管線支承梁｜與管線直交 L/300 且 ≤ 25 mm | B13: 管線支承梁 | C13: 300 | D13: 25 | E13: 總載重撓度 | F13: 取 Min(L/300, 25 mm)
A14: 管線支承梁｜與管線平行 L/600 且 ≤ 25 mm | B14: 管線支承梁 | C14: 600 | D14: 25 | E14: 總載重撓度 | F14: 取 Min(L/600, 25 mm)

Sheet DB_Dropdown
A1: H形鋼 | B1: I型梁 | C1: 槽鋼 | D1: P型鋼 | E1: L型鋼 | F1: BOX柱
A2: H-100x50x5x7 | B2: I-100x75x5x8 | C2: C-75x40x5x7 | D2: P-60x30x10x1.6 | E2: L-25x25x3 | F2: BOX-100x100x3.2
A3: H-100x100x6x8 | B3: I-125x75x5.5x9.5 | C3: C-100x50x5x7.5 | D3: P-60x30x10x2 | E3: L-30x30x3 | F3: BOX-100x100x4.5
A4: H-125x60x6x8 | B4: I-150x75x5.5x9.5 | C4: C-125x65x6x8 | D4: P-60x30x10x2.3 | E4: L-40x40x3 | F4: BOX-100x100x6
A5: H-125x125x6.5x9 | B5: I-150x125x8.5x14 | C5: C-150x75x6.5x10 | D5: P-70x40x25x1.6 | E5: L-40x40x5 | F5: BOX-125x125x3.2
A6: H-150x75x5x7 | B6: I-180x100x6x10 | C6: C-150x75x9x12.5 | D6: P-75x35x15x2.3 | E6: L-45x45x4 | F6: BOX-125x125x4.5
A7: H-150x100x6x9 | B7: I-200x100x7x10 | C7: C-180x75x7x10.5 | D7: P-75x45x15x1.6 | E7: L-45x45x5 | F7: BOX-125x125x6
A8: H-150x150x7x10 | B8: I-200x150x9x16 | C8: C-200x80x7.5x11 | D8: P-75x45x15x2 | E8: L-50x50x4 | F8: BOX-150x150x3.2
A9: H-175x90x5x8 | B9: I-250x125x7.5x12.5 | C9: C-200x90x8x13.5 | D9: P-75x45x15x2.3 | E9: L-50x50x5 | F9: BOX-150x150x4.5
A10: H-175x175x7.5x11 | B10: I-250x125x10x19 | C10: C-250x90x9x13 | D10: P-90x45x20x1.6 | E10: L-50x50x6 | F10: BOX-150x150x6
A11: H-200x100x4.5x7 | B11: I-300x150x8x13 | C11: C-250x90x11x14.5 | D11: P-90x45x20x2.3 | E11: L-60x60x4 | F11: BOX-150x150x9
A12: H-200x100x5.5x8 | B12: I-300x150x10x18.5 | C12: C-300x90x9x13 | D12: P-90x45x20x3.2 | E12: L-60x60x5 | F12: BOX-175x175x4.5
... A17: H-250x125x8x9 | B17: I-400x150x12.5x25 | C17: C-380x100x13x20 | D17: P-100x50x20x3.2 | E17: L-75x75x6 | F17: BOX-200x200x9
A18: H-250x175x7x11 | B18: I-450x175x11x20 | D18: P-100x50x20x4 | E18: L-75x75x9 | F18: BOX-200x200x12
A19: H-250x250x9x14 | B19: I-450x175x13x26 | D19: P-100x50x20x4.5 | E19: L-75x75x12 | F19: BOX-250x250x6
A20: H-250x250x14x14 | B20: I-600x190x13x25 | D20: P-120x40x20x3.2 | E20: L-80x80x6 | F20: BOX-250x250x9
A21: H-300x150x5.5x8 | B21: I-600x190x16x35 | D21: P-120x60x20x2.3 | E21: L-90x90x6 | F21: BOX-250x250x12
A22: H-300x150x6.5x9 | D22: P-120x60x20x3.2 | E22: L-90x90x7 | F22: BOX-250x250x16
A23: H-300x200x8x12 | D23: P-120x60x25x4.5 | E23: L-90x90x10 | F23: BOX-300x300x9
A24: H-300x300x12x12 | D24: P-125x50x20x2.3 | E24: L-90x90x13 | F24: BOX-300x300x12
A25: H-300x300x10x15 | D25: P-125x50x20x3.2 | E25: L-100x100x7 | F25: BOX-300x300x16
A26: H-300x300x15x15 | D26: P-125x50x20x4 | E26: L-100x100x10 | F26: BOX-300x300x19
A27: H-300x300x11x17 | D27: P-125x50x20x4.5 | E27: L-100x100x13 | F27: BOX-350x350x12
A28: H-300x300x13x21 | D28: P-150x50x20x2.3 | E28: L-120x120x8 | F28: BOX-350x350x16
A29: H-300x300x17x24 | D29: P-150x50x20x3.2 | E29: L-130x130x9 | F29: BOX-350x350x19
A30: H-300x300x20x28 | D30: P-150x50x20x4.5 | E30: L-130x130x12 | F30: BOX-400x400x12
A31: H-350x175x6x9 | D31: P-150x65x20x2.3 | E31: L-130x130x15 | F31: BOX-400x400x16
A32: H-350x175x7x11 | D32: P-150x65x20x3.2 | E32: L-150x150x12 | F32: BOX-400x400x19
A33: H-350x250x8x12 | D33: P-150x65x20x4 | E33: L-150x150x15 | F33: BOX-400x400x22
A34: H-350x250x9x14 | D34: P-150x75x20x3.2 | E34: L-150x150x19
A35: H-350x250x11x19 | D35: P-150x75x20x4 | E35: L-175x175x12
A36: H-350x250x15x22 | D36: P-150x75x20x4.5 | E36: L-175x175x15
A37: H-350x250x17x26 | D37: P-150x75x25x3.2 | E37: L-200x200x15
A38: H-350x350x13x13 | D38: P-150x75x25x4 | E38: L-200x200x20
A39: H-350x350x10x16 | D39: P-150x75x25x4.5 | E39: L-200x200x25
A40: H-350x350x16x16 | D40: P-200x75x20x3.2 | E40: L-250x250x25
A41: H-350x350x12x19 | D41: P-200x75x20x4 | E41: L-250x250x35
A42: H-350x350x19x19 | D42: P-200x75x20x4.5
A43: H-350x350x16x24 | D43: P-200x75x25x3.2
A44: H-350x350x18x28 | D44: P-200x75x25x4
...

Sheet DB_Grating
A1: 格柵型號 | B1: 承載條高 h (mm) | C1: 承載條厚 t (mm) | D1: 承載條間距 c/c (mm) | E1: 橫條間距 (mm) | F1: 自重 (kg/m²) | G1: 備註
A2: 20×3 @30 溝距100 | B2: 20 | C2: 3 | D2: 30 | E2: 100 | F2: =ROUND(C2*B2/D2*7850/1000000*1000+2,1) -> 17.7 | G2: 輕型水溝蓋
A3: 25×3 @30 溝距100 | B3: 25 | C3: 3 | D3: 30 | E3: 100 | F3: =ROUND(C3*B3/D3*7850/1000000*1000+2,1) -> 21.6 | G3: 一般水溝蓋
A4: 25×3 @30 溝距200 | B4: 25 | C4: 3 | D4: 30 | E4: 200 | F4: =ROUND(C4*B4/D4*7850/1000000*1000+2,1) -> 21.6 | G4: 一般水溝蓋(寬溝距)
A5: 25×3 @40 溝距200 | B5: 25 | C5: 3 | D5: 40 | E5: 200 | F5: =ROUND(C5*B5/D5*7850/1000000*1000+2,1) -> 16.7 | G5: 一般水溝蓋(寬溝距)
A6: 25×5 @30 溝距100 | B6: 25 | C6: 5 | D6: 30 | E6: 100 | F6: =ROUND(C6*B6/D6*7850/1000000*1000+2,1) -> 34.7 | G6: 重型水溝蓋
A7: 25×5 @30 溝距200 | B7: 25 | C7: 5 | D7: 30 | E7: 200 | F7: =ROUND(C7*B7/D7*7850/1000000*1000+2,1) -> 34.7 | G7: 重型水溝蓋(寬溝距)
A8: 25×5 @40 溝距200 | B8: 25 | C8: 5 | D8: 40 | E8: 200 | F8: =ROUND(C8*B8/D8*7850/1000000*1000+2,1) -> 26.5 | G8: 重型水溝蓋(寬溝距)
A9: 30×3 @30 溝距200 | B9: 30 | C9: 3 | D9: 30 | E9: 200 | F9: =ROUND(C9*B9/D9*7850/1000000*1000+2,1) -> 25.6 | G9: 標準平台格柵
A10: 30×5 @30 溝距100 | B10: 30 | C10: 5 | D10: 30 | E10: 100 | F10: =ROUND(C10*B10/D10*7850/1000000*1000+2,1) -> 41.3 | G10: 標準平台格柵
A11: 30×5 @40 溝距200 | B11: 30 | C11: 5 | D11: 40 | E11: 200 | F11: =ROUND(C11*B11/D11*7850/1000000*1000+2,1) -> 31.4 | G11: 標準平台格柵
A12: 32×5 @30 溝距100 | B12: 32 | C12: 5 | D12: 30 | E12: 100 | F12: =ROUND(C12*B12/D12*7850/1000000*1000+2,1) -> 43.9 | G12: 加強平台格柵
A13: 32×5 @40 溝距200 | B13: 32 | C13: 5 | D13: 40 | E13: 200 | F13: =ROUND(C13*B13/D13*7850/1000000*1000+2,1) -> 33.4 | G13: 加強平台格柵
... A21: 65×8 @30 溝距100 | B21: 65 | C21: 8 | D21: 30 | E21: 100 | F21: =ROUND(C21*B21/D21*7850/1000000*1000+2,1) -> 138.1 | G21: 特殊重載

Sheet DB_Deck
A1: Deck型號 | B1: 波高 hr (mm) | C1: 有效寬 b_eff (mm/m) | D1: 板厚 t (mm) | E1: Deck As (mm²/m) | F1: Deck Ix (mm⁴/m) | G1: Deck 自重 (kg/m²) | H1: 備註
A2: 1.0W-0.8mm | B2: 50 | C2: 600 | D2: 0.8 | E2: 1017 | F2: 234000 | G2: 9.5 | H2: 淺波50mm
A3: 1.0W-1.0mm | B3: 50 | C3: 600 | D3: 1 | E3: 1271 | F3: 289000 | G3: 11.8 | H3: 淺波50mm
A4: 1.0W-1.2mm | B4: 50 | C4: 600 | D4: 1.2 | E4: 1525 | F4: 342000 | G4: 14.2 | H4: 淺波50mm
A5: 1.5W-0.8mm | B5: 75 | C5: 600 | D5: 0.8 | E5: 1017 | F5: 456000 | G5: 10.2 | H5: 中波75mm
A6: 1.5W-1.0mm | B6: 75 | C6: 600 | D6: 1 | E6: 1271 | F6: 564000 | G6: 12.7 | H6: 中波75mm
A7: 1.5W-1.2mm | B7: 75 | C7: 600 | D7: 1.2 | E7: 1525 | F7: 670000 | G7: 15.2 | H7: 中波75mm
A8: 2.0W-0.8mm | B8: 75 | C8: 600 | D8: 0.8 | E8: 1017 | F8: 520000 | G8: 10.8 | H8: 深波75mm
A9: 2.0W-1.0mm | B9: 75 | C9: 600 | D9: 1 | E9: 1271 | F9: 648000 | G9: 13.5 | H9: 深波75mm
A10: 2.0W-1.2mm | B10: 75 | C10: 600 | D10: 1.2 | E10: 1525 | F10: 775000 | G10: 16.2 | H10: 深波75mm
A11: 3.0W-0.8mm | B11: 100 | C11: 600 | D11: 0.8 | E11: 1017 | F11: 750000 | G11: 12.5 | H11: 深波100mm
A12: 3.0W-1.0mm | B12: 100 | C12: 600 | D12: 1 | E12: 1271 | F12: 890000 | G12: 14.8 | H12: 深波100mm
A13: 3.0W-1.2mm | B13: 100 | C13: 600 | D13: 1.2 | E13: 1525 | F13: 1060000 | G13: 17.6 | H13: 深波100mm
A15: 電焊鋼絲網 (WWM) 規格表
A16: WWM規格 | B16: 鋼絲直徑 φ (mm) | C16: 經向間距 (mm) | D16: 緯向間距 (mm) | E16: As_經 (mm²/m) | F16: As_緯 (mm²/m) | G16: fy (MPa)
A17: φ3.2@100×100 | B17: 3.2 | C17: 100 | D17: 100 | E17: =ROUND(PI()/4*B17^2*(1000/C17),1) -> 80.4 | F17: =ROUND(PI()/4*B17^2*(1000/D17),1) -> 80.4 | G17: 490
A18: φ3.2@150×150 | B18: 3.2 | C18: 150 | D18: 150 | E18: =ROUND(PI()/4*B18^2*(1000/C18),1) -> 53.6 | F18: =ROUND(PI()/4*B18^2*(1000/D18),1) -> 53.6 | G18: 490
A19: φ4.0@100×100 | B19: 4 | C19: 100 | D19: 100 | E19: =ROUND(PI()/4*B19^2*(1000/C19),1) -> 125.7 | F19: =ROUND(PI()/4*B19^2*(1000/D19),1) -> 125.7 | G19: 490
A20: φ4.0@150×150 | B20: 4 | C20: 150 | D20: 150 | E20: =ROUND(PI()/4*B20^2*(1000/C20),1) -> 83.8 | F20: =ROUND(PI()/4*B20^2*(1000/D20),1) -> 83.8 | G20: 490
A21: φ4.0@200×200 | B21: 4 | C21: 200 | D21: 200 | E21: =ROUND(PI()/4*B21^2*(1000/C21),1) -> 62.8 | F21: =ROUND(PI()/4*B21^2*(1000/D21),1) -> 62.8 | G21: 490
A22: φ5.0@100×100 | B22: 5 | C22: 100 | D22: 100 | E22: =ROUND(PI()/4*B22^2*(1000/C22),1) -> 196.3 | F22: =ROUND(PI()/4*B22^2*(1000/D22),1) -> 196.3 | G22: 490
A23: φ5.0@150×150 | B23: 5 | C23: 150 | D23: 150 | E23: =ROUND(PI()/4*B23^2*(1000/C23),1) -> 130.9 | F23: =ROUND(PI()/4*B23^2*(1000/D23),1) -> 130.9 | G23: 490
A24: φ5.0@200×200 | B24: 5 | C24: 200 | D24: 200 | E24: =ROUND(PI()/4*B24^2*(1000/C24),1) -> 98.2 | F24: =ROUND(PI()/4*B24^2*(1000/D24),1) -> 98.2 | G24: 490
A25: φ6.0@100×100 | B25: 6 | C25: 100 | D25: 100 | E25: =ROUND(PI()/4*B25^2*(1000/C25),1) -> 282.7 | F25: =ROUND(PI()/4*B25^2*(1000/D25),1) -> 282.7 | G25: 490
A26: φ6.0@150×150 | B26: 6 | C26: 150 | D26: 150 | E26: =ROUND(PI()/4*B26^2*(1000/C26),1) -> 188.5 | F26: =ROUND(PI()/4*B26^2*(1000/D26),1) -> 188.5 | G26: 490
A27: φ6.0@200×200 | B27: 6 | C27: 200 | D27: 200 | E27: =ROUND(PI()/4*B27^2*(1000/C27),1) -> 141.4 | F27: =ROUND(PI()/4*B27^2*(1000/D27),1) -> 141.4 | G27: 490
